Workbook

Sheet Yearly Total To Date
B4: Yearly Total | F4: Total Average (Month) | J4: Total Average (Week) | N4: Total Average (Day) | R4: 2023 Occupancy Totals
B6: AM Field | C6: ='Monthly Totals'!C5+'Monthly Totals'!F5+'Monthly Totals'!I5+'Monthly Totals'!L5+'Monthly Totals'!O5+'Monthly Totals'!R5+'Monthly Totals'!C27+'Monthly Totals'!F27+'Monthly Totals'!I27+'Monthly Totals'!L27+'Monthly Totals'!O27+'Monthly Totals'!R27 -> 27085 | F6: AM Field | G6: =C6/12 -> 2257.0833 | J6: AM Field | K6: =C6 / 52 -> 520.86538 | N6: AM Field | O6: =C6 / 365 -> 74.205479 | R6: Time | S6: Bookings | T6: Spots Available | U6: Occupancy
B7: PM Field | C7: ='Monthly Totals'!C6+'Monthly Totals'!F6+'Monthly Totals'!I6+'Monthly Totals'!L6+'Monthly Totals'!O6+'Monthly Totals'!R6+'Monthly Totals'!C28+'Monthly Totals'!F28+'Monthly Totals'!I28+'Monthly Totals'!L28+'Monthly Totals'!O28+'Monthly Totals'!R28 -> 22666 | F7: PM Field | G7: =C7/12 -> 1888.8333 | J7: PM Field | K7: =C7 / 52 -> 435.88462 | N7: PM Field | O7: =C7 / 365 -> 62.09863 | R7: AM | S7: ='Occupancy Report Summarised'!L4+'Occupancy Report Summarised'!L8+'Occupancy Report Summarised'!L12+'Occupancy Report Summarised'!L16+'Occupancy Report Summarised'!L20+'Occupancy Report Summarised'!L24+'Occupancy Report Summarised'!L28+'Occupancy Report Summarised'!L32+'Occupancy Report Summarised'!L36+'Occupancy Report Summarised'!L40+'Occupancy Report Summarised'!L44+'Occupancy Report Summarised'!L48 -> 27085 | T7: ='Occupancy Report Summarised'!M4+'Occupancy Report Summarised'!M8+'Occupancy Report Summarised'!M12+'Occupancy Report Summarised'!M16+'Occupancy Report Summarised'!M20+'Occupancy Report Summarised'!M24+'Occupancy Report Summarised'!M28+'Occupancy Report Summarised'!M32+'Occupancy Report Summarised'!M36+'Occupancy Report Summarised'!M40+'Occupancy Report Summarised'!M44+'Occupancy Report Summarised'!M48 -> 33314 | U7: =SUM(S7/T7) -> 0.81302155
B8: Total Field | C8: ='Monthly Totals'!C7+'Monthly Totals'!F7+'Monthly Totals'!I7+'Monthly Totals'!L7+'Monthly Totals'!O7+'Monthly Totals'!R7+'Monthly Totals'!C29+'Monthly Totals'!F29+'Monthly Totals'!I29+'Monthly Totals'!L29+'Monthly Totals'!O29+'Monthly Totals'!R29 -> 49751 | F8: Total Field | G8: =C8/12 -> 4145.9167 | J8: Total Field | K8: =C8 / 52 -> 956.75 | N8: Total Field | O8: =C8 / 365 -> 136.30411 | R8: PM | S8: ='Occupancy Report Summarised'!L5+'Occupancy Report Summarised'!L9+'Occupancy Report Summarised'!L13+'Occupancy Report Summarised'!L17+'Occupancy Report Summarised'!L21+'Occupancy Report Summarised'!L25+'Occupancy Report Summarised'!L29+'Occupancy Report Summarised'!L33+'Occupancy Report Summarised'!L37+'Occupancy Report Summarised'!L41+'Occupancy Report Summarised'!L45+'Occupancy Report Summarised'!L49 -> 22666 | T8: ='Occupancy Report Summarised'!M5+'Occupancy Report Summarised'!M9+'Occupancy Report Summarised'!M13+'Occupancy Report Summarised'!M17+'Occupancy Report Summarised'!M21+'Occupancy Report Summarised'!M25+'Occupancy Report Summarised'!M29+'Occupancy Report Summarised'!M33+'Occupancy Report Summarised'!M37+'Occupancy Report Summarised'!M41+'Occupancy Report Summarised'!M45+'Occupancy Report Summarised'!M49 -> 31538 | U8: =SUM(S8/T8) -> 0.71868857
B9: Guests | C9: ='Monthly Totals'!C8+'Monthly Totals'!F8+'Monthly Totals'!I8+'Monthly Totals'!L8+'Monthly Totals'!O8+'Monthly Totals'!R8+'Monthly Totals'!C30+'Monthly Totals'!F30+'Monthly Totals'!I30+'Monthly Totals'!L30+'Monthly Totals'!O30+'Monthly Totals'!R30 -> 8588 | F9: Guests | G9: =C9/12 -> 715.66667 | J9: Guests | K9: =C9 / 52 -> 165.15385 | N9: Guests | O9: =C9 / 365 -> 23.528767 | R9: Total | S9: =SUM(S7:S8) -> 49751 | T9: =SUM(T7:T8) -> 64852 | U9: =SUM(S9/T9) -> 0.76714673
B10: Member / Guest Ratio | C10: =SUM(C9/C8) -> 0.17261965 | F10: Member / Guest Ratio | G10: =C10/12 -> 0.01438497 | J10: Member / Guest Ratio | K10: =C10 / 52 -> 0.0033196086 | N10: Member / Guest Ratio | O10: =C10 / 365 -> 0.00047293054
B11: Member Play | C11: ='Monthly Totals'!C10+'Monthly Totals'!F10+'Monthly Totals'!I10+'Monthly Totals'!L10+'Monthly Totals'!O10+'Monthly Totals'!R10+'Monthly Totals'!C32+'Monthly Totals'!F32+'Monthly Totals'!I32+'Monthly Totals'!L32+'Monthly Totals'!O32+'Monthly Totals'!R32 -> 40479 | F11: Member Play | G11: =C11/12 -> 3373.25 | J11: Member Play | K11: =C11 / 52 -> 778.44231 | N11: Member Play | O11: =C11 / 365 -> 110.90137
B12: Manger Intro | C12: ='Monthly Totals'!C11+'Monthly Totals'!F11+'Monthly Totals'!I11+'Monthly Totals'!L11+'Monthly Totals'!O11+'Monthly Totals'!R11+'Monthly Totals'!C33+'Monthly Totals'!F33+'Monthly Totals'!I33+'Monthly Totals'!L33+'Monthly Totals'!O33+'Monthly Totals'!R33 -> 43 | F12: Manger Intro | G12: =C12/12 -> 3.5833333 | J12: Manger Intro | K12: =C12 / 52 -> 0.82692308 | N12: Manger Intro | O12: =C12 / 365 -> 0.11780822
B13: Interstate | C13: ='Monthly Totals'!C12+'Monthly Totals'!F12+'Monthly Totals'!I12+'Monthly Totals'!L12+'Monthly Totals'!O12+'Monthly Totals'!R12+'Monthly Totals'!C34+'Monthly Totals'!F34+'Monthly Totals'!I34+'Monthly Totals'!L34+'Monthly Totals'!O34+'Monthly Totals'!R34 -> 174 | F13: Interstate | G13: =C13/12 -> 14.5 | J13: Interstate | K13: =C13 / 52 -> 3.3461538 | N13: Interstate | O13: =C13 / 365 -> 0.47671233
B14: International | C14: ='Monthly Totals'!C13+'Monthly Totals'!F13+'Monthly Totals'!I13+'Monthly Totals'!L13+'Monthly Totals'!O13+'Monthly Totals'!R13+'Monthly Totals'!C35+'Monthly Totals'!F35+'Monthly Totals'!I35+'Monthly Totals'!L35+'Monthly Totals'!O35+'Monthly Totals'!R35 -> 508 | F14: International | G14: =C14/12 -> 42.333333 | J14: International | K14: =C14 / 52 -> 9.7692308 | N14: International | O14: =C14 / 365 -> 1.3917808
B15: Industry Guest | C15: ='Monthly Totals'!C14+'Monthly Totals'!F14+'Monthly Totals'!I14+'Monthly Totals'!L14+'Monthly Totals'!O14+'Monthly Totals'!R14+'Monthly Totals'!C36+'Monthly Totals'!F36+'Monthly Totals'!I36+'Monthly Totals'!L36+'Monthly Totals'!O36+'Monthly Totals'!R36 -> 39 | F15: Industry Guest | G15: =C15/12 -> 3.25 | J15: Industry Guest | K15: =C15 / 52 -> 0.75 | N15: Industry Guest | O15: =C15 / 365 -> 0.10684932
B16: Member Intro | C16: ='Monthly Totals'!C15+'Monthly Totals'!F15+'Monthly Totals'!I15+'Monthly Totals'!L15+'Monthly Totals'!O15+'Monthly Totals'!R15+'Monthly Totals'!C37+'Monthly Totals'!F37+'Monthly Totals'!I37+'Monthly Totals'!L37+'Monthly Totals'!O37+'Monthly Totals'!R37 -> 3307 | F16: Member Intro | G16: =C16/12 -> 275.58333 | J16: Member Intro | K16: =C16 / 52 -> 63.596154 | N16: Member Intro | O16: =C16 / 365 -> 9.060274
B17: Member Guest Unaccompanied | C17: ='Monthly Totals'!C16+'Monthly Totals'!F16+'Monthly Totals'!I16+'Monthly Totals'!L16+'Monthly Totals'!O16+'Monthly Totals'!R16+'Monthly Totals'!C38+'Monthly Totals'!F38+'Monthly Totals'!I38+'Monthly Totals'!L38+'Monthly Totals'!O38+'Monthly Totals'!R38 -> 36 | F17: Member Guest Unaccompanied | G17: =C17/12 -> 3 | J17: Member Guest Unaccompanied | K17: =C17 / 52 -> 0.69230769 | N17: Member Guest Unaccompanied | O17: =C17 / 365 -> 0.098630137
B18: Corporate | C18: ='Monthly Totals'!C17+'Monthly Totals'!F17+'Monthly Totals'!I17+'Monthly Totals'!L17+'Monthly Totals'!O17+'Monthly Totals'!R17+'Monthly Totals'!C39+'Monthly Totals'!F39+'Monthly Totals'!I39+'Monthly Totals'!L39+'Monthly Totals'!O39+'Monthly Totals'!R39 -> 2598 | F18: Corporate | G18: =C18/12 -> 216.5 | J18: Corporate | K18: =C18 / 52 -> 49.961538 | N18: Corporate | O18: =C18 / 365 -> 7.1178082
B19: Non Playing | C19: ='Monthly Totals'!C19+'Monthly Totals'!F19+'Monthly Totals'!I19+'Monthly Totals'!L19+'Monthly Totals'!O19+'Monthly Totals'!R19+'Monthly Totals'!C41+'Monthly Totals'!F41+'Monthly Totals'!I41+'Monthly Totals'!L41+'Monthly Totals'!O41+'Monthly Totals'!R41 -> 404 | F19: Non Playing | G19: =C19/12 -> 33.666667 | J19: Non Playing | K19: =C19 / 52 -> 7.7692308 | N19: Non Playing | O19: =C19 / 365 -> 1.1068493
B20: Voucher | C20: ='Monthly Totals'!C20+'Monthly Totals'!F20+'Monthly Totals'!I20+'Monthly Totals'!L20+'Monthly Totals'!O20+'Monthly Totals'!R20+'Monthly Totals'!C42+'Monthly Totals'!F42+'Monthly Totals'!I42+'Monthly Totals'!L42+'Monthly Totals'!O42+'Monthly Totals'!R42 -> 522 | F20: Voucher | G20: =C20/12 -> 43.5 | J20: Voucher | K20: =C20 / 52 -> 10.038462 | N20: Voucher | O20: =C20 / 365 -> 1.430137
B21: Reciprocal | C21: ='Monthly Totals'!C21+'Monthly Totals'!F21+'Monthly Totals'!I21+'Monthly Totals'!L21+'Monthly Totals'!O21+'Monthly Totals'!R21+'Monthly Totals'!C43+'Monthly Totals'!F43+'Monthly Totals'!I43+'Monthly Totals'!L43+'Monthly Totals'!O43+'Monthly Totals'!R43 -> 879 | F21: Reciprocal | G21: =C21/12 -> 73.25 | J21: Reciprocal | K21: =C21 / 52 -> 16.903846 | N21: Reciprocal | O21: =C21 / 365 -> 2.4082192
B22: Competition | C22: ='Monthly Totals'!C22+'Monthly Totals'!F22+'Monthly Totals'!I22+'Monthly Totals'!L22+'Monthly Totals'!O22+'Monthly Totals'!R22+'Monthly Totals'!C44+'Monthly Totals'!F44+'Monthly Totals'!I44+'Monthly Totals'!L44+'Monthly Totals'!O44+'Monthly Totals'!R44 -> 26827 | F22: Competition | G22: =C22/12 -> 2235.5833 | J22: Competition | K22: =C22 / 52 -> 515.90385 | N22: Competition | O22: =C22 / 365 -> 73.49863

Sheet Occupancy Report
B2: January | D2: Bookings | E2: Spots Available | F2: Occupancy | G2: Notes | I2: Feburary | K2: Bookings | L2: Spots Available | M2: Occupancy | N2: Notes | P2: March | R2: Bookings | S2: Spots Available | T2: Occupancy | U2: Notes
B4: Monday | C4: AM | D4: =GETPIVOTDATA("Sum of AM FIELD",'Pivot Table'!$A$4,"DAY","Mon") -> 358 | E4: =SUM(104+120+96+112+96) -> 528 | F4: =SUM(D4/E4) -> 0.6780303 | I4: Monday | J4: AM | K4: =GETPIVOTDATA("Sum of AM FIELD",'Pivot Table'!$A$16,"DAY","Mon") -> 197 | L4: =SUM(92+0+92+92) -> 276 | M4: =SUM(K4/L4) -> 0.71376812 | P4: Monday | Q4: AM | R4: =GETPIVOTDATA("Sum of AM FIELD",'Pivot Table'!$A$28,"DAY","Mon") -> 241 | S4: =SUM(92+104+80+0) -> 276 | T4: =SUM(R4/S4) -> 0.87318841
B5: Monday | C5: PM | D5: =GETPIVOTDATA("Sum of PM FIELD",'Pivot Table'!$A$4,"DAY","Mon") -> 263 | E5: =SUM(56+104+96+96+96) -> 448 | F5: =SUM(D5/E5) -> 0.58705357 | I5: Monday | J5: PM | K5: =GETPIVOTDATA("Sum of PM FIELD",'Pivot Table'!$A$16,"DAY","Mon") -> 296 | L5: =SUM(96+96+96+96) -> 384 | M5: =SUM(K5/L5) -> 0.77083333 | P5: Monday | Q5: PM | R5: =GETPIVOTDATA("Sum of PM FIELD",'Pivot Table'!$A$28,"DAY","Mon") -> 328 | S5: =SUM(88+96+84+88) -> 356 | T5: =SUM(R5/S5) -> 0.92134831
B6: Total Occupancy | D6: =SUM(D3:D5) -> 621 | E6: =SUM(E3:E5) -> 976 | F6: =SUM(D6/E6) -> 0.63627049 | I6: Total Occupancy | K6: =SUM(K3:K5) -> 493 | L6: =SUM(L3:L5) -> 660 | M6: =SUM(K6/L6) -> 0.7469697 | P6: Total Occupancy | R6: =SUM(R3:R5) -> 569 | S6: =SUM(S4:S5) -> 632 | T6: =SUM(R6/S6) -> 0.90031646
B8: Tuesday | C8: AM | D8: =GETPIVOTDATA("Sum of AM FIELD",'Pivot Table'!$A$4,"DAY","Tue") -> 378 | E8: =SUM(120+120+112+116+116) -> 584 | F8: =SUM(D8/E8) -> 0.64726027 | I8: Tuesday | J8: AM | K8: =GETPIVOTDATA("Sum of AM FIELD",'Pivot Table'!$A$16,"DAY","Tue") -> 425 | L8: =SUM(140+112+112+112) -> 476 | M8: =SUM(K8/L8) -> 0.89285714 | P8: Tuesday | Q8: AM | R8: =GETPIVOTDATA("Sum of AM FIELD",'Pivot Table'!$A$28,"DAY","Tue") -> 369 | S8: =SUM(112+112+112+96) -> 432 | T8: =SUM(R8/S8) -> 0.85416667
B9: Tuesday | C9: PM | D9: =GETPIVOTDATA("Sum of PM FIELD",'Pivot Table'!$A$4,"DAY","Tue") -> 96 | E9: =SUM(80+80+80+80+80) -> 400 | F9: =SUM(D9/E9) -> 0.24 | I9: Tuesday | J9: PM | K9: =GETPIVOTDATA("Sum of PM FIELD",'Pivot Table'!$A$16,"DAY","Tue") -> 168 | L9: =SUM(40+76+80+80) -> 276 | M9: =SUM(K9/L9) -> 0.60869565 | P9: Tuesday | Q9: PM | R9: =GETPIVOTDATA("Sum of PM FIELD",'Pivot Table'!$A$28,"DAY","Tue") -> 129 | S9: =SUM(80+80+80+44) -> 284 | T9: =SUM(R9/S9) -> 0.45422535
B10: Total Occupancy | D10: =SUM(D7:D9) -> 474 | E10: =SUM(E7:E9) -> 984 | F10: =SUM(D10/E10) -> 0.48170732 | I10: Total Occupancy | K10: =SUM(K7:K9) -> 593 | L10: =SUM(L7:L9) -> 752 | M10: =SUM(K10/L10) -> 0.78856383 | P10: Total Occupancy | R10: =SUM(R7:R9) -> 498 | S10: =SUM(S7:S9) -> 716 | T10: =SUM(R10/S10) -> 0.69553073
B12: Wednesday | C12: AM | D12: =GETPIVOTDATA("Sum of AM FIELD",'Pivot Table'!$A$4,"DAY","Wed") -> 299 | E12: =SUM(120+120+104+88) -> 432 | F12: =SUM(D12/E12) -> 0.69212963 | I12: Wednesday | J12: AM | K12: =GETPIVOTDATA("Sum of AM FIELD",'Pivot Table'!$A$16,"DAY","Wed") -> 315 | L12: =SUM(120+120+120+100) -> 460 | M12: =SUM(K12/L12) -> 0.68478261 | P12: Wednesday | Q12: AM | R12: =GETPIVOTDATA("Sum of AM FIELD",'Pivot Table'!$A$28,"DAY","Wed") -> 310 | S12: =SUM(120+120+100+80+76) -> 496 | T12: =SUM(R12/S12) -> 0.625
B13: Wednesday | C13: PM | D13: =GETPIVOTDATA("Sum of PM FIELD",'Pivot Table'!$A$4,"DAY","Wed") -> 317 | E13: =SUM(104+104+104+172) -> 484 | F13: =SUM(D13/E13) -> 0.65495868 | I13: Wednesday | J13: PM | K13: =GETPIVOTDATA("Sum of PM FIELD",'Pivot Table'!$A$16,"DAY","Wed") -> 277 | L13: =SUM(104+100+100+104) -> 408 | M13: =SUM(K13/L13) -> 0.67892157 | P13: Wednesday | Q13: PM | R13: =GETPIVOTDATA("Sum of PM FIELD",'Pivot Table'!$A$28,"DAY","Wed") -> 377 | S13: =SUM(108+88+80+82+92) -> 450 | T13: =SUM(R13/S13) -> 0.83777778
B14: Total Occupancy | D14: =SUM(D11:D13) -> 616 | E14: =SUM(E11:E13) -> 916 | F14: =SUM(D14/E14) -> 0.67248908 | I14: Total Occupancy | K14: =SUM(K11:K13) -> 592 | L14: =SUM(L11:L13) -> 868 | M14: =SUM(K14/L14) -> 0.68202765 | P14: Total Occupancy | R14: =SUM(R11:R13) -> 687 | S14: =SUM(S11:S13) -> 946 | T14: =SUM(R14/S14) -> 0.72621564
B16: Thursday | C16: AM | D16: =GETPIVOTDATA("Sum of AM FIELD",'Pivot Table'!$A$4,"DAY","Thu") -> 337 | E16: =SUM(88+84+88+104) -> 364 | F16: =SUM(D16/E16) -> 0.92582418 | I16: Thursday | J16: AM | K16: =GETPIVOTDATA("Sum of AM FIELD",'Pivot Table'!$A$16,"DAY","Thu") -> 335 | L16: =SUM(88+88+88+88) -> 352 | M16: =SUM(K16/L16) -> 0.95170455 | P16: Thursday | Q16: AM | R16: =GETPIVOTDATA("Sum of AM FIELD",'Pivot Table'!$A$28,"DAY","Thu") -> 317 | S16: =SUM(80+72+88+64+96) -> 400 | T16: =SUM(R16/S16) -> 0.7925
B17: Thursday | C17: PM | D17: =GETPIVOTDATA("Sum of PM FIELD",'Pivot Table'!$A$4,"DAY","Thu") -> 337 | E17: =SUM(96+96+96+96) -> 384 | F17: =SUM(D17/E17) -> 0.87760417 | I17: Thursday | J17: PM | K17: =GETPIVOTDATA("Sum of PM FIELD",'Pivot Table'!$A$16,"DAY","Thu") -> 239 | L17: =SUM(96+96+0+96) -> 288 | M17: =SUM(K17/L17) -> 0.82986111 | P17: Thursday | Q17: PM | R17: =GETPIVOTDATA("Sum of PM FIELD",'Pivot Table'!$A$28,"DAY","Thu") -> 405 | S17: =SUM(96+96+96+96+96) -> 480 | T17: =SUM(R17/S17) -> 0.84375
B18: Total Occupancy | D18: =SUM(D15:D17) -> 674 | E18: =SUM(E15:E17) -> 748 | F18: =SUM(D18/E18) -> 0.90106952 | I18: Total Occupancy | K18: =SUM(K15:K17) -> 574 | L18: =SUM(L15:L17) -> 640 | M18: =SUM(K18/L18) -> 0.896875 | P18: Total Occupancy | R18: =SUM(R15:R17) -> 722 | S18: =SUM(S15:S17) -> 880 | T18: =SUM(R18/S18) -> 0.82045455
B20: Friday | C20: AM | D20: =GETPIVOTDATA("Sum of AM FIELD",'Pivot Table'!$A$4,"DAY","Fri") -> 427 | E20: =SUM(120+120+120+120) -> 480 | F20: =SUM(D20/E20) -> 0.88958333 | I20: Friday | J20: AM | K20: =GETPIVOTDATA("Sum of AM FIELD",'Pivot Table'!$A$16,"DAY","Fri") -> 301 | L20: =SUM(120+88+88+88) -> 384 | M20: =SUM(K20/L20) -> 0.78385417 | P20: Friday | Q20: AM | R20: =GETPIVOTDATA("Sum of AM FIELD",'Pivot Table'!$A$28,"DAY","Fri") -> 401 | S20: =SUM(80+80+56+108+108) -> 432 | T20: =SUM(R20/S20) -> 0.92824074
B21: Friday | C21: PM | D21: =GETPIVOTDATA("Sum of PM FIELD",'Pivot Table'!$A$4,"DAY","Fri") -> 325 | E21: =SUM(104+104+104+104) -> 416 | F21: =SUM(D21/E21) -> 0.78125 | I21: Friday | J21: PM | K21: =GETPIVOTDATA("Sum of PM FIELD",'Pivot Table'!$A$16,"DAY","Fri") -> 329 | L21: =SUM(104+164+104+152) -> 524 | M21: =SUM(K21/L21) -> 0.6278626 | P21: Friday | Q21: PM | R21: =GETPIVOTDATA("Sum of PM FIELD",'Pivot Table'!$A$28,"DAY","Fri") -> 499 | S21: =SUM(188+188+80+76+88) -> 620 | T21: =SUM(R21/S21) -> 0.80483871 | U21: Twlights
B22: Total Occupancy | D22: =SUM(D19:D21) -> 752 | E22: =SUM(E19:E21) -> 896 | F22: =SUM(D22/E22) -> 0.83928571 | I22: Total Occupancy | K22: =SUM(K19:K21) -> 630 | L22: =SUM(L19:L21) -> 908 | M22: =SUM(K22/L22) -> 0.6938326 | P22: Total Occupancy | R22: =SUM(R19:R21) -> 900 | S22: =SUM(S19:S21) -> 1052 | T22: =SUM(R22/S22) -> 0.85551331
B24: Saturday | C24: AM | D24: =GETPIVOTDATA("Sum of AM FIELD",'Pivot Table'!$A$4,"DAY","Sat") -> 364 | E24: =SUM(104+104+104+100) -> 412 | F24: =SUM(D24/E24) -> 0.88349515 | I24: Saturday | J24: AM | K24: =GETPIVOTDATA("Sum of AM FIELD",'Pivot Table'!$A$16,"DAY","Sat") -> 322 | L24: =SUM(104+104+68+104) -> 380 | M24: =SUM(K24/L24) -> 0.84736842 | P24: Saturday | Q24: AM | R24: =GETPIVOTDATA("Sum of AM FIELD",'Pivot Table'!$A$28,"DAY","Sat") -> 325 | S24: =SUM(104+48+104+96) -> 352 | T24: =SUM(R24/S24) -> 0.92329545
B25: Saturday | C25: PM | D25: =GETPIVOTDATA("Sum of PM FIELD",'Pivot Table'!$A$4,"DAY","Sat") -> 121 | E25: =SUM(96+0+60+56) -> 212 | F25: =SUM(D25/E25) -> 0.57075472 | I25: Saturday | J25: PM | K25: =GETPIVOTDATA("Sum of PM FIELD",'Pivot Table'!$A$16,"DAY","Sat") -> 303 | L25: =SUM(96+88+96+96) -> 376 | M25: =SUM(K25/L25) -> 0.80585106 | P25: Saturday | Q25: PM | R25: =GETPIVOTDATA("Sum of PM FIELD",'Pivot Table'!$A$28,"DAY","Sat") -> 190 | S25: =SUM(96+60+96+72) -> 324 | T25: =SUM(R25/S25) -> 0.58641975
B26: Total Occupancy | D26: =SUM(D23:D25) -> 485 | E26: =SUM(E23:E25) -> 624 | F26: =SUM(D26/E26) -> 0.77724359 | I26: Total Occupancy | K26: =SUM(K23:K25) -> 625 | L26: =SUM(L23:L25) -> 756 | M26: =SUM(K26/L26) -> 0.82671958 | P26: Total Occupancy | R26: =SUM(R23:R25) -> 515 | S26: =SUM(S23:S25) -> 676 | T26: =SUM(R26/S26) -> 0.76183432
B28: Sunday | C28: AM | D28: =GETPIVOTDATA("Sum of AM FIELD",'Pivot Table'!$A$4,"DAY","Sun") -> 451 | E28: =SUM(104+104+104+104+104) -> 520 | F28: =SUM(D28/E28) -> 0.86730769 | I28: Sunday | J28: AM | K28: =GETPIVOTDATA("Sum of AM FIELD",'Pivot Table'!$A$16,"DAY","Sun") -> 395 | L28: =SUM(104+104+104+104) -> 416 | M28: =SUM(K28/L28) -> 0.94951923 | P28: Sunday | Q28: AM | R28: =GETPIVOTDATA("Sum of AM FIELD",'Pivot Table'!$A$28,"DAY","Sun") -> 370 | S28: =SUM(104+104+104+96) -> 408 | T28: =SUM(R28/S28) -> 0.90686275
B29: Sunday | C29: PM | D29: =GETPIVOTDATA("Sum of PM FIELD",'Pivot Table'!$A$4,"DAY","Sun") -> 314 | E29: =SUM(96+80+92+96+96) -> 460 | F29: =SUM(D29/E29) -> 0.6826087 | I29: Sunday | J29: PM | K29: =GETPIVOTDATA("Sum of PM FIELD",'Pivot Table'!$A$16,"DAY","Sun") -> 386 | L29: =SUM(108+108+104+104) -> 424 | M29: =SUM(K29/L29) -> 0.91037736 | P29: Sunday | Q29: PM | R29: =GETPIVOTDATA("Sum of PM FIELD",'Pivot Table'!$A$28,"DAY","Sun") -> 374 | S29: =SUM(108+96+108+108) -> 420 | T29: =SUM(R29/S29) -> 0.89047619
B30: Total Occupancy | D30: =SUM(D27:D29) -> 765 | E30: =SUM(E27:E29) -> 980 | F30: =SUM(D30/E30) -> 0.78061224 | I30: Total Occupancy | K30: =SUM(K27:K29) -> 781 | L30: =SUM(L27:L29) -> 840 | M30: =SUM(K30/L30) -> 0.9297619 | P30: Total Occupancy | R30: =SUM(R27:R29) -> 744 | S30: =SUM(S27:S29) -> 828 | T30: =SUM(R30/S30) -> 0.89855072
B33: April | D33: Bookings | E33: Spots Available | F33: Occupancy | G33: Notes | I33: May | K33: Bookings | L33: Spots Available | M33: Occupancy | N33: Notes | P33: June | R33: Bookings | S33: Spots Available | T33: Occupancy | U33: Notes
B35: Monday | C35: AM | D35: =GETPIVOTDATA("Sum of AM FIELD",'Pivot Table'!$A$40,"DAY","Mon") -> 240 | E35: =SUM(88+104+0+84) -> 276 | F35: =SUM(D35/E35) -> 0.86956522 | I35: Monday | J35: AM | K35: =GETPIVOTDATA("Sum of AM FIELD",'Pivot Table'!$A$52,"DAY","Mon") -> 253 | L35: =SUM(88+68+88+0+80) -> 324 | M35: =SUM(K35/L35) -> 0.7808642 | P35: Monday | Q35: AM | R35: =GETPIVOTDATA("Sum of AM FIELD",'Pivot Table'!$A$64,"DAY","Mon") -> 152 | S35: =0+96+92+80 -> 268 | T35: =SUM(R35/S35) -> 0.56716418
B36: Monday | C36: PM | D36: =GETPIVOTDATA("Sum of PM FIELD",'Pivot Table'!$A$40,"DAY","Mon") -> 289 | E36: =SUM(80+88+88+80) -> 336 | F36: =SUM(D36/E36) -> 0.86011905 | I36: Monday | J36: PM | K36: =GETPIVOTDATA("Sum of PM FIELD",'Pivot Table'!$A$52,"DAY","Mon") -> 327 | L36: =SUM(88+80+80+80+80) -> 408 | M36: =SUM(K36/L36) -> 0.80147059 | P36: Monday | Q36: PM | R36: =GETPIVOTDATA("Sum of PM FIELD",'Pivot Table'!$A$64,"DAY","Mon") -> 243 | S36: =80+88+80+80 -> 328 | T36: =SUM(R36/S36) -> 0.74085366
B37: Total Occupancy | D37: =SUM(D34:D36) -> 529 | E37: =SUM(E34:E36) -> 612 | F37: =SUM(D37/E37) -> 0.86437908 | I37: Total Occupancy | K37: =SUM(K34:K36) -> 580 | L37: =SUM(L34:L36) -> 732 | M37: =SUM(K37/L37) -> 0.79234973 | P37: Total Occupancy | R37: =SUM(R34:R36) -> 395 | S37: 596 | T37: =SUM(R37/S37) -> 0.66275168
B39: Tuesday | C39: AM | D39: =GETPIVOTDATA("Sum of AM FIELD",'Pivot Table'!$A$40,"DAY","Tue") -> 357 | E39: =SUM(112+112+112+104) -> 440 | F39: =SUM(D39/E39) -> 0.81136364 | I39: Tuesday | J39: AM | K39: =GETPIVOTDATA("Sum of AM FIELD",'Pivot Table'!$A$52,"DAY","Tue") -> 432 | L39: =SUM(112+112+100+112+88) -> 524 | M39: =SUM(K39/L39) -> 0.82442748 | P39: Tuesday | Q39: AM | R39: =GETPIVOTDATA("Sum of AM FIELD",'Pivot Table'!$A$64,"DAY","Tue") -> 277 | S39: =112+116+112+80 -> 420 | T39: =SUM(R39/S39) -> 0.65952381
B40: Tuesday | C40: PM | D40: =GETPIVOTDATA("Sum of PM FIELD",'Pivot Table'!$A$40,"DAY","Tue") -> 200 | E40: =SUM(80+80+80+88) -> 328 | F40: =SUM(D40/E40) -> 0.6097561 | I40: Tuesday | J40: PM | K40: =GETPIVOTDATA("Sum of PM FIELD",'Pivot Table'!$A$52,"DAY","Tue") -> 143 | L40: =SUM(80+80+0+80+80) -> 320 | M40: =SUM(K40/L40) -> 0.446875 | P40: Tuesday | Q40: PM | R40: =GETPIVOTDATA("Sum of PM FIELD",'Pivot Table'!$A$64,"DAY","Tue") -> 132 | S40: =80+80+80+80 -> 320 | T40: =SUM(R40/S40) -> 0.4125
B41: Total Occupancy | D41: =SUM(D38:D40) -> 557 | E41: =SUM(E38:E40) -> 768 | F41: =SUM(D41/E41) -> 0.72526042 | I41: Total Occupancy | K41: =SUM(K38:K40) -> 575 | L41: =SUM(L38:L40) -> 844 | M41: =SUM(K41/L41) -> 0.68127962 | P41: Total Occupancy | R41: =SUM(R38:R40) -> 409 | S41: 748 | T41: =SUM(R41/S41) -> 0.54679144
B43: Wednesday | C43: AM | D43: =GETPIVOTDATA("Sum of AM FIELD",'Pivot Table'!$A$40,"DAY","Wed") -> 249 | E43: =SUM(96+96+72+108) -> 372 | F43: =SUM(D43/E43) -> 0.66935484 | I43: Wednesday | J43: AM | K43: =GETPIVOTDATA("Sum of AM FIELD",'Pivot Table'!$A$52,"DAY","Wed") -> 369 | L43: =SUM(96+108+84+108+80) -> 476 | M43: =SUM(K43/L43) -> 0.77521008 | P43: Wednesday | Q43: AM | R43: =GETPIVOTDATA("Sum of AM FIELD",'Pivot Table'!$A$64,"DAY","Wed") -> 134 | S43: =80+60+48+108 -> 296 | T43: =SUM(R43/S43) -> 0.4527027
B44: Wednesday | C44: PM | D44: =GETPIVOTDATA("Sum of PM FIELD",'Pivot Table'!$A$40,"DAY","Wed") -> 268 | E44: =SUM(96+76+100+84) -> 356 | F44: =SUM(D44/E44) -> 0.75280899 | I44: Wednesday | J44: PM | K44: =GETPIVOTDATA("Sum of PM FIELD",'Pivot Table'!$A$52,"DAY","Wed") -> 269 | L44: =SUM(100+88+72+88+48) -> 396 | M44: =SUM(K44/L44) -> 0.67929293 | P44: Wednesday | Q44: PM | R44: =GETPIVOTDATA("Sum of PM FIELD",'Pivot Table'!$A$64,"DAY","Wed") -> 244 | S44: =108+88+80+88 -> 364 | T44: =SUM(R44/S44) -> 0.67032967
B45: Total Occupancy | D45: =SUM(D42:D44) -> 517 | E45: =SUM(E42:E44) -> 728 | F45: =SUM(D45/E45) -> 0.71016484 | I45: Total Occupancy | K45: =SUM(K42:K44) -> 638 | L45: =SUM(L42:L44) -> 872 | M45: =SUM(K45/L45) -> 0.73165138 | P45: Total Occupancy | R45: =SUM(R42:R44) -> 378 | S45: 660 | T45: =SUM(R45/S45) -> 0.57272727
B47: Thursday | C47: AM | D47: =GETPIVOTDATA("Sum of AM FIELD",'Pivot Table'!$A$40,"DAY","Thu") -> 309 | E47: =SUM(88+80+80+72) -> 320 | F47: =SUM(D47/E47) -> 0.965625 | I47: Thursday | J47: AM | K47: =GETPIVOTDATA("Sum of AM FIELD",'Pivot Table'!$A$52,"DAY","Thu") -> 284 | L47: =SUM(80+80+80+80) -> 320 | M47: =SUM(K47/L47) -> 0.8875 | P47: Thursday | Q47: AM | R47: =GETPIVOTDATA("Sum of AM FIELD",'Pivot Table'!$A$64,"DAY","Thu") -> 341 | S47: =80+68+76+76+68 -> 368 | T47: =SUM(R47/S47) -> 0.92663043
B48: Thursday | C48: PM | D48: =GETPIVOTDATA("Sum of PM FIELD",'Pivot Table'!$A$40,"DAY","Thu") -> 332 | E48: =SUM(88+96+104+96) -> 384 | F48: =SUM(D48/E48) -> 0.86458333 | I48: Thursday | J48: PM | K48: =GETPIVOTDATA("Sum of PM FIELD",'Pivot Table'!$A$52,"DAY","Thu") -> 268 | L48: =SUM(96+96+96+96) -> 384 | M48: =SUM(K48/L48) -> 0.69791667 | P48: Thursday | Q48: PM | R48: =GETPIVOTDATA("Sum of PM FIELD",'Pivot Table'!$A$64,"DAY","Thu") -> 399 | S48: =96+96+96+88+88 -> 464 | T48: =SUM(R48/S48) -> 0.85991379
B49: Total Occupancy | D49: =SUM(D46:D48) -> 641 | E49: =SUM(E46:E48) -> 704 | F49: =SUM(D49/E49) -> 0.91051136 | I49: Total Occupancy | K49: =SUM(K46:K48) -> 552 | L49: =SUM(L46:L48) -> 704 | M49: =SUM(K49/L49) -> 0.78409091 | P49: Total Occupancy | R49: =SUM(R46:R48) -> 740 | S49: 840 | T49: =SUM(R49/S49) -> 0.88095238
B51: Friday | C51: AM | D51: =GETPIVOTDATA("Sum of AM FIELD",'Pivot Table'!$A$40,"DAY","Fri") -> 358 | E51: =SUM(104+108+80+108) -> 400 | F51: =SUM(D51/E51) -> 0.895 | I51: Friday | J51: AM | K51: =GETPIVOTDATA("Sum of AM FIELD",'Pivot Table'!$A$52,"DAY","Fri") -> 356 | L51: =SUM(108+108+80+80) -> 376 | M51: =SUM(K51/L51) -> 0.94680851 | P51: Friday | Q51: AM | R51: =GETPIVOTDATA("Sum of AM FIELD",'Pivot Table'!$A$64,"DAY","Fri") -> 372 | S51: =88+100+68+108+108 -> 472 | T51: =SUM(R51/S51) -> 0.78813559
B52: Friday | C52: PM | D52: =GETPIVOTDATA("Sum of PM FIELD",'Pivot Table'!$A$40,"DAY","Fri") -> 257 | E52: =SUM(72+88+56+84) -> 300 | F52: =SUM(D52/E52) -> 0.85666667 | I52: Friday | J52: PM | K52: =GETPIVOTDATA("Sum of PM FIELD",'Pivot Table'!$A$52,"DAY","Fri") -> 198 | L52: =SUM(72+88+80+88) -> 328 | M52: =SUM(K52/L52) -> 0.60365854 | P52: Friday | Q52: PM | R52: =GETPIVOTDATA("Sum of PM FIELD",'Pivot Table'!$A$64,"DAY","Fri") -> 328 | S52: =88+76+80+88+88 -> 420 | T52: =SUM(R52/S52) -> 0.78095238
B53: Total Occupancy | D53: =SUM(D50:D52) -> 615 | E53: =SUM(E50:E52) -> 700 | F53: =SUM(D53/E53) -> 0.87857143 | I53: Total Occupancy | K53: =SUM(K50:K52) -> 554 | L53: =SUM(L50:L52) -> 704 | M53: =SUM(K53/L53) -> 0.78693182 | P53: Total Occupancy | R53: =SUM(R50:R52) -> 700 | S53: 888 | T53: =SUM(R53/S53) -> 0.78828829
B55: Saturday | C55: AM | D55: =GETPIVOTDATA("Sum of AM FIELD",'Pivot Table'!$A$40,"DAY","Sat") -> 425 | E55: =SUM(92+92+104+104+68) -> 460 | F55: =SUM(D55/E55) -> 0.92391304 | I55: Saturday | J55: AM | K55: =GETPIVOTDATA("Sum of AM FIELD",'Pivot Table'!$A$52,"DAY","Sat") -> 312 | L55: =SUM(76+104+96+88) -> 364 | M55: =SUM(K55/L55) -> 0.85714286 | P55: Saturday | Q55: AM | R55: =GETPIVOTDATA("Sum of AM FIELD",'Pivot Table'!$A$64,"DAY","Sat") -> 304 | S55: =80+72+84+80 -> 316 | T55: =SUM(R55/S55) -> 0.96202532
B56: Saturday | C56: PM | D56: =GETPIVOTDATA("Sum of PM FIELD",'Pivot Table'!$A$40,"DAY","Sat") -> 222 | E56: =SUM(96+88+88+88+40) -> 400 | F56: =SUM(D56/E56) -> 0.555 | I56: Saturday | J56: PM | K56: =GETPIVOTDATA("Sum of PM FIELD",'Pivot Table'!$A$52,"DAY","Sat") -> 233 | L56: =SUM(92+88+88+52) -> 320 | M56: =SUM(K56/L56) -> 0.728125 | P56: Saturday | Q56: PM | R56: =GETPIVOTDATA("Sum of PM FIELD",'Pivot Table'!$A$64,"DAY","Sat") -> 220 | S56: =88+60+88+88 -> 324 | T56: =SUM(R56/S56) -> 0.67901235
...

Sheet Occupancy Report Summarised
B2: 2023 Totals (By Day) | D2: Bookings | E2: Spots Available | F2: Occupancy | G2: Notes | J2: 2023 Totals (By Month) | L2: Bookings | M2: Spots Available | N2: Occupancy | O2: Notes
B4: Monday | C4: AM | D4: ='Occupancy Report'!D4+'Occupancy Report'!K4+'Occupancy Report'!R4+'Occupancy Report'!D35+'Occupancy Report'!K35+'Occupancy Report'!R35+'Occupancy Report'!D66+'Occupancy Report'!K66+'Occupancy Report'!R66+'Occupancy Report'!D97+'Occupancy Report'!K97+'Occupancy Report'!R97 -> 2343 | E4: ='Occupancy Report'!E4+'Occupancy Report'!L4+'Occupancy Report'!S4+'Occupancy Report'!S35+'Occupancy Report'!L35+'Occupancy Report'!E35+'Occupancy Report'!E66+'Occupancy Report'!L66+'Occupancy Report'!S66+'Occupancy Report'!S97+'Occupancy Report'!L97+'Occupancy Report'!E97 -> 3466 | F4: =SUM(D4/E4) -> 0.67599538 | J4: January | K4: AM | L4: ='Occupancy Report'!D4+'Occupancy Report'!D8+'Occupancy Report'!D12+'Occupancy Report'!D16+'Occupancy Report'!D20+'Occupancy Report'!D24+'Occupancy Report'!D28 -> 2614 | M4: ='Occupancy Report'!E4+'Occupancy Report'!E8+'Occupancy Report'!E12+'Occupancy Report'!E16+'Occupancy Report'!E20+'Occupancy Report'!E24+'Occupancy Report'!E28 -> 3320 | N4: =SUM(L4/M4) -> 0.7873494
B5: Monday | C5: PM | D5: ='Occupancy Report'!D5+'Occupancy Report'!L5+'Occupancy Report'!R5+'Occupancy Report'!R36+'Occupancy Report'!K36+'Occupancy Report'!D36+'Occupancy Report'!D67+'Occupancy Report'!K67+'Occupancy Report'!R67+'Occupancy Report'!R98+'Occupancy Report'!K98+'Occupancy Report'!D98 -> 3329 | E5: ='Occupancy Report'!E5+'Occupancy Report'!L5+'Occupancy Report'!S4+'Occupancy Report'!S36+'Occupancy Report'!L36+'Occupancy Report'!E36+'Occupancy Report'!E67+'Occupancy Report'!L67+'Occupancy Report'!S67+'Occupancy Report'!S98+'Occupancy Report'!L98+'Occupancy Report'!E98 -> 4104 | F5: =SUM(D5/E5) -> 0.81115984 | J5: January | K5: PM | L5: ='Occupancy Report'!D5+'Occupancy Report'!D9+'Occupancy Report'!D13+'Occupancy Report'!D17+'Occupancy Report'!D21+'Occupancy Report'!D25+'Occupancy Report'!D29 -> 1773 | M5: ='Occupancy Report'!E5+'Occupancy Report'!E9+'Occupancy Report'!E13+'Occupancy Report'!E17+'Occupancy Report'!E21+'Occupancy Report'!E25+'Occupancy Report'!E29 -> 2804 | N5: =SUM(L5/M5) -> 0.63231098
B6: Total Monday Occupancy | D6: =SUM(D4:D5) -> 5672 | E6: =SUM(E4:E5) -> 7570 | F6: =SUM(D6/E6) -> 0.74927345 | J6: Total January Occupancy | L6: =SUM(L4:L5) -> 4387 | M6: =SUM(M4:M5) -> 6124 | N6: =SUM(L6/M6) -> 0.71636185
B8: Tuesday | C8: AM | D8: ='Occupancy Report'!D8+'Occupancy Report'!K8+'Occupancy Report'!R8+'Occupancy Report'!R39+'Occupancy Report'!K39+'Occupancy Report'!D39+'Occupancy Report'!D70+'Occupancy Report'!K70+'Occupancy Report'!R70+'Occupancy Report'!R101+'Occupancy Report'!L101+'Occupancy Report'!D101 -> 4480 | E8: ='Occupancy Report'!E8+'Occupancy Report'!L8+'Occupancy Report'!S8+'Occupancy Report'!S39+'Occupancy Report'!L39+'Occupancy Report'!E39+'Occupancy Report'!E70+'Occupancy Report'!L70+'Occupancy Report'!S70+'Occupancy Report'!S101+'Occupancy Report'!L101+'Occupancy Report'!E101 -> 5644 | F8: =SUM(D8/E8) -> 0.79376329 | J8: February | K8: AM | L8: ='Occupancy Report'!K4+'Occupancy Report'!K8+'Occupancy Report'!K12+'Occupancy Report'!K16+'Occupancy Report'!K20+'Occupancy Report'!K24+'Occupancy Report'!K28 -> 2290 | M8: ='Occupancy Report'!L4+'Occupancy Report'!L8+'Occupancy Report'!L12+'Occupancy Report'!L16+'Occupancy Report'!L20+'Occupancy Report'!L24+'Occupancy Report'!L28 -> 2744 | N8: =SUM(L8/M8) -> 0.8345481
B9: Tuesday | C9: PM | D9: ='Occupancy Report'!D9+'Occupancy Report'!K9+'Occupancy Report'!R9+'Occupancy Report'!R40+'Occupancy Report'!K40+'Occupancy Report'!D40+'Occupancy Report'!D71+'Occupancy Report'!K71+'Occupancy Report'!R71+'Occupancy Report'!R102+'Occupancy Report'!L102+'Occupancy Report'!D102 -> 1670 | E9: ='Occupancy Report'!E9+'Occupancy Report'!L9+'Occupancy Report'!S9+'Occupancy Report'!S40+'Occupancy Report'!L40+'Occupancy Report'!E40+'Occupancy Report'!E71+'Occupancy Report'!L71+'Occupancy Report'!S71+'Occupancy Report'!S102+'Occupancy Report'!L102+'Occupancy Report'!E102 -> 3720 | F9: =SUM(D9/E9) -> 0.44892473 | J9: February | K9: PM | L9: ='Occupancy Report'!K5+'Occupancy Report'!K9+'Occupancy Report'!K13+'Occupancy Report'!K17+'Occupancy Report'!K21+'Occupancy Report'!K25+'Occupancy Report'!K29 -> 1998 | M9: ='Occupancy Report'!L5+'Occupancy Report'!L9+'Occupancy Report'!L13+'Occupancy Report'!L17+'Occupancy Report'!L21+'Occupancy Report'!L25+'Occupancy Report'!L29 -> 2680 | N9: =SUM(L9/M9) -> 0.74552239
B10: Total Tuesday Occupancy | D10: =SUM(D8:D9) -> 6150 | E10: =SUM(E8:E9) -> 9364 | F10: =SUM(D10/E10) -> 0.65677061 | J10: Total February Occupancy | L10: =SUM(L8:L9) -> 4288 | M10: =SUM(M8:M9) -> 5424 | N10: =SUM(L10/M10) -> 0.79056047
B12: Wednesday | C12: AM | D12: ='Occupancy Report'!D12+'Occupancy Report'!K12+'Occupancy Report'!R12+'Occupancy Report'!R43+'Occupancy Report'!K43+'Occupancy Report'!D43+'Occupancy Report'!D74+'Occupancy Report'!K74+'Occupancy Report'!R74+'Occupancy Report'!R105+'Occupancy Report'!L105+'Occupancy Report'!D105 -> 3429 | E12: ='Occupancy Report'!E12+'Occupancy Report'!L12+'Occupancy Report'!S12+'Occupancy Report'!S43+'Occupancy Report'!L43+'Occupancy Report'!E43+'Occupancy Report'!E74+'Occupancy Report'!L74+'Occupancy Report'!S74+'Occupancy Report'!S105+'Occupancy Report'!L105+'Occupancy Report'!E105 -> 4848 | F12: =SUM(D12/E12) -> 0.70730198 | J12: March | K12: AM | L12: =GETPIVOTDATA("Sum of AM FIELD",'Pivot Table'!$A$28) -> 2333 | M12: ='Occupancy Report'!S4+'Occupancy Report'!S8+'Occupancy Report'!S12+'Occupancy Report'!S16+'Occupancy Report'!S20+'Occupancy Report'!S24+'Occupancy Report'!S28 -> 2796 | N12: =SUM(L12/M12) -> 0.83440629
B13: Wednesday | C13: PM | D13: ='Occupancy Report'!D13+'Occupancy Report'!K13+'Occupancy Report'!R13+'Occupancy Report'!R44+'Occupancy Report'!K44+'Occupancy Report'!D44+'Occupancy Report'!D75+'Occupancy Report'!K75+'Occupancy Report'!R75+'Occupancy Report'!R106+'Occupancy Report'!L106+'Occupancy Report'!D106 -> 3400 | E13: ='Occupancy Report'!E13+'Occupancy Report'!L13+'Occupancy Report'!S13+'Occupancy Report'!S44+'Occupancy Report'!L44+'Occupancy Report'!E44+'Occupancy Report'!E75+'Occupancy Report'!L75+'Occupancy Report'!S75+'Occupancy Report'!S106+'Occupancy Report'!L106+'Occupancy Report'!E106 -> 4822 | F13: =SUM(D13/E13) -> 0.70510162 | J13: March | K13: PM | L13: =GETPIVOTDATA("Sum of PM FIELD",'Pivot Table'!$A$28) -> 2302 | M13: ='Occupancy Report'!S5+'Occupancy Report'!S9+'Occupancy Report'!S13+'Occupancy Report'!S17+'Occupancy Report'!S21+'Occupancy Report'!S25+'Occupancy Report'!S29 -> 2934 | N13: =SUM(L13/M13) -> 0.78459441
B14: Total Wednesday Occupancy | D14: =SUM(D12:D13) -> 6829 | E14: =SUM(E12:E13) -> 9670 | F14: =SUM(D14/E14) -> 0.70620476 | J14: Total March Occupancy | L14: =SUM(L12:L13) -> 4635 | M14: =SUM(M12:M13) -> 5730 | N14: =SUM(L14/M14) -> 0.80890052
B16: Thursday | C16: AM | D16: ='Occupancy Report'!D16+'Occupancy Report'!K16+'Occupancy Report'!R16+'Occupancy Report'!R47+'Occupancy Report'!K47+'Occupancy Report'!D47+'Occupancy Report'!D78+'Occupancy Report'!K78+'Occupancy Report'!R78+'Occupancy Report'!R109+'Occupancy Report'!L109+'Occupancy Report'!D109 -> 3913 | E16: ='Occupancy Report'!E16+'Occupancy Report'!L16+'Occupancy Report'!S16+'Occupancy Report'!S47+'Occupancy Report'!L47+'Occupancy Report'!E47+'Occupancy Report'!E78+'Occupancy Report'!L78+'Occupancy Report'!S78+'Occupancy Report'!S109+'Occupancy Report'!L109+'Occupancy Report'!E109 -> 4300 | F16: =SUM(D16/E16) -> 0.91 | J16: April | K16: AM | L16: =GETPIVOTDATA("Sum of AM FIELD",'Pivot Table'!$A$40) -> 2263 | M16: ='Occupancy Report'!E35+'Occupancy Report'!E39+'Occupancy Report'!E43+'Occupancy Report'!E47+'Occupancy Report'!E51+'Occupancy Report'!E55+'Occupancy Report'!E59 -> 2676 | N16: =SUM(L16/M16) -> 0.84566517
B17: Thursday | C17: PM | D17: ='Occupancy Report'!D17+'Occupancy Report'!K17+'Occupancy Report'!R17+'Occupancy Report'!R48+'Occupancy Report'!K48+'Occupancy Report'!D48+'Occupancy Report'!D79+'Occupancy Report'!K79+'Occupancy Report'!R79+'Occupancy Report'!R110+'Occupancy Report'!L110+'Occupancy Report'!D110 -> 3913 | E17: ='Occupancy Report'!E17+'Occupancy Report'!L17+'Occupancy Report'!S17+'Occupancy Report'!S48+'Occupancy Report'!L48+'Occupancy Report'!E48+'Occupancy Report'!E79+'Occupancy Report'!L79+'Occupancy Report'!S79+'Occupancy Report'!S110+'Occupancy Report'!L110+'Occupancy Report'!E110 -> 4776 | F17: =SUM(D17/E17) -> 0.81930486 | J17: April | K17: PM | L17: =GETPIVOTDATA("Sum of PM FIELD",'Pivot Table'!$A$40) -> 1923 | M17: ='Occupancy Report'!E36+'Occupancy Report'!E40+'Occupancy Report'!E44+'Occupancy Report'!E48+'Occupancy Report'!E52+'Occupancy Report'!E56+'Occupancy Report'!E60 -> 2512 | N17: =SUM(L17/M17) -> 0.76552548
B18: Total Thursday Occupancy | D18: =SUM(D16:D17) -> 7826 | E18: =SUM(E16:E17) -> 9076 | F18: =SUM(D18/E18) -> 0.86227413 | J18: Total April Occupancy | L18: =SUM(L16:L17) -> 4186 | M18: =SUM(M16:M17) -> 5188 | N18: =SUM(L18/M18) -> 0.80686199
B20: Friday | C20: AM | D20: ='Occupancy Report'!D20+'Occupancy Report'!K20+'Occupancy Report'!R20+'Occupancy Report'!R51+'Occupancy Report'!K51+'Occupancy Report'!D51+'Occupancy Report'!D82+'Occupancy Report'!K82+'Occupancy Report'!R82+'Occupancy Report'!R113+'Occupancy Report'!L113+'Occupancy Report'!D113 -> 4523 | E20: ='Occupancy Report'!E20+'Occupancy Report'!L20+'Occupancy Report'!S20+'Occupancy Report'!S51+'Occupancy Report'!L51+'Occupancy Report'!E51+'Occupancy Report'!E82+'Occupancy Report'!L82+'Occupancy Report'!S82+'Occupancy Report'!S113+'Occupancy Report'!L113+'Occupancy Report'!E113 -> 5200 | F20: =SUM(D20/E20) -> 0.86980769 | J20: May | K20: AM | L20: =GETPIVOTDATA("Sum of AM FIELD",'Pivot Table'!$A$52) -> 2308 | M20: ='Occupancy Report'!L35+'Occupancy Report'!L39+'Occupancy Report'!L43+'Occupancy Report'!L47+'Occupancy Report'!L51+'Occupancy Report'!L55+'Occupancy Report'!L59 -> 2768 | N20: =SUM(L20/M20) -> 0.83381503
B21: Friday | C21: PM | D21: ='Occupancy Report'!D21+'Occupancy Report'!K21+'Occupancy Report'!R21+'Occupancy Report'!R52+'Occupancy Report'!K52+'Occupancy Report'!D52+'Occupancy Report'!D83+'Occupancy Report'!K83+'Occupancy Report'!R83+'Occupancy Report'!R114+'Occupancy Report'!L114+'Occupancy Report'!D114 -> 3891 | E21: ='Occupancy Report'!E21+'Occupancy Report'!L21+'Occupancy Report'!S21+'Occupancy Report'!S52+'Occupancy Report'!L52+'Occupancy Report'!E52+'Occupancy Report'!E83+'Occupancy Report'!L83+'Occupancy Report'!S83+'Occupancy Report'!S114+'Occupancy Report'!L114+'Occupancy Report'!E114 -> 4964 | F21: =SUM(D21/E21) -> 0.78384367 | J21: May | K21: PM | L21: =GETPIVOTDATA("Sum of PM FIELD",'Pivot Table'!$A$52) -> 1748 | M21: ='Occupancy Report'!L60+'Occupancy Report'!L56+'Occupancy Report'!L52+'Occupancy Report'!L48+'Occupancy Report'!L44+'Occupancy Report'!L40+'Occupancy Report'!L36 -> 2508 | N21: =SUM(L21/M21) -> 0.6969697
B22: Total Friday Occupancy | D22: =SUM(D20:D21) -> 8414 | E22: =SUM(E20:E21) -> 10164 | F22: =SUM(D22/E22) -> 0.82782369 | J22: Total May Occupancy | L22: =SUM(L20:L21) -> 4056 | M22: =SUM(M20:M21) -> 5276 | N22: =SUM(L22/M22) -> 0.76876422
B24: Saturday | C24: AM | D24: ='Occupancy Report'!D24+'Occupancy Report'!K24+'Occupancy Report'!R24+'Occupancy Report'!R55+'Occupancy Report'!K55+'Occupancy Report'!D55+'Occupancy Report'!D86+'Occupancy Report'!K86+'Occupancy Report'!R86+'Occupancy Report'!R117+'Occupancy Report'!L117+'Occupancy Report'!D117 -> 4271 | E24: ='Occupancy Report'!E24+'Occupancy Report'!L24+'Occupancy Report'!S24+'Occupancy Report'!S55+'Occupancy Report'!L55+'Occupancy Report'!E55+'Occupancy Report'!E86+'Occupancy Report'!L86+'Occupancy Report'!S86+'Occupancy Report'!S117+'Occupancy Report'!L117+'Occupancy Report'!E117 -> 4808 | F24: =SUM(D24/E24) -> 0.88831115 | J24: June | K24: AM | L24: =GETPIVOTDATA("Sum of AM FIELD",'Pivot Table'!$A$64) -> 1911 | M24: ='Occupancy Report'!S35+'Occupancy Report'!S39+'Occupancy Report'!S43+'Occupancy Report'!S47+'Occupancy Report'!S51+'Occupancy Report'!S55+'Occupancy Report'!S59 -> 2496 | N24: =SUM(L24/M24) -> 0.765625
B25: Saturday | C25: PM | D25: ='Occupancy Report'!D25+'Occupancy Report'!K25+'Occupancy Report'!R25+'Occupancy Report'!R56+'Occupancy Report'!K56+'Occupancy Report'!D56+'Occupancy Report'!D87+'Occupancy Report'!K87+'Occupancy Report'!R87+'Occupancy Report'!R118+'Occupancy Report'!L118+'Occupancy Report'!D118 -> 2919 | E25: ='Occupancy Report'!E25+'Occupancy Report'!L25+'Occupancy Report'!S25+'Occupancy Report'!S56+'Occupancy Report'!L56+'Occupancy Report'!E56+'Occupancy Report'!E87+'Occupancy Report'!L87+'Occupancy Report'!S87+'Occupancy Report'!S118+'Occupancy Report'!L118+'Occupancy Report'!E118 -> 4272 | F25: =SUM(D25/E25) -> 0.68328652 | J25: June | K25: PM | L25: =GETPIVOTDATA("Sum of PM FIELD",'Pivot Table'!$A$64) -> 1890 | M25: ='Occupancy Report'!S36+'Occupancy Report'!S40+'Occupancy Report'!S44+'Occupancy Report'!S48+'Occupancy Report'!S52+'Occupancy Report'!S56+'Occupancy Report'!S60 -> 2564 | N25: =SUM(L25/M25) -> 0.73712949
B26: Total Saturday Occupancy | D26: =SUM(D24:D25) -> 7190 | E26: =SUM(E24:E25) -> 9080 | F26: =SUM(D26/E26) -> 0.79185022 | J26: Total June Occupancy | L26: =SUM(L24:L25) -> 3801 | M26: =SUM(M24:M25) -> 5060 | N26: =SUM(L26/M26) -> 0.75118577
B28: Sunday | C28: AM | D28: ='Occupancy Report'!D28+'Occupancy Report'!K28+'Occupancy Report'!R28+'Occupancy Report'!R59+'Occupancy Report'!K59+'Occupancy Report'!D59+'Occupancy Report'!D90+'Occupancy Report'!K90+'Occupancy Report'!R90+'Occupancy Report'!R121+'Occupancy Report'!L121+'Occupancy Report'!D121 -> 4520 | E28: ='Occupancy Report'!E28+'Occupancy Report'!L28+'Occupancy Report'!S28+'Occupancy Report'!S59+'Occupancy Report'!L59+'Occupancy Report'!E59+'Occupancy Report'!E90+'Occupancy Report'!L90+'Occupancy Report'!S90+'Occupancy Report'!S121+'Occupancy Report'!L121+'Occupancy Report'!E121 -> 5048 | F28: =SUM(D28/E28) -> 0.89540412 | J28: July | K28: AM | L28: ='Occupancy Report'!D66+'Occupancy Report'!D70+'Occupancy Report'!D74+'Occupancy Report'!D78+'Occupancy Report'!D82+'Occupancy Report'!D86+'Occupancy Report'!D90 -> 2160 | M28: ='Occupancy Report'!E66+'Occupancy Report'!E70+'Occupancy Report'!E74+'Occupancy Report'!E78+'Occupancy Report'!E82+'Occupancy Report'!E86+'Occupancy Report'!E90 -> 2668 | N28: =SUM(L28/M28) -> 0.8095952
B29: Sunday | C29: PM | D29: ='Occupancy Report'!D29+'Occupancy Report'!K29+'Occupancy Report'!R29+'Occupancy Report'!R60+'Occupancy Report'!K60+'Occupancy Report'!D60+'Occupancy Report'!D91+'Occupancy Report'!K91+'Occupancy Report'!R91+'Occupancy Report'!R122+'Occupancy Report'!L122+'Occupancy Report'!D122 -> 4206 | E29: ='Occupancy Report'!E29+'Occupancy Report'!L29+'Occupancy Report'!S29+'Occupancy Report'!S60+'Occupancy Report'!L60+'Occupancy Report'!E60+'Occupancy Report'!E91+'Occupancy Report'!L91+'Occupancy Report'!S91+'Occupancy Report'!S122+'Occupancy Report'!L122+'Occupancy Report'!E122 -> 4800 | F29: =SUM(D29/E29) -> 0.87625 | J29: July | K29: PM | L29: ='Occupancy Report'!D67+'Occupancy Report'!D71+'Occupancy Report'!D75+'Occupancy Report'!D79+'Occupancy Report'!D83+'Occupancy Report'!D87+'Occupancy Report'!D91 -> 1824 | M29: ='Occupancy Report'!E67+'Occupancy Report'!E71+'Occupancy Report'!E75+'Occupancy Report'!E79+'Occupancy Report'!E83++'Occupancy Report'!E87+'Occupancy Report'!E91 -> 2690 | N29: =SUM(L29/M29) -> 0.67806691
B30: Total Sunday Occupancy | D30: =SUM(D28:D29) -> 8726 | E30: =SUM(E28:E29) -> 9848 | F30: =SUM(D30/E30) -> 0.88606824 | J30: Total July Occupancy | L30: =SUM(L28:L29) -> 3984 | M30: =SUM(M28:M29) -> 5358 | N30: =SUM(L30/M30) -> 0.74356103
J32: August | K32: AM | L32: ='Occupancy Report'!K66+'Occupancy Report'!K70+'Occupancy Report'!K74+'Occupancy Report'!K78+'Occupancy Report'!K82+'Occupancy Report'!K86+'Occupancy Report'!K90 -> 2166 | M32: ='Occupancy Report'!L66+'Occupancy Report'!L70+'Occupancy Report'!L74+'Occupancy Report'!L78+'Occupancy Report'!L82+'Occupancy Report'!L86+'Occupancy Report'!L90 -> 2780 | N32: =SUM(L32/M32) -> 0.77913669
J33: August | K33: PM | L33: ='Occupancy Report'!K67+'Occupancy Report'!K71+'Occupancy Report'!K75+'Occupancy Report'!K79+'Occupancy Report'!K83+'Occupancy Report'!K87+'Occupancy Report'!K91 -> 1826 | M33: ='Occupancy Report'!L67+'Occupancy Report'!L71+'Occupancy Report'!L75+'Occupancy Report'!L79+'Occupancy Report'!L83+'Occupancy Report'!L87+'Occupancy Report'!L91 -> 2750 | N33: =SUM(L33/M33) -> 0.664
J34: Total August Occupancy | L34: =SUM(L32:L33) -> 3992 | M34: =SUM(M32:M33) -> 5530 | N34: =SUM(L34/M34) -> 0.72188065
J36: September | K36: AM | L36: ='Occupancy Report'!R66+'Occupancy Report'!R70+'Occupancy Report'!R74+'Occupancy Report'!R78+'Occupancy Report'!R82+'Occupancy Report'!R86+'Occupancy Report'!R90 -> 2237 | M36: ='Occupancy Report'!S66+'Occupancy Report'!S70+'Occupancy Report'!S74+'Occupancy Report'!S78+'Occupancy Report'!S82+'Occupancy Report'!S86+'Occupancy Report'!S90 -> 2744 | N36: =SUM(L36/M36) -> 0.81523324
J37: September | K37: PM | L37: ='Occupancy Report'!R67+'Occupancy Report'!R71+'Occupancy Report'!R75+'Occupancy Report'!R79+'Occupancy Report'!R83+'Occupancy Report'!R87+'Occupancy Report'!R91 -> 1826 | M37: ='Occupancy Report'!S67+'Occupancy Report'!S71+'Occupancy Report'!S75+'Occupancy Report'!S79+'Occupancy Report'!S83+'Occupancy Report'!S87+'Occupancy Report'!S91 -> 2548 | N37: =SUM(L37/M37) -> 0.7166405
J38: Total September Occupancy | L38: =SUM(L36:L37) -> 4063 | M38: =SUM(M36:M37) -> 5292 | N38: =SUM(L38/M38) -> 0.76776266
J40: October | K40: AM | L40: =GETPIVOTDATA("Sum of AM FIELD",'Pivot Table'!$A$112) -> 2147 | M40: ='Occupancy Report'!E97+'Occupancy Report'!E101+'Occupancy Report'!E105+'Occupancy Report'!E109+'Occupancy Report'!E113+'Occupancy Report'!E117+'Occupancy Report'!E121 -> 2762 | N40: =SUM(L40/M40) -> 0.77733526
J41: October | K41: PM | L41: =GETPIVOTDATA("Sum of PM FIELD",'Pivot Table'!$A$112) -> 1883 | M41: ='Occupancy Report'!E98+'Occupancy Report'!E102+'Occupancy Report'!E106+'Occupancy Report'!E110+'Occupancy Report'!E114+'Occupancy Report'!E118+'Occupancy Report'!E122 -> 2588 | N41: =SUM(L41/M41) -> 0.72758887
J42: Total October Occupancy | L42: =SUM(L40:L41) -> 4030 | M42: =SUM(M40:M41) -> 5350 | N42: =SUM(L42/M42) -> 0.75327103
J44: November | K44: AM | L44: =GETPIVOTDATA("Sum of AM FIELD",'Pivot Table'!$A$124) -> 2386 | M44: ='Occupancy Report'!L97+'Occupancy Report'!L101+'Occupancy Report'!L105+'Occupancy Report'!L109+'Occupancy Report'!L113+'Occupancy Report'!L117+'Occupancy Report'!L121 -> 2892 | N44: =SUM(L44/M44) -> 0.82503458
J45: November | K45: PM | L45: =GETPIVOTDATA("Sum of PM FIELD",'Pivot Table'!$A$124) -> 2031 | M45: ='Occupancy Report'!L98+'Occupancy Report'!L102+'Occupancy Report'!L106+'Occupancy Report'!L110+'Occupancy Report'!L114+'Occupancy Report'!L118+'Occupancy Report'!L122 -> 2632 | N45: =SUM(L45/M45) -> 0.77165653
J46: Total November Occupancy | L46: =SUM(L44:L45) -> 4417 | M46: =SUM(M44:M45) -> 5524 | N46: =SUM(L46/M46) -> 0.79960174
J48: December | K48: AM | L48: =GETPIVOTDATA("Sum of AM FIELD",'Pivot Table'!$A$136) -> 2270 | M48: =SUM('Occupancy Report'!S97+'Occupancy Report'!S101+'Occupancy Report'!S105+'Occupancy Report'!S109+'Occupancy Report'!S113+'Occupancy Report'!S117+'Occupancy Report'!S121) -> 2668 | N48: =SUM(L48/M48) -> 0.85082459
J49: December | K49: PM | L49: =GETPIVOTDATA("Sum of PM FIELD",'Pivot Table'!$A$136) -> 1642 | M49: =SUM('Occupancy Report'!S98+'Occupancy Report'!S102+'Occupancy Report'!S106+'Occupancy Report'!S110+'Occupancy Report'!S114+'Occupancy Report'!S118+'Occupancy Report'!S122) -> 2328 | N49: =SUM(L49/M49) -> 0.70532646
J50: Total December Occupancy | L50: =SUM(L48:L49) -> 3912 | M50: =SUM(M48:M49) -> 4996 | N50: =SUM(L50/M50) -> 0.78302642

Sheet Day by Day Totals
B2: Day by Totals
B4: Monday | E4: Tuesday | H4: Wednesday | K4: Thursday | N4: Friday | Q4: Saturday | T4: Sunday
B6: AM Field | C6: =GETPIVOTDATA("Sum of AM FIELD",'Pivot Table'!$A$4,"DAY","Mon")+GETPIVOTDATA("Sum of AM FIELD",'Pivot Table'!$A$16,"DAY","Mon")+GETPIVOTDATA("Sum of AM FIELD",'Pivot Table'!$A$28,"DAY","Mon")+GETPIVOTDATA("Sum of AM FIELD",'Pivot Table'!$A$40,"DAY","Mon")+GETPIVOTDATA("Sum of AM FIELD",'Pivot Table'!$A$52,"DAY","Mon")+GETPIVOTDATA("Sum of AM FIELD",'Pivot Table'!$A$64,"DAY","Mon")+GETPIVOTDATA("Sum of AM FIELD",'Pivot Table'!$A$76,"DAY","Mon")+GETPIVOTDATA("Sum of AM FIELD",'Pivot Table'!$A$88,"DAY","Mon")+GETPIVOTDATA("Sum of AM FIELD",'Pivot Table'!$A$100,"DAY","Mon")+GETPIVOTDATA("Sum of AM FIELD",'Pivot Table'!$A$112,"DAY","Mon")+GETPIVOTDATA("Sum of AM FIELD",'Pivot Table'!$A$124,"DAY","Mon")+GETPIVOTDATA("Sum of AM FIELD",'Pivot Table'!$A$136,"DAY","Mon") -> 2343 | E6: AM Field | F6: =GETPIVOTDATA("Sum of AM FIELD",'Pivot Table'!$A$4,"DAY","Tue")+GETPIVOTDATA("Sum of AM FIELD",'Pivot Table'!$A$16,"DAY","Tue")+GETPIVOTDATA("Sum of AM FIELD",'Pivot Table'!$A$28,"DAY","Tue")+GETPIVOTDATA("Sum of AM FIELD",'Pivot Table'!$A$40,"DAY","Tue")+GETPIVOTDATA("Sum of AM FIELD",'Pivot Table'!$A$52,"DAY","Tue")+GETPIVOTDATA("Sum of AM FIELD",'Pivot Table'!$A$64,"DAY","Tue")+GETPIVOTDATA("Sum of AM FIELD",'Pivot Table'!$A$76,"DAY","Tue")+GETPIVOTDATA("Sum of AM FIELD",'Pivot Table'!$A$88,"DAY","Tue")+GETPIVOTDATA("Sum of AM FIELD",'Pivot Table'!$A$100,"DAY","Tue")+GETPIVOTDATA("Sum of AM FIELD",'Pivot Table'!$A$112,"DAY","Tue")+GETPIVOTDATA("Sum of AM FIELD",'Pivot Table'!$A$124,"DAY","Tue")+GETPIVOTDATA("Sum of AM FIELD",'Pivot Table'!$A$136,"DAY","Tue") -> 4424 | H6: AM Field | I6: =GETPIVOTDATA("Sum of AM FIELD",'Pivot Table'!$A$4,"DAY","Wed")+GETPIVOTDATA("Sum of AM FIELD",'Pivot Table'!$A$16,"DAY","Wed")+GETPIVOTDATA("Sum of AM FIELD",'Pivot Table'!$A$28,"DAY","Wed")+GETPIVOTDATA("Sum of AM FIELD",'Pivot Table'!$A$40,"DAY","Wed")+GETPIVOTDATA("Sum of AM FIELD",'Pivot Table'!$A$52,"DAY","Wed")+GETPIVOTDATA("Sum of AM FIELD",'Pivot Table'!$A$64,"DAY","Wed")+GETPIVOTDATA("Sum of AM FIELD",'Pivot Table'!$A$76,"DAY","Wed")+GETPIVOTDATA("Sum of AM FIELD",'Pivot Table'!$A$88,"DAY","Wed")+GETPIVOTDATA("Sum of AM FIELD",'Pivot Table'!$A$100,"DAY","Wed")+GETPIVOTDATA("Sum of AM FIELD",'Pivot Table'!$A$112,"DAY","Wed")+GETPIVOTDATA("Sum of AM FIELD",'Pivot Table'!$A$124,"DAY","Wed")+GETPIVOTDATA("Sum of AM FIELD",'Pivot Table'!$A$136,"DAY","Wed") -> 3254 | K6: AM Field | L6: =GETPIVOTDATA("Sum of AM FIELD",'Pivot Table'!$A$4,"DAY","Thu")+GETPIVOTDATA("Sum of AM FIELD",'Pivot Table'!$A$16,"DAY","Thu")+GETPIVOTDATA("Sum of AM FIELD",'Pivot Table'!$A$28,"DAY","Thu")+GETPIVOTDATA("Sum of AM FIELD",'Pivot Table'!$A$40,"DAY","Thu")+GETPIVOTDATA("Sum of AM FIELD",'Pivot Table'!$A$52,"DAY","Thu")+GETPIVOTDATA("Sum of AM FIELD",'Pivot Table'!$A$64,"DAY","Thu")+GETPIVOTDATA("Sum of AM FIELD",'Pivot Table'!$A$76,"DAY","Thu")+GETPIVOTDATA("Sum of AM FIELD",'Pivot Table'!$A$88,"DAY","Thu")+GETPIVOTDATA("Sum of AM FIELD",'Pivot Table'!$A$100,"DAY","Thu")+GETPIVOTDATA("Sum of AM FIELD",'Pivot Table'!$A$112,"DAY","Thu")+GETPIVOTDATA("Sum of AM FIELD",'Pivot Table'!$A$124,"DAY","Thu")+GETPIVOTDATA("Sum of AM FIELD",'Pivot Table'!$A$136,"DAY","Thu") -> 3862 | N6: AM Field | O6: =GETPIVOTDATA("Sum of AM FIELD",'Pivot Table'!$A$4,"DAY","Fri")+GETPIVOTDATA("Sum of AM FIELD",'Pivot Table'!$A$16,"DAY","Fri")+GETPIVOTDATA("Sum of AM FIELD",'Pivot Table'!$A$28,"DAY","Fri")+GETPIVOTDATA("Sum of AM FIELD",'Pivot Table'!$A$40,"DAY","Fri")+GETPIVOTDATA("Sum of AM FIELD",'Pivot Table'!$A$52,"DAY","Fri")+GETPIVOTDATA("Sum of AM FIELD",'Pivot Table'!$A$64,"DAY","Fri")+GETPIVOTDATA("Sum of AM FIELD",'Pivot Table'!$A$76,"DAY","Fri")+GETPIVOTDATA("Sum of AM FIELD",'Pivot Table'!$A$88,"DAY","Fri")+GETPIVOTDATA("Sum of AM FIELD",'Pivot Table'!$A$100,"DAY","Fri")+GETPIVOTDATA("Sum of AM FIELD",'Pivot Table'!$A$112,"DAY","Fri")+GETPIVOTDATA("Sum of AM FIELD",'Pivot Table'!$A$124,"DAY","Fri")+GETPIVOTDATA("Sum of AM FIELD",'Pivot Table'!$A$136,"DAY","Fri") -> 4486 | Q6: AM Field | R6: =GETPIVOTDATA("Sum of AM FIELD",'Pivot Table'!$A$4,"DAY","Sat")+GETPIVOTDATA("Sum of AM FIELD",'Pivot Table'!$A$16,"DAY","Sat")+GETPIVOTDATA("Sum of AM FIELD",'Pivot Table'!$A$28,"DAY","Sat")+GETPIVOTDATA("Sum of AM FIELD",'Pivot Table'!$A$40,"DAY","Sat")+GETPIVOTDATA("Sum of AM FIELD",'Pivot Table'!$A$52,"DAY","Sat")+GETPIVOTDATA("Sum of AM FIELD",'Pivot Table'!$A$64,"DAY","Sat")+GETPIVOTDATA("Sum of AM FIELD",'Pivot Table'!$A$76,"DAY","Sat")+GETPIVOTDATA("Sum of AM FIELD",'Pivot Table'!$A$88,"DAY","Sat")+GETPIVOTDATA("Sum of AM FIELD",'Pivot Table'!$A$100,"DAY","Sat")+GETPIVOTDATA("Sum of AM FIELD",'Pivot Table'!$A$112,"DAY","Sat")+GETPIVOTDATA("Sum of AM FIELD",'Pivot Table'!$A$124,"DAY","Sat")+GETPIVOTDATA("Sum of AM FIELD",'Pivot Table'!$A$136,"DAY","Sat") -> 4231 | T6: AM Field | U6: =GETPIVOTDATA("Sum of AM FIELD",'Pivot Table'!$A$4,"DAY","Sun")+GETPIVOTDATA("Sum of AM FIELD",'Pivot Table'!$A$16,"DAY","Sun")+GETPIVOTDATA("Sum of AM FIELD",'Pivot Table'!$A$28,"DAY","Sun")+GETPIVOTDATA("Sum of AM FIELD",'Pivot Table'!$A$40,"DAY","Sun")+GETPIVOTDATA("Sum of AM FIELD",'Pivot Table'!$A$52,"DAY","Sun")+GETPIVOTDATA("Sum of AM FIELD",'Pivot Table'!$A$64,"DAY","Sun")+GETPIVOTDATA("Sum of AM FIELD",'Pivot Table'!$A$76,"DAY","Sun")+GETPIVOTDATA("Sum of AM FIELD",'Pivot Table'!$A$88,"DAY","Sun")+GETPIVOTDATA("Sum of AM FIELD",'Pivot Table'!$A$100,"DAY","Sun")+GETPIVOTDATA("Sum of AM FIELD",'Pivot Table'!$A$112,"DAY","Sun")+GETPIVOTDATA("Sum of AM FIELD",'Pivot Table'!$A$124,"DAY","Sun")+GETPIVOTDATA("Sum of AM FIELD",'Pivot Table'!$A$136,"DAY","Sun") -> 4485
B7: PM Field | C7: =GETPIVOTDATA("Sum of PM FIELD",'Pivot Table'!$A$4,"DAY","Mon")+GETPIVOTDATA("Sum of PM FIELD",'Pivot Table'!$A$16,"DAY","Mon")+GETPIVOTDATA("Sum of PM FIELD",'Pivot Table'!$A$28,"DAY","Mon")+GETPIVOTDATA("Sum of PM FIELD",'Pivot Table'!$A$40,"DAY","Mon")+GETPIVOTDATA("Sum of PM FIELD",'Pivot Table'!$A$52,"DAY","Mon")+GETPIVOTDATA("Sum of PM FIELD",'Pivot Table'!$A$64,"DAY","Mon")+GETPIVOTDATA("Sum of PM FIELD",'Pivot Table'!$A$76,"DAY","Mon")+GETPIVOTDATA("Sum of PM FIELD",'Pivot Table'!$A$88,"DAY","Mon")++GETPIVOTDATA("Sum of PM FIELD",'Pivot Table'!$A$112,"DAY","Mon")+GETPIVOTDATA("Sum of PM FIELD",'Pivot Table'!$A$100,"DAY","Mon")+GETPIVOTDATA("Sum of PM FIELD",'Pivot Table'!$A$124,"DAY","Mon")+GETPIVOTDATA("Sum of PM FIELD",'Pivot Table'!$A$136,"DAY","Mon") -> 3241 | E7: PM Field | F7: =GETPIVOTDATA("Sum of PM FIELD",'Pivot Table'!$A$4,"DAY","Tue")+GETPIVOTDATA("Sum of PM FIELD",'Pivot Table'!$A$16,"DAY","Tue")+GETPIVOTDATA("Sum of PM FIELD",'Pivot Table'!$A$28,"DAY","Tue")+GETPIVOTDATA("Sum of PM FIELD",'Pivot Table'!$A$40,"DAY","Tue")+GETPIVOTDATA("Sum of PM FIELD",'Pivot Table'!$A$52,"DAY","Tue")+GETPIVOTDATA("Sum of PM FIELD",'Pivot Table'!$A$64,"DAY","Tue")+GETPIVOTDATA("Sum of PM FIELD",'Pivot Table'!$A$76,"DAY","Tue")+GETPIVOTDATA("Sum of PM FIELD",'Pivot Table'!$A$88,"DAY","Tue")+GETPIVOTDATA("Sum of PM FIELD",'Pivot Table'!$A$100,"DAY","Tue")+GETPIVOTDATA("Sum of PM FIELD",'Pivot Table'!$A$112,"DAY","Tue")+GETPIVOTDATA("Sum of PM FIELD",'Pivot Table'!$A$124,"DAY","Tue")+GETPIVOTDATA("Sum of PM FIELD",'Pivot Table'!$A$136,"DAY","Tue") -> 1530 | H7: PM Field | I7: =GETPIVOTDATA("Sum of PM FIELD",'Pivot Table'!$A$4,"DAY","Wed")+GETPIVOTDATA("Sum of PM FIELD",'Pivot Table'!$A$16,"DAY","Wed")+GETPIVOTDATA("Sum of PM FIELD",'Pivot Table'!$A$28,"DAY","Wed")+GETPIVOTDATA("Sum of PM FIELD",'Pivot Table'!$A$40,"DAY","Wed")+GETPIVOTDATA("Sum of PM FIELD",'Pivot Table'!$A$52,"DAY","Wed")+GETPIVOTDATA("Sum of PM FIELD",'Pivot Table'!$A$64,"DAY","Wed")+GETPIVOTDATA("Sum of PM FIELD",'Pivot Table'!$A$76,"DAY","Wed")+GETPIVOTDATA("Sum of PM FIELD",'Pivot Table'!$A$88,"DAY","Wed")+GETPIVOTDATA("Sum of PM FIELD",'Pivot Table'!$A$100,"DAY","Wed")+GETPIVOTDATA("Sum of PM FIELD",'Pivot Table'!$A$112,"DAY","Wed")+GETPIVOTDATA("Sum of PM FIELD",'Pivot Table'!$A$124,"DAY","Wed")+GETPIVOTDATA("Sum of PM FIELD",'Pivot Table'!$A$136,"DAY","Wed") -> 3252 | K7: PM Field | L7: =GETPIVOTDATA("Sum of PM FIELD",'Pivot Table'!$A$4,"DAY","Thu")+GETPIVOTDATA("Sum of PM FIELD",'Pivot Table'!$A$16,"DAY","Thu")+GETPIVOTDATA("Sum of PM FIELD",'Pivot Table'!$A$28,"DAY","Thu")+GETPIVOTDATA("Sum of PM FIELD",'Pivot Table'!$A$40,"DAY","Thu")+GETPIVOTDATA("Sum of PM FIELD",'Pivot Table'!$A$52,"DAY","Thu")+GETPIVOTDATA("Sum of PM FIELD",'Pivot Table'!$A$64,"DAY","Thu")+GETPIVOTDATA("Sum of PM FIELD",'Pivot Table'!$A$76,"DAY","Thu")+GETPIVOTDATA("Sum of PM FIELD",'Pivot Table'!$A$88,"DAY","Thu")+GETPIVOTDATA("Sum of PM FIELD",'Pivot Table'!$A$100,"DAY","Thu")+GETPIVOTDATA("Sum of PM FIELD",'Pivot Table'!$A$112,"DAY","Thu")+GETPIVOTDATA("Sum of PM FIELD",'Pivot Table'!$A$124,"DAY","Thu")+GETPIVOTDATA("Sum of PM FIELD",'Pivot Table'!$A$136,"DAY","Thu") -> 3811 | N7: PM Field | O7: =GETPIVOTDATA("Sum of PM FIELD",'Pivot Table'!$A$4,"DAY","Fri")+GETPIVOTDATA("Sum of PM FIELD",'Pivot Table'!$A$16,"DAY","Fri")+GETPIVOTDATA("Sum of PM FIELD",'Pivot Table'!$A$28,"DAY","Fri")+GETPIVOTDATA("Sum of PM FIELD",'Pivot Table'!$A$40,"DAY","Fri")+GETPIVOTDATA("Sum of PM FIELD",'Pivot Table'!$A$52,"DAY","Fri")+GETPIVOTDATA("Sum of PM FIELD",'Pivot Table'!$A$64,"DAY","Fri")+GETPIVOTDATA("Sum of PM FIELD",'Pivot Table'!$A$76,"DAY","Fri")+GETPIVOTDATA("Sum of PM FIELD",'Pivot Table'!$A$88,"DAY","Fri")+GETPIVOTDATA("Sum of PM FIELD",'Pivot Table'!$A$100,"DAY","Fri")+GETPIVOTDATA("Sum of PM FIELD",'Pivot Table'!$A$112,"DAY","Fri")+GETPIVOTDATA("Sum of PM FIELD",'Pivot Table'!$A$124,"DAY","Fri")+GETPIVOTDATA("Sum of PM FIELD",'Pivot Table'!$A$136,"DAY","Fri") -> 3846 | Q7: PM Field | R7: =GETPIVOTDATA("Sum of PM FIELD",'Pivot Table'!$A$4,"DAY","Sat")+GETPIVOTDATA("Sum of PM FIELD",'Pivot Table'!$A$16,"DAY","Sat")+GETPIVOTDATA("Sum of PM FIELD",'Pivot Table'!$A$28,"DAY","Sat")+GETPIVOTDATA("Sum of PM FIELD",'Pivot Table'!$A$40,"DAY","Sat")+GETPIVOTDATA("Sum of PM FIELD",'Pivot Table'!$A$52,"DAY","Sat")+GETPIVOTDATA("Sum of PM FIELD",'Pivot Table'!$A$64,"DAY","Sat")+GETPIVOTDATA("Sum of PM FIELD",'Pivot Table'!$A$76,"DAY","Sat")+GETPIVOTDATA("Sum of PM FIELD",'Pivot Table'!$A$88,"DAY","Sat")+GETPIVOTDATA("Sum of PM FIELD",'Pivot Table'!$A$100,"DAY","Sat")+GETPIVOTDATA("Sum of PM FIELD",'Pivot Table'!$A$112,"DAY","Sat")+GETPIVOTDATA("Sum of PM FIELD",'Pivot Table'!$A$124,"DAY","Sat")+GETPIVOTDATA("Sum of PM FIELD",'Pivot Table'!$A$136,"DAY","Sat") -> 2800 | T7: PM Field | U7: =GETPIVOTDATA("Sum of PM FIELD",'Pivot Table'!$A$4,"DAY","Sun")+GETPIVOTDATA("Sum of PM FIELD",'Pivot Table'!$A$16,"DAY","Sun")+GETPIVOTDATA("Sum of PM FIELD",'Pivot Table'!$A$28,"DAY","Sun")+GETPIVOTDATA("Sum of PM FIELD",'Pivot Table'!$A$40,"DAY","Sun")+GETPIVOTDATA("Sum of PM FIELD",'Pivot Table'!$A$52,"DAY","Sun")+GETPIVOTDATA("Sum of PM FIELD",'Pivot Table'!$A$64,"DAY","Sun")+GETPIVOTDATA("Sum of PM FIELD",'Pivot Table'!$A$76,"DAY","Sun")+GETPIVOTDATA("Sum of PM FIELD",'Pivot Table'!$A$88,"DAY","Sun")+GETPIVOTDATA("Sum of PM FIELD",'Pivot Table'!$A$100,"DAY","Sun")+GETPIVOTDATA("Sum of PM FIELD",'Pivot Table'!$A$112,"DAY","Sun")+GETPIVOTDATA("Sum of PM FIELD",'Pivot Table'!$A$124,"DAY","Sun")+GETPIVOTDATA("Sum of PM FIELD",'Pivot Table'!$A$136,"DAY","Sun") -> 4186
