Workbook

Sheet Yearly Total To Date
B4: Yearly Total | F4: Total Average (Month) | J4: Total Average (Week) | N4: Total Average (Day) | R4: 2024 Occupancy Totals
B6: AM Field | C6: ='Monthly Totals'!C5+'Monthly Totals'!F5+'Monthly Totals'!I5+'Monthly Totals'!L5+'Monthly Totals'!O5+'Monthly Totals'!R5+'Monthly Totals'!C27+'Monthly Totals'!F27+'Monthly Totals'!I27+'Monthly Totals'!L27+'Monthly Totals'!O27+'Monthly Totals'!R27 -> 26916 | F6: AM Field | G6: =C6 / 12 -> 2243 | J6: AM Field | K6: =C6 / 52 -> 517.61538 | N6: AM Field | O6: =C6 / 365 -> 73.742466 | R6: Time | S6: Bookings | T6: Spots Available | U6: Occupancy
B7: PM Field | C7: ='Monthly Totals'!C6+'Monthly Totals'!F6+'Monthly Totals'!I6+'Monthly Totals'!L6+'Monthly Totals'!O6+'Monthly Totals'!R6+'Monthly Totals'!C28+'Monthly Totals'!F28+'Monthly Totals'!I28+'Monthly Totals'!L28+'Monthly Totals'!O28+'Monthly Totals'!R28 -> 23285 | F7: PM Field | G7: =C7 / 12 -> 1940.4167 | J7: PM Field | K7: =C7 / 52 -> 447.78846 | N7: PM Field | O7: =C7 / 365 -> 63.794521 | R7: AM | S7: ='Occupancy Report Summarised'!L4+'Occupancy Report Summarised'!L8+'Occupancy Report Summarised'!L12+'Occupancy Report Summarised'!L16+'Occupancy Report Summarised'!L20+'Occupancy Report Summarised'!L24+'Occupancy Report Summarised'!L28+'Occupancy Report Summarised'!L32+'Occupancy Report Summarised'!L36+'Occupancy Report Summarised'!L40+'Occupancy Report Summarised'!L44+'Occupancy Report Summarised'!L48 -> 26916 | T7: ='Occupancy Report Summarised'!M4+'Occupancy Report Summarised'!M8+'Occupancy Report Summarised'!M12+'Occupancy Report Summarised'!M16+'Occupancy Report Summarised'!M20+'Occupancy Report Summarised'!M24+'Occupancy Report Summarised'!M28+'Occupancy Report Summarised'!M32+'Occupancy Report Summarised'!M36+'Occupancy Report Summarised'!M40+'Occupancy Report Summarised'!M44+'Occupancy Report Summarised'!M48 -> 32756 | U7: =SUM(S7/T7) -> 0.82171205
B8: Total Field | C8: ='Monthly Totals'!C7+'Monthly Totals'!F7+'Monthly Totals'!I7+'Monthly Totals'!L7+'Monthly Totals'!O7+'Monthly Totals'!R7+'Monthly Totals'!C29+'Monthly Totals'!F29+'Monthly Totals'!I29+'Monthly Totals'!L29+'Monthly Totals'!O29+'Monthly Totals'!R29 -> 50201 | F8: Total Field | G8: =C8 / 12 -> 4183.4167 | J8: Total Field | K8: =C8 / 52 -> 965.40385 | N8: Total Field | O8: =C8 / 365 -> 137.53699 | R8: PM | S8: ='Occupancy Report Summarised'!L5+'Occupancy Report Summarised'!L9+'Occupancy Report Summarised'!L13+'Occupancy Report Summarised'!L17+'Occupancy Report Summarised'!L21+'Occupancy Report Summarised'!L25+'Occupancy Report Summarised'!L29+'Occupancy Report Summarised'!L33+'Occupancy Report Summarised'!L37+'Occupancy Report Summarised'!L41+'Occupancy Report Summarised'!L45+'Occupancy Report Summarised'!L49 -> 23285 | T8: ='Occupancy Report Summarised'!M5+'Occupancy Report Summarised'!M9+'Occupancy Report Summarised'!M13+'Occupancy Report Summarised'!M17+'Occupancy Report Summarised'!M21+'Occupancy Report Summarised'!M25+'Occupancy Report Summarised'!M29+'Occupancy Report Summarised'!M33+'Occupancy Report Summarised'!M37+'Occupancy Report Summarised'!M41+'Occupancy Report Summarised'!M45+'Occupancy Report Summarised'!M49 -> 31584 | U8: =SUM(S8/T8) -> 0.73724037
B9: Guests | C9: ='Monthly Totals'!C8+'Monthly Totals'!F8+'Monthly Totals'!I8+'Monthly Totals'!L8+'Monthly Totals'!O8+'Monthly Totals'!R8+'Monthly Totals'!C30+'Monthly Totals'!F30+'Monthly Totals'!I30+'Monthly Totals'!L30+'Monthly Totals'!O30+'Monthly Totals'!R30 -> 9577 | F9: Guests | G9: =C9 / 12 -> 798.08333 | J9: Guests | K9: =C9 / 52 -> 184.17308 | N9: Guests | O9: =C9 / 365 -> 26.238356 | R9: Total | S9: =SUM(S7:S8) -> 50201 | T9: =SUM(T7:T8) -> 64340 | U9: =SUM(S9/T9) -> 0.78024557
B10: Member / Guest Ratio | C10: =SUM(C9/C8) -> 0.19077309 | F10: Member / Guest Ratio | G10: - | J10: Member / Guest Ratio | K10: - | N10: Member / Guest Ratio | O10: -
B11: Member Play | C11: ='Monthly Totals'!C10+'Monthly Totals'!F10+'Monthly Totals'!I10+'Monthly Totals'!L10+'Monthly Totals'!O10+'Monthly Totals'!R10+'Monthly Totals'!C32+'Monthly Totals'!F32+'Monthly Totals'!I32+'Monthly Totals'!L32+'Monthly Totals'!O32+'Monthly Totals'!R32 -> 40395 | F11: Member Play | G11: =C11 / 12 -> 3366.25 | J11: Member Play | K11: =C11 / 52 -> 776.82692 | N11: Member Play | O11: =C11 / 365 -> 110.67123
B12: Manger Intro | C12: ='Monthly Totals'!C11+'Monthly Totals'!F11+'Monthly Totals'!I11+'Monthly Totals'!L11+'Monthly Totals'!O11+'Monthly Totals'!R11+'Monthly Totals'!C33+'Monthly Totals'!F33+'Monthly Totals'!I33+'Monthly Totals'!L33+'Monthly Totals'!O33+'Monthly Totals'!R33 -> 191 | F12: Manger Intro | G12: =C12 / 12 -> 15.916667 | J12: Manger Intro | K12: =C12 / 52 -> 3.6730769 | N12: Manger Intro | O12: =C12 / 365 -> 0.52328767
B13: Interstate | C13: ='Monthly Totals'!C12+'Monthly Totals'!F12+'Monthly Totals'!I12+'Monthly Totals'!L12+'Monthly Totals'!O12+'Monthly Totals'!R12+'Monthly Totals'!C34+'Monthly Totals'!F34+'Monthly Totals'!I34+'Monthly Totals'!L34+'Monthly Totals'!O34+'Monthly Totals'!R34 -> 147 | F13: Interstate | G13: =C13 / 12 -> 12.25 | J13: Interstate | K13: =C13 / 52 -> 2.8269231 | N13: Interstate | O13: =C13 / 365 -> 0.40273973
B14: International | C14: ='Monthly Totals'!C13+'Monthly Totals'!F13+'Monthly Totals'!I13+'Monthly Totals'!L13+'Monthly Totals'!O13+'Monthly Totals'!R13+'Monthly Totals'!C35+'Monthly Totals'!F35+'Monthly Totals'!I35+'Monthly Totals'!L35+'Monthly Totals'!O35+'Monthly Totals'!R35 -> 332 | F14: International | G14: =C14 / 12 -> 27.666667 | J14: International | K14: =C14 / 52 -> 6.3846154 | N14: International | O14: =C14 / 365 -> 0.90958904
B15: Industry Guest | C15: ='Monthly Totals'!C14+'Monthly Totals'!F14+'Monthly Totals'!I14+'Monthly Totals'!L14+'Monthly Totals'!O14+'Monthly Totals'!R14+'Monthly Totals'!C36+'Monthly Totals'!F36+'Monthly Totals'!I36+'Monthly Totals'!L36+'Monthly Totals'!O36+'Monthly Totals'!R36 -> 101 | F15: Industry Guest | G15: =C15 / 12 -> 8.4166667 | J15: Industry Guest | K15: =C15 / 52 -> 1.9423077 | N15: Industry Guest | O15: =C15 / 365 -> 0.27671233
B16: Member Intro | C16: ='Monthly Totals'!C15+'Monthly Totals'!F15+'Monthly Totals'!I15+'Monthly Totals'!L15+'Monthly Totals'!O15+'Monthly Totals'!R15+'Monthly Totals'!C37+'Monthly Totals'!F37+'Monthly Totals'!I37+'Monthly Totals'!L37+'Monthly Totals'!O37+'Monthly Totals'!R37 -> 3702 | F16: Member Intro | G16: =C16 / 12 -> 308.5 | J16: Member Intro | K16: =C16 / 52 -> 71.192308 | N16: Member Intro | O16: =C16 / 365 -> 10.142466
B17: Member Guest Unaccompanied | C17: ='Monthly Totals'!C16+'Monthly Totals'!F16+'Monthly Totals'!I16+'Monthly Totals'!L16+'Monthly Totals'!O16+'Monthly Totals'!R16+'Monthly Totals'!C38+'Monthly Totals'!F38+'Monthly Totals'!I38+'Monthly Totals'!L38+'Monthly Totals'!O38+'Monthly Totals'!R38 -> 44 | F17: Member Guest Unaccompanied | G17: =C17 / 12 -> 3.6666667 | J17: Member Guest Unaccompanied | K17: =C17 / 52 -> 0.84615385 | N17: Member Guest Unaccompanied | O17: =C17 / 365 -> 0.12054795
B18: Corporate | C18: ='Monthly Totals'!C17+'Monthly Totals'!F17+'Monthly Totals'!I17+'Monthly Totals'!L17+'Monthly Totals'!O17+'Monthly Totals'!R17+'Monthly Totals'!C39+'Monthly Totals'!F39+'Monthly Totals'!I39+'Monthly Totals'!L39+'Monthly Totals'!O39+'Monthly Totals'!R39 -> 2652 | F18: Corporate | G18: =C18 / 12 -> 221 | J18: Corporate | K18: =C18 / 52 -> 51 | N18: Corporate | O18: =C18 / 365 -> 7.2657534
B19: Event | C19: ='Monthly Totals'!C18+'Monthly Totals'!F18+'Monthly Totals'!I18+'Monthly Totals'!L18+'Monthly Totals'!O18+'Monthly Totals'!R18+'Monthly Totals'!C40+'Monthly Totals'!F40+'Monthly Totals'!I40+'Monthly Totals'!L40+'Monthly Totals'!O40+'Monthly Totals'!R40 -> 1003 | F19: Event | G19: =C19 / 12 -> 83.583333 | J19: Event | K19: =C19 / 52 -> 19.288462 | N19: Event | O19: =C19 / 365 -> 2.7479452
B20: Non Playing | C20: ='Monthly Totals'!C19+'Monthly Totals'!F19+'Monthly Totals'!I19+'Monthly Totals'!L19+'Monthly Totals'!O19+'Monthly Totals'!R19+'Monthly Totals'!C41+'Monthly Totals'!F41+'Monthly Totals'!I41+'Monthly Totals'!L41+'Monthly Totals'!O41+'Monthly Totals'!R41 -> 229 | F20: Non Playing | G20: =C20 / 12 -> 19.083333 | J20: Non Playing | K20: =C20 / 52 -> 4.4038462 | N20: Non Playing | O20: =C20 / 365 -> 0.62739726
B21: Voucher | C21: ='Monthly Totals'!C20+'Monthly Totals'!F20+'Monthly Totals'!I20+'Monthly Totals'!L20+'Monthly Totals'!O20+'Monthly Totals'!R20+'Monthly Totals'!C42+'Monthly Totals'!F42+'Monthly Totals'!I42+'Monthly Totals'!L42+'Monthly Totals'!O42+'Monthly Totals'!R42 -> 628 | F21: Voucher | G21: =C21 / 12 -> 52.333333 | J21: Voucher | K21: =C21 / 52 -> 12.076923 | N21: Voucher | O21: =C21 / 365 -> 1.7205479
B22: Reciprocal | C22: ='Monthly Totals'!C21+'Monthly Totals'!F21+'Monthly Totals'!I21+'Monthly Totals'!L21+'Monthly Totals'!O21+'Monthly Totals'!R21+'Monthly Totals'!C43+'Monthly Totals'!F43+'Monthly Totals'!I43+'Monthly Totals'!L43+'Monthly Totals'!O43+'Monthly Totals'!R43 -> 777 | F22: Reciprocal | G22: =C22 / 12 -> 64.75 | J22: Reciprocal | K22: =C22 / 52 -> 14.942308 | N22: Reciprocal | O22: =C22 / 365 -> 2.1287671
B23: Competition | C23: ='Monthly Totals'!C22+'Monthly Totals'!F22+'Monthly Totals'!I22+'Monthly Totals'!L22+'Monthly Totals'!O22+'Monthly Totals'!R22+'Monthly Totals'!C44+'Monthly Totals'!F44+'Monthly Totals'!I44+'Monthly Totals'!L44+'Monthly Totals'!O44+'Monthly Totals'!R44 -> 26767 | F23: Competition | G23: =C23 / 12 -> 2230.5833 | J23: Competition | K23: =C23 / 52 -> 514.75 | N23: Competition | O23: =C23 / 365 -> 73.334247

Sheet Occupancy Report
B2: January | D2: Bookings | E2: Spots Available | F2: Occupancy | G2: Notes | I2: February | K2: Bookings | L2: Spots Available | M2: Occupancy | N2: Notes | P2: March | R2: Bookings | S2: Spots Available | T2: Occupancy | U2: Notes
B4: Monday | C4: AM | D4: =GETPIVOTDATA("Sum of AM FIELD",'Pivot Table'!$A$4,"DAY","Mon") -> 303 | E4: =SUM(104+80+88+92+88) -> 452 | F4: =SUM(D4/E4) -> 0.67035398 | I4: Monday | J4: AM | K4: =GETPIVOTDATA("Sum of AM FIELD",'Pivot Table'!$A$16,"DAY","Mon") -> 182 | L4: =SUM(88+0+88+88) -> 264 | M4: =SUM(K4/L4) -> 0.68939394 | P4: Monday | Q4: AM | R4: =GETPIVOTDATA("Sum of AM FIELD",'Pivot Table'!$A$28,"DAY","Mon") -> 224 | S4: =SUM(88+96+104+0) -> 288 | T4: =SUM(R4/S4) -> 0.77777778
C5: PM | D5: =GETPIVOTDATA("Sum of PM FIELD",'Pivot Table'!$A$4,"DAY","Mon") -> 312 | E5: =SUM(84+96+84+88+88) -> 440 | F5: =SUM(D5/E5) -> 0.70909091 | J5: PM | K5: =GETPIVOTDATA("Sum of PM FIELD",'Pivot Table'!$A$16,"DAY","Mon") -> 284 | L5: =SUM(88+88+88+88) -> 352 | M5: =SUM(K5/L5) -> 0.80681818 | Q5: PM | R5: =GETPIVOTDATA("Sum of PM FIELD",'Pivot Table'!$A$28,"DAY","Mon") -> 246 | S5: =SUM(88+96+96+80) -> 360 | T5: =SUM(R5/S5) -> 0.68333333
B6: Total Occupancy | D6: =SUM(D3:D5) -> 615 | E6: =SUM(E3:E5) -> 892 | F6: =SUM(D6/E6) -> 0.68946188 | I6: Total Occupancy | K6: =SUM(K3:K5) -> 466 | L6: =SUM(L3:L5) -> 616 | M6: =SUM(K6/L6) -> 0.75649351 | P6: Total Occupancy | R6: =SUM(R3:R5) -> 470 | S6: =SUM(S4:S5) -> 648 | T6: =SUM(R6/S6) -> 0.72530864
B8: Tuesday | C8: AM | D8: =GETPIVOTDATA("Sum of AM FIELD",'Pivot Table'!$A$4,"DAY","Tue") -> 413 | E8: =SUM(112+112+112+112+112) -> 560 | F8: =SUM(D8/E8) -> 0.7375 | I8: Tuesday | J8: AM | K8: =GETPIVOTDATA("Sum of AM FIELD",'Pivot Table'!$A$16,"DAY","Tue") -> 358 | L8: =SUM(112+112+112+112) -> 448 | M8: =SUM(K8/L8) -> 0.79910714 | P8: Tuesday | Q8: AM | R8: =GETPIVOTDATA("Sum of AM FIELD",'Pivot Table'!$A$28,"DAY","Tue") -> 403 | S8: =SUM(112+112+112+100) -> 436 | T8: =SUM(R8/S8) -> 0.92431193
C9: PM | D9: =GETPIVOTDATA("Sum of PM FIELD",'Pivot Table'!$A$4,"DAY","Tue") -> 120 | E9: =SUM(84+84+84+84+84) -> 420 | F9: =SUM(D9/E9) -> 0.28571429 | J9: PM | K9: =GETPIVOTDATA("Sum of PM FIELD",'Pivot Table'!$A$16,"DAY","Tue") -> 116 | L9: =SUM(84+84+84+84) -> 336 | M9: =SUM(K9/L9) -> 0.3452381 | Q9: PM | R9: =GETPIVOTDATA("Sum of PM FIELD",'Pivot Table'!$A$28,"DAY","Tue") -> 77 | S9: =SUM(84+84+84+32) -> 284 | T9: =SUM(R9/S9) -> 0.27112676
B10: Total Occupancy | D10: =SUM(D7:D9) -> 533 | E10: =SUM(E7:E9) -> 980 | F10: =SUM(D10/E10) -> 0.54387755 | I10: Total Occupancy | K10: =SUM(K7:K9) -> 474 | L10: =SUM(L7:L9) -> 784 | M10: =SUM(K10/L10) -> 0.60459184 | P10: Total Occupancy | R10: =SUM(R7:R9) -> 480 | S10: =SUM(S7:S9) -> 720 | T10: =SUM(R10/S10) -> 0.66666667
B12: Wednesday | C12: AM | D12: =GETPIVOTDATA("Sum of AM FIELD",'Pivot Table'!$A$4,"DAY","Wed") -> 384 | E12: =SUM(108+108+88+88+108) -> 500 | F12: =SUM(D12/E12) -> 0.768 | I12: Wednesday | J12: AM | K12: =GETPIVOTDATA("Sum of AM FIELD",'Pivot Table'!$A$16,"DAY","Wed") -> 258 | L12: =SUM(104+104+104+96) -> 408 | M12: =SUM(K12/L12) -> 0.63235294 | P12: Wednesday | Q12: AM | R12: =GETPIVOTDATA("Sum of AM FIELD",'Pivot Table'!$A$28,"DAY","Wed") -> 252 | S12: =SUM(96+104+72+104) -> 376 | T12: =SUM(R12/S12) -> 0.67021277
C13: PM | D13: =GETPIVOTDATA("Sum of PM FIELD",'Pivot Table'!$A$4,"DAY","Wed") -> 439 | E13: =SUM(88+88+164+164+88) -> 592 | F13: =SUM(D13/E13) -> 0.74155405 | J13: PM | K13: =GETPIVOTDATA("Sum of PM FIELD",'Pivot Table'!$A$16,"DAY","Wed") -> 390 | L13: =SUM(92+180+96+56) -> 424 | M13: =SUM(K13/L13) -> 0.91981132 | Q13: PM | R13: =GETPIVOTDATA("Sum of PM FIELD",'Pivot Table'!$A$28,"DAY","Wed") -> 317 | S13: =SUM(92+88+88+100) -> 368 | T13: =SUM(R13/S13) -> 0.86141304
B14: Total Occupancy | D14: =SUM(D11:D13) -> 823 | E14: =SUM(E11:E13) -> 1092 | F14: =SUM(D14/E14) -> 0.753663 | I14: Total Occupancy | K14: =SUM(K11:K13) -> 648 | L14: =SUM(L11:L13) -> 832 | M14: =SUM(K14/L14) -> 0.77884615 | P14: Total Occupancy | R14: =SUM(R11:R13) -> 569 | S14: =SUM(S11:S13) -> 744 | T14: =SUM(R14/S14) -> 0.76478495
B16: Thursday | C16: AM | D16: =GETPIVOTDATA("Sum of AM FIELD",'Pivot Table'!$A$4,"DAY","Thu") -> 313 | E16: =SUM(88+88+88+88) -> 352 | F16: =SUM(D16/E16) -> 0.88920455 | I16: Thursday | J16: AM | K16: =GETPIVOTDATA("Sum of AM FIELD",'Pivot Table'!$A$16,"DAY","Thu") -> 396 | L16: =SUM(88+88+88+88+88) -> 440 | M16: =SUM(K16/L16) -> 0.9 | P16: Thursday | Q16: AM | R16: =GETPIVOTDATA("Sum of AM FIELD",'Pivot Table'!$A$28,"DAY","Thu") -> 325 | S16: =SUM(88+88+88+88) -> 352 | T16: =SUM(R16/S16) -> 0.92329545
C17: PM | D17: =GETPIVOTDATA("Sum of PM FIELD",'Pivot Table'!$A$4,"DAY","Thu") -> 311 | E17: =SUM(96+96+96+96) -> 384 | F17: =SUM(D17/E17) -> 0.80989583 | J17: PM | K17: =GETPIVOTDATA("Sum of PM FIELD",'Pivot Table'!$A$16,"DAY","Thu") -> 372 | L17: =SUM(96+96+96+96+96) -> 480 | M17: =SUM(K17/L17) -> 0.775 | Q17: PM | R17: =GETPIVOTDATA("Sum of PM FIELD",'Pivot Table'!$A$28,"DAY","Thu") -> 280 | S17: =SUM(96+96+96+96) -> 384 | T17: =SUM(R17/S17) -> 0.72916667
B18: Total Occupancy | D18: =SUM(D15:D17) -> 624 | E18: =SUM(E15:E17) -> 736 | F18: =SUM(D18/E18) -> 0.84782609 | I18: Total Occupancy | K18: =SUM(K15:K17) -> 768 | L18: =SUM(L15:L17) -> 920 | M18: =SUM(K18/L18) -> 0.83478261 | P18: Total Occupancy | R18: =SUM(R15:R17) -> 605 | S18: =SUM(S15:S17) -> 736 | T18: =SUM(R18/S18) -> 0.82201087
B20: Friday | C20: AM | D20: =GETPIVOTDATA("Sum of AM FIELD",'Pivot Table'!$A$4,"DAY","Fri") -> 377 | E20: =SUM(108+108+108+104) -> 428 | F20: =SUM(D20/E20) -> 0.88084112 | I20: Friday | J20: AM | K20: =GETPIVOTDATA("Sum of AM FIELD",'Pivot Table'!$A$16,"DAY","Fri") -> 329 | L20: =SUM(104+100+100+54) -> 358 | M20: =SUM(K20/L20) -> 0.91899441 | P20: Friday | Q20: AM | R20: =GETPIVOTDATA("Sum of AM FIELD",'Pivot Table'!$A$28,"DAY","Fri") -> 399 | S20: =SUM(104+104+56+104+88) -> 456 | T20: =SUM(R20/S20) -> 0.875
C21: PM | D21: =GETPIVOTDATA("Sum of PM FIELD",'Pivot Table'!$A$4,"DAY","Fri") -> 309 | E21: =SUM(88+88+88+88) -> 352 | F21: =SUM(D21/E21) -> 0.87784091 | J21: PM | K21: =GETPIVOTDATA("Sum of PM FIELD",'Pivot Table'!$A$16,"DAY","Fri") -> 372 | L21: =SUM(176+96+104+68) -> 444 | M21: =SUM(K21/L21) -> 0.83783784 | Q21: PM | R21: =GETPIVOTDATA("Sum of PM FIELD",'Pivot Table'!$A$28,"DAY","Fri") -> 543 | S21: =SUM(136+168+80+96+96) -> 576 | T21: =SUM(R21/S21) -> 0.94270833
B22: Total Occupancy | D22: =SUM(D19:D21) -> 686 | E22: =SUM(E19:E21) -> 780 | F22: =SUM(D22/E22) -> 0.87948718 | I22: Total Occupancy | K22: =SUM(K19:K21) -> 701 | L22: =SUM(L19:L21) -> 802 | M22: =SUM(K22/L22) -> 0.87406484 | P22: Total Occupancy | R22: =SUM(R19:R21) -> 942 | S22: =SUM(S19:S21) -> 1032 | T22: =SUM(R22/S22) -> 0.9127907
B24: Saturday | C24: AM | D24: =GETPIVOTDATA("Sum of AM FIELD",'Pivot Table'!$A$4,"DAY","Sat") -> 376 | E24: =SUM(104+104+104+104) -> 416 | F24: =SUM(D24/E24) -> 0.90384615 | I24: Saturday | J24: AM | K24: =GETPIVOTDATA("Sum of AM FIELD",'Pivot Table'!$A$16,"DAY","Sat") -> 336 | L24: =SUM(104+104+68+80) -> 356 | M24: =SUM(K24/L24) -> 0.94382022 | P24: Saturday | Q24: AM | R24: =GETPIVOTDATA("Sum of AM FIELD",'Pivot Table'!$A$28,"DAY","Sat") -> 426 | S24: =SUM(104+96+96+88+88) -> 472 | T24: =SUM(R24/S24) -> 0.90254237
C25: PM | D25: =GETPIVOTDATA("Sum of PM FIELD",'Pivot Table'!$A$4,"DAY","Sat") -> 238 | E25: =SUM(92+88+88+88) -> 356 | F25: =SUM(D25/E25) -> 0.66853933 | J25: PM | K25: =GETPIVOTDATA("Sum of PM FIELD",'Pivot Table'!$A$16,"DAY","Sat") -> 341 | L25: =SUM(88+96+96+88) -> 368 | M25: =SUM(K25/L25) -> 0.92663043 | Q25: PM | R25: =GETPIVOTDATA("Sum of PM FIELD",'Pivot Table'!$A$28,"DAY","Sat") -> 268 | S25: =SUM(96+96+96+88+88) -> 464 | T25: =SUM(R25/S25) -> 0.57758621
B26: Total Occupancy | D26: =SUM(D23:D25) -> 614 | E26: =SUM(E23:E25) -> 772 | F26: =SUM(D26/E26) -> 0.79533679 | I26: Total Occupancy | K26: =SUM(K23:K25) -> 677 | L26: =SUM(L23:L25) -> 724 | M26: =SUM(K26/L26) -> 0.93508287 | P26: Total Occupancy | R26: =SUM(R23:R25) -> 694 | S26: =SUM(S23:S25) -> 936 | T26: =SUM(R26/S26) -> 0.74145299
B28: Sunday | C28: AM | D28: =GETPIVOTDATA("Sum of AM FIELD",'Pivot Table'!$A$4,"DAY","Sun") -> 395 | E28: =SUM(104+104+104+104) -> 416 | F28: =SUM(D28/E28) -> 0.94951923 | I28: Sunday | J28: AM | K28: =GETPIVOTDATA("Sum of AM FIELD",'Pivot Table'!$A$16,"DAY","Sun") -> 389 | L28: =SUM(104+104+104+104) -> 416 | M28: =SUM(K28/L28) -> 0.93509615 | P28: Sunday | Q28: AM | R28: =GETPIVOTDATA("Sum of AM FIELD",'Pivot Table'!$A$28,"DAY","Sun") -> 356 | S28: =SUM(104+96+76+40+88) -> 404 | T28: =SUM(R28/S28) -> 0.88118812
C29: PM | D29: =GETPIVOTDATA("Sum of PM FIELD",'Pivot Table'!$A$4,"DAY","Sun") -> 315 | E29: =SUM(96+96+96+96) -> 384 | F29: =SUM(D29/E29) -> 0.8203125 | J29: PM | K29: =GETPIVOTDATA("Sum of PM FIELD",'Pivot Table'!$A$16,"DAY","Sun") -> 290 | L29: =SUM(96+96+96+96) -> 384 | M29: =SUM(K29/L29) -> 0.75520833 | Q29: PM | R29: =GETPIVOTDATA("Sum of PM FIELD",'Pivot Table'!$A$28,"DAY","Sun") -> 298 | S29: =SUM(96+96+52+56+96) -> 396 | T29: =SUM(R29/S29) -> 0.75252525
B30: Total Occupancy | D30: =SUM(D27:D29) -> 710 | E30: =SUM(E27:E29) -> 800 | F30: =SUM(D30/E30) -> 0.8875 | I30: Total Occupancy | K30: =SUM(K27:K29) -> 679 | L30: =SUM(L27:L29) -> 800 | M30: =SUM(K30/L30) -> 0.84875 | P30: Total Occupancy | R30: =SUM(R27:R29) -> 654 | S30: =SUM(S27:S29) -> 800 | T30: =SUM(R30/S30) -> 0.8175
B33: April | D33: Bookings | E33: Spots Available | F33: Occupancy | G33: Notes | I33: May | K33: Bookings | L33: Spots Available | M33: Occupancy | N33: Notes | P33: June | R33: Bookings | S33: Spots Available | T33: Occupancy | U33: Notes
B35: Monday | C35: AM | D35: =GETPIVOTDATA("Sum of AM FIELD",'Pivot Table'!$A$40,"DAY","Mon") -> 234 | E35: =SUM(88+88+0+64+32) -> 272 | F35: =SUM(D35/E35) -> 0.86029412 | I35: Monday | J35: AM | K35: =GETPIVOTDATA("Sum of AM FIELD",'Pivot Table'!$A$52,"DAY","Mon") -> 164 | L35: =SUM(88+88+88+0) -> 264 | M35: =SUM(K35/L35) -> 0.62121212 | P35: Monday | Q35: AM | R35: =GETPIVOTDATA("Sum of AM FIELD",'Pivot Table'!$A$64,"DAY","Mon") -> 159 | S35: =SUM(88+88+76+0) -> 252 | T35: =SUM(R35/S35) -> 0.63095238
C36: PM | D36: =GETPIVOTDATA("Sum of PM FIELD",'Pivot Table'!$A$40,"DAY","Mon") -> 337 | E36: =SUM(96+80+80+88+80) -> 424 | F36: =SUM(D36/E36) -> 0.79481132 | J36: PM | K36: =GETPIVOTDATA("Sum of PM FIELD",'Pivot Table'!$A$52,"DAY","Mon") -> 292 | L36: =SUM(80+80+80+80) -> 320 | M36: =SUM(K36/L36) -> 0.9125 | Q36: PM | R36: =GETPIVOTDATA("Sum of PM FIELD",'Pivot Table'!$A$64,"DAY","Mon") -> 299 | S36: =SUM(80+72+80+80) -> 312 | T36: =SUM(R36/S36) -> 0.95833333
B37: Total Occupancy | D37: =SUM(D34:D36) -> 571 | E37: =SUM(E34:E36) -> 696 | F37: =SUM(D37/E37) -> 0.8204023 | I37: Total Occupancy | K37: =SUM(K34:K36) -> 456 | L37: =SUM(L34:L36) -> 584 | M37: =SUM(K37/L37) -> 0.78082192 | P37: Total Occupancy | R37: =SUM(R34:R36) -> 458 | S37: =SUM(S34:S36) -> 564 | T37: =SUM(R37/S37) -> 0.81205674
B39: Tuesday | C39: AM | D39: =GETPIVOTDATA("Sum of AM FIELD",'Pivot Table'!$A$40,"DAY","Tue") -> 345 | E39: =SUM(112+112+112+112+64) -> 512 | F39: =SUM(D39/E39) -> 0.67382812 | I39: Tuesday | J39: AM | K39: =GETPIVOTDATA("Sum of AM FIELD",'Pivot Table'!$A$52,"DAY","Tue") -> 342 | L39: =SUM(104+112+112+76) -> 404 | M39: =SUM(K39/L39) -> 0.84653465 | P39: Tuesday | Q39: AM | R39: =GETPIVOTDATA("Sum of AM FIELD",'Pivot Table'!$A$64,"DAY","Tue") -> 266 | S39: =SUM(112+112+84+112) -> 420 | T39: =SUM(R39/S39) -> 0.63333333
C40: PM | D40: =GETPIVOTDATA("Sum of PM FIELD",'Pivot Table'!$A$40,"DAY","Tue") -> 204 | E40: =SUM(80+80+80+80) -> 320 | F40: =SUM(D40/E40) -> 0.6375 | J40: PM | K40: =GETPIVOTDATA("Sum of PM FIELD",'Pivot Table'!$A$52,"DAY","Tue") -> 147 | L40: =SUM(80+80+80+80) -> 320 | M40: =SUM(K40/L40) -> 0.459375 | Q40: PM | R40: =GETPIVOTDATA("Sum of PM FIELD",'Pivot Table'!$A$64,"DAY","Tue") -> 80 | S40: =SUM(80+80+0+80) -> 240 | T40: =SUM(R40/S40) -> 0.33333333
B41: Total Occupancy | D41: =SUM(D38:D40) -> 549 | E41: =SUM(E38:E40) -> 832 | F41: =SUM(D41/E41) -> 0.65985577 | I41: Total Occupancy | K41: =SUM(K38:K40) -> 489 | L41: =SUM(L38:L40) -> 724 | M41: =SUM(K41/L41) -> 0.67541436 | P41: Total Occupancy | R41: =SUM(R38:R40) -> 346 | S41: =SUM(S38:S40) -> 660 | T41: =SUM(R41/S41) -> 0.52424242
B43: Wednesday | C43: AM | D43: =GETPIVOTDATA("Sum of AM FIELD",'Pivot Table'!$A$40,"DAY","Wed") -> 302 | E43: =SUM(108+96+108+104) -> 416 | F43: =SUM(D43/E43) -> 0.72596154 | I43: Wednesday | J43: AM | K43: =GETPIVOTDATA("Sum of AM FIELD",'Pivot Table'!$A$52,"DAY","Wed") -> 409 | L43: =SUM(90+104+112+108) -> 414 | M43: =SUM(K43/L43) -> 0.98792271 | P43: Wednesday | Q43: AM | R43: =GETPIVOTDATA("Sum of AM FIELD",'Pivot Table'!$A$64,"DAY","Wed") -> 246 | S43: =SUM(88+96+108+108) -> 400 | T43: =SUM(R43/S43) -> 0.615
C44: PM | D44: =GETPIVOTDATA("Sum of PM FIELD",'Pivot Table'!$A$40,"DAY","Wed") -> 339 | E44: =SUM(88+96+88+124) -> 396 | F44: =SUM(D44/E44) -> 0.85606061 | J44: PM | K44: =GETPIVOTDATA("Sum of PM FIELD",'Pivot Table'!$A$52,"DAY","Wed") -> 309 | L44: =SUM(104+88+100+88) -> 380 | M44: =SUM(K44/L44) -> 0.81315789 | Q44: PM | R44: =GETPIVOTDATA("Sum of PM FIELD",'Pivot Table'!$A$64,"DAY","Wed") -> 280 | S44: =SUM(116+100+88+88) -> 392 | T44: =SUM(R44/S44) -> 0.71428571
B45: Total Occupancy | D45: =SUM(D42:D44) -> 641 | E45: =SUM(E42:E44) -> 812 | F45: =SUM(D45/E45) -> 0.78940887 | I45: Total Occupancy | K45: =SUM(K42:K44) -> 718 | L45: =SUM(L42:L44) -> 794 | M45: =SUM(K45/L45) -> 0.90428212 | P45: Total Occupancy | R45: =SUM(R42:R44) -> 526 | S45: =SUM(S42:S44) -> 792 | T45: =SUM(R45/S45) -> 0.66414141
B47: Thursday | C47: AM | D47: =GETPIVOTDATA("Sum of AM FIELD",'Pivot Table'!$A$40,"DAY","Thu") -> 342 | E47: =SUM(88+80+80+104) -> 352 | F47: =SUM(D47/E47) -> 0.97159091 | I47: Thursday | J47: AM | K47: =GETPIVOTDATA("Sum of AM FIELD",'Pivot Table'!$A$52,"DAY","Thu") -> 364 | L47: =SUM(80+80+80+80+80) -> 400 | M47: =SUM(K47/L47) -> 0.91 | P47: Thursday | Q47: AM | R47: =GETPIVOTDATA("Sum of AM FIELD",'Pivot Table'!$A$64,"DAY","Thu") -> 280 | S47: =SUM(80+80+80+80) -> 320 | T47: =SUM(R47/S47) -> 0.875
C48: PM | D48: =GETPIVOTDATA("Sum of PM FIELD",'Pivot Table'!$A$40,"DAY","Thu") -> 344 | E48: =SUM(96+96+96+96) -> 384 | F48: =SUM(D48/E48) -> 0.89583333 | J48: PM | K48: =GETPIVOTDATA("Sum of PM FIELD",'Pivot Table'!$A$52,"DAY","Thu") -> 404 | L48: =SUM(96+100+96+96+96) -> 484 | M48: =SUM(K48/L48) -> 0.83471074 | Q48: PM | R48: =GETPIVOTDATA("Sum of PM FIELD",'Pivot Table'!$A$64,"DAY","Thu") -> 292 | S48: =SUM(96+96+96+96) -> 384 | T48: =SUM(R48/S48) -> 0.76041667
B49: Total Occupancy | D49: =SUM(D46:D48) -> 686 | E49: =SUM(E46:E48) -> 736 | F49: =SUM(D49/E49) -> 0.93206522 | I49: Total Occupancy | K49: =SUM(K46:K48) -> 768 | L49: =SUM(L46:L48) -> 884 | M49: =SUM(K49/L49) -> 0.86877828 | P49: Total Occupancy | R49: =SUM(R46:R48) -> 572 | S49: =SUM(S46:S48) -> 704 | T49: =SUM(R49/S49) -> 0.8125
B51: Friday | C51: AM | D51: =GETPIVOTDATA("Sum of AM FIELD",'Pivot Table'!$A$40,"DAY","Fri") -> 385 | E51: =SUM(108+104+108+108) -> 428 | F51: =SUM(D51/E51) -> 0.89953271 | I51: Friday | J51: AM | K51: =GETPIVOTDATA("Sum of AM FIELD",'Pivot Table'!$A$52,"DAY","Fri") -> 498 | L51: =SUM(104+120+108+108+108) -> 548 | M51: =SUM(K51/L51) -> 0.90875912 | P51: Friday | Q51: AM | R51: =GETPIVOTDATA("Sum of AM FIELD",'Pivot Table'!$A$64,"DAY","Fri") -> 346 | S51: =SUM(108+108+108+108) -> 432 | T51: =SUM(R51/S51) -> 0.80092593
C52: PM | D52: =GETPIVOTDATA("Sum of PM FIELD",'Pivot Table'!$A$40,"DAY","Fri") -> 297 | E52: =SUM(88+56+88+88) -> 320 | F52: =SUM(D52/E52) -> 0.928125 | J52: PM | K52: =GETPIVOTDATA("Sum of PM FIELD",'Pivot Table'!$A$52,"DAY","Fri") -> 367 | L52: =SUM(88+104+92+88+88) -> 460 | M52: =SUM(K52/L52) -> 0.79782609 | Q52: PM | R52: =GETPIVOTDATA("Sum of PM FIELD",'Pivot Table'!$A$64,"DAY","Fri") -> 258 | S52: =SUM(88+88+88+88) -> 352 | T52: =SUM(R52/S52) -> 0.73295455
B53: Total Occupancy | D53: =SUM(D50:D52) -> 682 | E53: =SUM(E50:E52) -> 748 | F53: =SUM(D53/E53) -> 0.91176471 | I53: Total Occupancy | K53: =SUM(K50:K52) -> 865 | L53: =SUM(L50:L52) -> 1008 | M53: =SUM(K53/L53) -> 0.85813492 | P53: Total Occupancy | R53: =SUM(R50:R52) -> 604 | S53: =SUM(S50:S52) -> 784 | T53: =SUM(R53/S53) -> 0.77040816
B55: Saturday | C55: AM | D55: =GETPIVOTDATA("Sum of AM FIELD",'Pivot Table'!$A$40,"DAY","Sat") -> 324 | E55: =SUM(80+108+96+76) -> 360 | F55: =SUM(D55/E55) -> 0.9 | I55: Saturday | J55: AM | K55: =GETPIVOTDATA("Sum of AM FIELD",'Pivot Table'!$A$52,"DAY","Sat") -> 356 | L55: =SUM(112+104+96+88) -> 400 | M55: =SUM(K55/L55) -> 0.89 | P55: Saturday | Q55: AM | R55: =GETPIVOTDATA("Sum of AM FIELD",'Pivot Table'!$A$64,"DAY","Sat") -> 356 | S55: =SUM(88+88+88+72+80) -> 416 | T55: =SUM(R55/S55) -> 0.85576923
C56: PM | D56: =GETPIVOTDATA("Sum of PM FIELD",'Pivot Table'!$A$40,"DAY","Sat") -> 287 | E56: =SUM(88+92+90+88) -> 358 | F56: =SUM(D56/E56) -> 0.80167598 | J56: PM | K56: =GETPIVOTDATA("Sum of PM FIELD",'Pivot Table'!$A$52,"DAY","Sat") -> 295 | L56: =SUM(96+88+88+88) -> 360 | M56: =SUM(K56/L56) -> 0.81944444 | Q56: PM | R56: =GETPIVOTDATA("Sum of PM FIELD",'Pivot Table'!$A$64,"DAY","Sat") -> 251 | S56: =SUM(80+88+88+80+88) -> 424 | T56: =SUM(R56/S56) -> 0.59198113
...

Sheet Occupancy Report Summarised
B2: 2024 Totals (By Day) | D2: Bookings | E2: Spots Available | F2: Occupancy | G2: Notes | J2: 2024 Totals (By Month) | L2: Bookings | M2: Spots Available | N2: Occupancy | O2: Notes
B4: Monday | C4: AM | D4: ='Occupancy Report'!D4+'Occupancy Report'!K4+'Occupancy Report'!R4+'Occupancy Report'!D35+'Occupancy Report'!K35+'Occupancy Report'!R35+'Occupancy Report'!D66+'Occupancy Report'!K66+'Occupancy Report'!R66+'Occupancy Report'!D97+'Occupancy Report'!K97+'Occupancy Report'!R97 -> 2260 | E4: ='Occupancy Report'!E4+'Occupancy Report'!L4+'Occupancy Report'!S4+'Occupancy Report'!S35+'Occupancy Report'!L35+'Occupancy Report'!E35+'Occupancy Report'!E66+'Occupancy Report'!L66+'Occupancy Report'!S66+'Occupancy Report'!S97+'Occupancy Report'!L97+'Occupancy Report'!E97 -> 3394 | F4: =SUM(D4/E4) -> 0.66588097 | J4: January | K4: AM | L4: ='Occupancy Report'!D4+'Occupancy Report'!D8+'Occupancy Report'!D12+'Occupancy Report'!D16+'Occupancy Report'!D20+'Occupancy Report'!D24+'Occupancy Report'!D28 -> 2561 | M4: ='Occupancy Report'!E4+'Occupancy Report'!E8+'Occupancy Report'!E12+'Occupancy Report'!E16+'Occupancy Report'!E20+'Occupancy Report'!E24+'Occupancy Report'!E28 -> 3124 | N4: =SUM(L4/M4) -> 0.81978233
C5: PM | D5: ='Occupancy Report'!D5+'Occupancy Report'!L5+'Occupancy Report'!R5+'Occupancy Report'!R36+'Occupancy Report'!K36+'Occupancy Report'!D36+'Occupancy Report'!D67+'Occupancy Report'!K67+'Occupancy Report'!R67+'Occupancy Report'!R98+'Occupancy Report'!K98+'Occupancy Report'!D98 -> 3467 | E5: ='Occupancy Report'!E5+'Occupancy Report'!L5+'Occupancy Report'!S4+'Occupancy Report'!S36+'Occupancy Report'!L36+'Occupancy Report'!E36+'Occupancy Report'!E67+'Occupancy Report'!L67+'Occupancy Report'!S67+'Occupancy Report'!S98+'Occupancy Report'!L98+'Occupancy Report'!E98 -> 4192 | F5: =SUM(D5/E5) -> 0.82705153 | K5: PM | L5: ='Occupancy Report'!D5+'Occupancy Report'!D9+'Occupancy Report'!D13+'Occupancy Report'!D17+'Occupancy Report'!D21+'Occupancy Report'!D25+'Occupancy Report'!D29 -> 2044 | M5: ='Occupancy Report'!E5+'Occupancy Report'!E9+'Occupancy Report'!E13+'Occupancy Report'!E17+'Occupancy Report'!E21+'Occupancy Report'!E25+'Occupancy Report'!E29 -> 2928 | N5: =SUM(L5/M5) -> 0.69808743
B6: Total Monday Occupancy | D6: =SUM(D4:D5) -> 5727 | E6: =SUM(E4:E5) -> 7586 | F6: =SUM(D6/E6) -> 0.75494332 | J6: Total January Occupancy | L6: =SUM(L4:L5) -> 4605 | M6: =SUM(M4:M5) -> 6052 | N6: =SUM(L6/M6) -> 0.76090549
B8: Tuesday | C8: AM | D8: ='Occupancy Report'!D8+'Occupancy Report'!K8+'Occupancy Report'!R8+'Occupancy Report'!R39+'Occupancy Report'!K39+'Occupancy Report'!D39+'Occupancy Report'!D70+'Occupancy Report'!K70+'Occupancy Report'!R70+'Occupancy Report'!R101+'Occupancy Report'!K101+'Occupancy Report'!D101 -> 4220 | E8: ='Occupancy Report'!E8+'Occupancy Report'!L8+'Occupancy Report'!S8+'Occupancy Report'!S39+'Occupancy Report'!L39+'Occupancy Report'!E39+'Occupancy Report'!E70+'Occupancy Report'!L70+'Occupancy Report'!S70+'Occupancy Report'!S101+'Occupancy Report'!L101+'Occupancy Report'!E101 -> 5468 | F8: =SUM(D8/E8) -> 0.77176298 | J8: February | K8: AM | L8: ='Occupancy Report'!K4+'Occupancy Report'!K8+'Occupancy Report'!K12+'Occupancy Report'!K16+'Occupancy Report'!K20+'Occupancy Report'!K24+'Occupancy Report'!K28 -> 2248 | M8: ='Occupancy Report'!L4+'Occupancy Report'!L8+'Occupancy Report'!L12+'Occupancy Report'!L16+'Occupancy Report'!L20+'Occupancy Report'!L24+'Occupancy Report'!L28 -> 2690 | N8: =SUM(L8/M8) -> 0.83568773
C9: PM | D9: ='Occupancy Report'!D9+'Occupancy Report'!K9+'Occupancy Report'!R9+'Occupancy Report'!R40+'Occupancy Report'!K40+'Occupancy Report'!D40+'Occupancy Report'!D71+'Occupancy Report'!K71+'Occupancy Report'!R71+'Occupancy Report'!R102+'Occupancy Report'!K102+'Occupancy Report'!D102 -> 1635 | E9: ='Occupancy Report'!E9+'Occupancy Report'!L9+'Occupancy Report'!S9+'Occupancy Report'!S40+'Occupancy Report'!L40+'Occupancy Report'!E40+'Occupancy Report'!E71+'Occupancy Report'!L71+'Occupancy Report'!S71+'Occupancy Report'!S102+'Occupancy Report'!L102+'Occupancy Report'!E102 -> 3800 | F9: =SUM(D9/E9) -> 0.43026316 | K9: PM | L9: ='Occupancy Report'!K5+'Occupancy Report'!K9+'Occupancy Report'!K13+'Occupancy Report'!K17+'Occupancy Report'!K21+'Occupancy Report'!K25+'Occupancy Report'!K29 -> 2165 | M9: ='Occupancy Report'!L5+'Occupancy Report'!L9+'Occupancy Report'!L13+'Occupancy Report'!L17+'Occupancy Report'!L21+'Occupancy Report'!L25+'Occupancy Report'!L29 -> 2788 | N9: =SUM(L9/M9) -> 0.77654232
B10: Total Tuesday Occupancy | D10: =SUM(D8:D9) -> 5855 | E10: =SUM(E8:E9) -> 9268 | F10: =SUM(D10/E10) -> 0.63174363 | J10: Total February Occupancy | L10: =SUM(L8:L9) -> 4413 | M10: =SUM(M8:M9) -> 5478 | N10: =SUM(L10/M10) -> 0.80558598
B12: Wednesday | C12: AM | D12: ='Occupancy Report'!D12+'Occupancy Report'!K12+'Occupancy Report'!R12+'Occupancy Report'!R43+'Occupancy Report'!K43+'Occupancy Report'!D43+'Occupancy Report'!D74+'Occupancy Report'!K74+'Occupancy Report'!R74+'Occupancy Report'!R105+'Occupancy Report'!K105+'Occupancy Report'!D105 -> 3352 | E12: ='Occupancy Report'!E12+'Occupancy Report'!L12+'Occupancy Report'!S12+'Occupancy Report'!S43+'Occupancy Report'!L43+'Occupancy Report'!E43+'Occupancy Report'!E74+'Occupancy Report'!L74+'Occupancy Report'!S74+'Occupancy Report'!S105+'Occupancy Report'!L105+'Occupancy Report'!E105 -> 4632 | F12: =SUM(D12/E12) -> 0.72366149 | J12: March | K12: AM | L12: =GETPIVOTDATA("Sum of AM FIELD",'Pivot Table'!$A$28) -> 2385 | M12: ='Occupancy Report'!S4+'Occupancy Report'!S8+'Occupancy Report'!S12+'Occupancy Report'!S16+'Occupancy Report'!S20+'Occupancy Report'!S24+'Occupancy Report'!S28 -> 2784 | N12: =SUM(L12/M12) -> 0.85668103
C13: PM | D13: ='Occupancy Report'!D13+'Occupancy Report'!K13+'Occupancy Report'!R13+'Occupancy Report'!R44+'Occupancy Report'!K44+'Occupancy Report'!D44+'Occupancy Report'!D75+'Occupancy Report'!K75+'Occupancy Report'!R75+'Occupancy Report'!R106+'Occupancy Report'!K106+'Occupancy Report'!D106 -> 3559 | E13: ='Occupancy Report'!E13+'Occupancy Report'!L13+'Occupancy Report'!S13+'Occupancy Report'!S44+'Occupancy Report'!L44+'Occupancy Report'!E44+'Occupancy Report'!E75+'Occupancy Report'!L75+'Occupancy Report'!S75+'Occupancy Report'!S106+'Occupancy Report'!L106+'Occupancy Report'!E106 -> 4734 | F13: =SUM(D13/E13) -> 0.75179552 | K13: PM | L13: =GETPIVOTDATA("Sum of PM FIELD",'Pivot Table'!$A$28) -> 2029 | M13: ='Occupancy Report'!S5+'Occupancy Report'!S9+'Occupancy Report'!S13+'Occupancy Report'!S17+'Occupancy Report'!S21+'Occupancy Report'!S25+'Occupancy Report'!S29 -> 2832 | N13: =SUM(L13/M13) -> 0.7164548
B14: Total Wednesday Occupancy | D14: =SUM(D12:D13) -> 6911 | E14: =SUM(E12:E13) -> 9366 | F14: =SUM(D14/E14) -> 0.7378817 | J14: Total March Occupancy | L14: =SUM(L12:L13) -> 4414 | M14: =SUM(M12:M13) -> 5616 | N14: =SUM(L14/M14) -> 0.78596866
B16: Thursday | C16: AM | D16: ='Occupancy Report'!D16+'Occupancy Report'!K16+'Occupancy Report'!R16+'Occupancy Report'!R47+'Occupancy Report'!K47+'Occupancy Report'!D47+'Occupancy Report'!D78+'Occupancy Report'!K78+'Occupancy Report'!R78+'Occupancy Report'!R109+'Occupancy Report'!K109+'Occupancy Report'!D109 -> 3874 | E16: ='Occupancy Report'!E16+'Occupancy Report'!L16+'Occupancy Report'!S16+'Occupancy Report'!S47+'Occupancy Report'!L47+'Occupancy Report'!E47+'Occupancy Report'!E78+'Occupancy Report'!L78+'Occupancy Report'!S78+'Occupancy Report'!S109+'Occupancy Report'!L109+'Occupancy Report'!E109 -> 4308 | F16: =SUM(D16/E16) -> 0.8992572 | J16: April | K16: AM | L16: =GETPIVOTDATA("Sum of AM FIELD",'Pivot Table'!$A$40) -> 2280 | M16: ='Occupancy Report'!E35+'Occupancy Report'!E39+'Occupancy Report'!E43+'Occupancy Report'!E47+'Occupancy Report'!E51+'Occupancy Report'!E55+'Occupancy Report'!E59 -> 2708 | N16: =SUM(L16/M16) -> 0.84194978
C17: PM | D17: ='Occupancy Report'!D17+'Occupancy Report'!K17+'Occupancy Report'!R17+'Occupancy Report'!R48+'Occupancy Report'!K48+'Occupancy Report'!D48+'Occupancy Report'!D79+'Occupancy Report'!K79+'Occupancy Report'!R79+'Occupancy Report'!R110+'Occupancy Report'!K110+'Occupancy Report'!D110 -> 3826 | E17: ='Occupancy Report'!E17+'Occupancy Report'!L17+'Occupancy Report'!S17+'Occupancy Report'!S48+'Occupancy Report'!L48+'Occupancy Report'!E48+'Occupancy Report'!E79+'Occupancy Report'!L79+'Occupancy Report'!S79+'Occupancy Report'!S110+'Occupancy Report'!L110+'Occupancy Report'!E110 -> 4888 | F17: =SUM(D17/E17) -> 0.78273322 | K17: PM | L17: =GETPIVOTDATA("Sum of PM FIELD",'Pivot Table'!$A$40) -> 2120 | M17: ='Occupancy Report'!E36+'Occupancy Report'!E40+'Occupancy Report'!E44+'Occupancy Report'!E48+'Occupancy Report'!E52+'Occupancy Report'!E56+'Occupancy Report'!E60 -> 2570 | N17: =SUM(L17/M17) -> 0.82490272
B18: Total Thursday Occupancy | D18: =SUM(D16:D17) -> 7700 | E18: =SUM(E16:E17) -> 9196 | F18: =SUM(D18/E18) -> 0.83732057 | J18: Total April Occupancy | L18: =SUM(L16:L17) -> 4400 | M18: =SUM(M16:M17) -> 5278 | N18: =SUM(L18/M18) -> 0.83364911
B20: Friday | C20: AM | D20: ='Occupancy Report'!D20+'Occupancy Report'!K20+'Occupancy Report'!R20+'Occupancy Report'!R51+'Occupancy Report'!K51+'Occupancy Report'!D51+'Occupancy Report'!D82+'Occupancy Report'!K82+'Occupancy Report'!R82+'Occupancy Report'!R113+'Occupancy Report'!K113+'Occupancy Report'!D113 -> 4579 | E20: ='Occupancy Report'!E20+'Occupancy Report'!L20+'Occupancy Report'!S20+'Occupancy Report'!S51+'Occupancy Report'!L51+'Occupancy Report'!E51+'Occupancy Report'!E82+'Occupancy Report'!L82+'Occupancy Report'!S82+'Occupancy Report'!S113+'Occupancy Report'!L113+'Occupancy Report'!E113 -> 5318 | F20: =SUM(D20/E20) -> 0.86103798 | J20: May | K20: AM | L20: =GETPIVOTDATA("Sum of AM FIELD",'Pivot Table'!$A$52) -> 2487 | M20: ='Occupancy Report'!L35+'Occupancy Report'!L39+'Occupancy Report'!L43+'Occupancy Report'!L47+'Occupancy Report'!L51+'Occupancy Report'!L55+'Occupancy Report'!L59 -> 2822 | N20: =SUM(L20/M20) -> 0.88128987
C21: PM | D21: ='Occupancy Report'!D21+'Occupancy Report'!K21+'Occupancy Report'!R21+'Occupancy Report'!R52+'Occupancy Report'!K52+'Occupancy Report'!D52+'Occupancy Report'!D83+'Occupancy Report'!K83+'Occupancy Report'!R83+'Occupancy Report'!R114+'Occupancy Report'!K114+'Occupancy Report'!D114 -> 3759 | E21: ='Occupancy Report'!E21+'Occupancy Report'!L21+'Occupancy Report'!S21+'Occupancy Report'!S52+'Occupancy Report'!L52+'Occupancy Report'!E52+'Occupancy Report'!E83+'Occupancy Report'!L83+'Occupancy Report'!S83+'Occupancy Report'!S114+'Occupancy Report'!L114+'Occupancy Report'!E114 -> 4684 | F21: =SUM(D21/E21) -> 0.80251921 | K21: PM | L21: =GETPIVOTDATA("Sum of PM FIELD",'Pivot Table'!$A$52) -> 2173 | M21: ='Occupancy Report'!L60+'Occupancy Report'!L56+'Occupancy Report'!L52+'Occupancy Report'!L48+'Occupancy Report'!L44+'Occupancy Report'!L40+'Occupancy Report'!L36 -> 2720 | N21: =SUM(L21/M21) -> 0.79889706
B22: Total Friday Occupancy | D22: =SUM(D20:D21) -> 8338 | E22: =SUM(E20:E21) -> 10002 | F22: =SUM(D22/E22) -> 0.83363327 | J22: Total May Occupancy | L22: =SUM(L20:L21) -> 4660 | M22: =SUM(M20:M21) -> 5542 | N22: =SUM(L22/M22) -> 0.84085168
B24: Saturday | C24: AM | D24: ='Occupancy Report'!D24+'Occupancy Report'!K24+'Occupancy Report'!R24+'Occupancy Report'!R55+'Occupancy Report'!K55+'Occupancy Report'!D55+'Occupancy Report'!D86+'Occupancy Report'!K86+'Occupancy Report'!R86+'Occupancy Report'!R117+'Occupancy Report'!K117+'Occupancy Report'!D117 -> 4305 | E24: ='Occupancy Report'!E24+'Occupancy Report'!L24+'Occupancy Report'!S24+'Occupancy Report'!S55+'Occupancy Report'!L55+'Occupancy Report'!E55+'Occupancy Report'!E86+'Occupancy Report'!L86+'Occupancy Report'!S86+'Occupancy Report'!S117+'Occupancy Report'!L117+'Occupancy Report'!E117 -> 4888 | F24: =SUM(D24/E24) -> 0.88072831 | J24: June | K24: AM | L24: =GETPIVOTDATA("Sum of AM FIELD",'Pivot Table'!$A$64) -> 2046 | M24: ='Occupancy Report'!S35+'Occupancy Report'!S39+'Occupancy Report'!S43+'Occupancy Report'!S47+'Occupancy Report'!S51+'Occupancy Report'!S55+'Occupancy Report'!S59 -> 2680 | N24: =SUM(L24/M24) -> 0.76343284
C25: PM | D25: ='Occupancy Report'!D25+'Occupancy Report'!K25+'Occupancy Report'!R25+'Occupancy Report'!R56+'Occupancy Report'!K56+'Occupancy Report'!D56+'Occupancy Report'!D87+'Occupancy Report'!K87+'Occupancy Report'!R87+'Occupancy Report'!R118+'Occupancy Report'!K118+'Occupancy Report'!D118 -> 3315 | E25: ='Occupancy Report'!E25+'Occupancy Report'!L25+'Occupancy Report'!S25+'Occupancy Report'!S56+'Occupancy Report'!L56+'Occupancy Report'!E56+'Occupancy Report'!E87+'Occupancy Report'!L87+'Occupancy Report'!S87+'Occupancy Report'!S118+'Occupancy Report'!L118+'Occupancy Report'!E118 -> 4638 | F25: =SUM(D25/E25) -> 0.71474774 | K25: PM | L25: =GETPIVOTDATA("Sum of PM FIELD",'Pivot Table'!$A$64) -> 1859 | M25: ='Occupancy Report'!S36+'Occupancy Report'!S40+'Occupancy Report'!S44+'Occupancy Report'!S48+'Occupancy Report'!S52+'Occupancy Report'!S56+'Occupancy Report'!S60 -> 2576 | N25: =SUM(L25/M25) -> 0.72166149
B26: Total Saturday Occupancy | D26: =SUM(D24:D25) -> 7620 | E26: =SUM(E24:E25) -> 9526 | F26: =SUM(D26/E26) -> 0.79991602 | J26: Total June Occupancy | L26: =SUM(L24:L25) -> 3905 | M26: =SUM(M24:M25) -> 5256 | N26: =SUM(L26/M26) -> 0.74296043
B28: Sunday | C28: AM | D28: ='Occupancy Report'!D28+'Occupancy Report'!K28+'Occupancy Report'!R28+'Occupancy Report'!R59+'Occupancy Report'!K59+'Occupancy Report'!D59+'Occupancy Report'!D90+'Occupancy Report'!K90+'Occupancy Report'!R90+'Occupancy Report'!R121+'Occupancy Report'!K121+'Occupancy Report'!D121 -> 4326 | E28: ='Occupancy Report'!E28+'Occupancy Report'!L28+'Occupancy Report'!S28+'Occupancy Report'!S59+'Occupancy Report'!L59+'Occupancy Report'!E59+'Occupancy Report'!E90+'Occupancy Report'!L90+'Occupancy Report'!S90+'Occupancy Report'!S121+'Occupancy Report'!L121+'Occupancy Report'!E121 -> 4748 | F28: =SUM(D28/E28) -> 0.91112047 | J28: July | K28: AM | L28: ='Occupancy Report'!D66+'Occupancy Report'!D70+'Occupancy Report'!D74+'Occupancy Report'!D78+'Occupancy Report'!D82+'Occupancy Report'!D86+'Occupancy Report'!D90 -> 1966 | M28: ='Occupancy Report'!E66+'Occupancy Report'!E70+'Occupancy Report'!E74+'Occupancy Report'!E78+'Occupancy Report'!E82+'Occupancy Report'!E86+'Occupancy Report'!E90 -> 2816 | N28: =SUM(L28/M28) -> 0.69815341
C29: PM | D29: ='Occupancy Report'!D29+'Occupancy Report'!K29+'Occupancy Report'!R29+'Occupancy Report'!R60+'Occupancy Report'!K60+'Occupancy Report'!D60+'Occupancy Report'!D91+'Occupancy Report'!K91+'Occupancy Report'!R91+'Occupancy Report'!R122+'Occupancy Report'!K122+'Occupancy Report'!D122 -> 3792 | E29: ='Occupancy Report'!E29+'Occupancy Report'!L29+'Occupancy Report'!S29+'Occupancy Report'!S60+'Occupancy Report'!L60+'Occupancy Report'!E60+'Occupancy Report'!E91+'Occupancy Report'!L91+'Occupancy Report'!S91+'Occupancy Report'!S122+'Occupancy Report'!L122+'Occupancy Report'!E122 -> 4576 | F29: =SUM(D29/E29) -> 0.82867133 | K29: PM | L29: ='Occupancy Report'!D67+'Occupancy Report'!D71+'Occupancy Report'!D75+'Occupancy Report'!D79+'Occupancy Report'!D83+'Occupancy Report'!D87+'Occupancy Report'!D91 -> 1784 | M29: ='Occupancy Report'!E67+'Occupancy Report'!E71+'Occupancy Report'!E75+'Occupancy Report'!E79+'Occupancy Report'!E83++'Occupancy Report'!E87+'Occupancy Report'!E91 -> 2672 | N29: =SUM(L29/M29) -> 0.66766467
B30: Total Sunday Occupancy | D30: =SUM(D28:D29) -> 8118 | E30: =SUM(E28:E29) -> 9324 | F30: =SUM(D30/E30) -> 0.87065637 | J30: Total July Occupancy | L30: =SUM(L28:L29) -> 3750 | M30: =SUM(M28:M29) -> 5488 | N30: =SUM(L30/M30) -> 0.68330904
J32: August | K32: AM | L32: ='Occupancy Report'!K66+'Occupancy Report'!K70+'Occupancy Report'!K74+'Occupancy Report'!K78+'Occupancy Report'!K82+'Occupancy Report'!K86+'Occupancy Report'!K90 -> 2248 | M32: ='Occupancy Report'!L66+'Occupancy Report'!L70+'Occupancy Report'!L74+'Occupancy Report'!L78+'Occupancy Report'!L82+'Occupancy Report'!L86+'Occupancy Report'!L90 -> 2900 | N32: =SUM(L32/M32) -> 0.77517241
K33: PM | L33: ='Occupancy Report'!K67+'Occupancy Report'!K71+'Occupancy Report'!K75+'Occupancy Report'!K79+'Occupancy Report'!K83+'Occupancy Report'!K87+'Occupancy Report'!K91 -> 1807 | M33: ='Occupancy Report'!L67+'Occupancy Report'!L71+'Occupancy Report'!L75+'Occupancy Report'!L79+'Occupancy Report'!L83+'Occupancy Report'!L87+'Occupancy Report'!L91 -> 2756 | N33: =SUM(L33/M33) -> 0.65566038
J34: Total August Occupancy | L34: =SUM(L32:L33) -> 4055 | M34: =SUM(M32:M33) -> 5656 | N34: =SUM(L34/M34) -> 0.71693777
J36: September | K36: AM | L36: =GETPIVOTDATA("Sum of AM FIELD",'Pivot Table'!$A$100) -> 2254 | M36: ='Occupancy Report'!S66+'Occupancy Report'!S70+'Occupancy Report'!S74+'Occupancy Report'!S78+'Occupancy Report'!S82+'Occupancy Report'!S86+'Occupancy Report'!S90 -> 2856 | N36: =SUM(L36/M36) -> 0.78921569
K37: PM | L37: =GETPIVOTDATA("Sum of PM FIELD",'Pivot Table'!$A$100) -> 1835 | M37: ='Occupancy Report'!S67+'Occupancy Report'!S71+'Occupancy Report'!S75+'Occupancy Report'!S79+'Occupancy Report'!S83+'Occupancy Report'!S87+'Occupancy Report'!S91 -> 2604 | N37: =SUM(L37/M37) -> 0.7046851
J38: Total September Occupancy | L38: =SUM(L36:L37) -> 4089 | M38: =SUM(M36:M37) -> 5460 | N38: =SUM(L38/M38) -> 0.7489011
J40: October | K40: AM | L40: =GETPIVOTDATA("Sum of AM FIELD",'Pivot Table'!$A$112) -> 2109 | M40: ='Occupancy Report'!E97+'Occupancy Report'!E101+'Occupancy Report'!E105+'Occupancy Report'!E109+'Occupancy Report'!E113+'Occupancy Report'!E117+'Occupancy Report'!E121 -> 2428 | N40: =SUM(L40/M40) -> 0.86861614
K41: PM | L41: =GETPIVOTDATA("Sum of PM FIELD",'Pivot Table'!$A$112) -> 2049 | M41: ='Occupancy Report'!E98+'Occupancy Report'!E102+'Occupancy Report'!E106+'Occupancy Report'!E110+'Occupancy Report'!E114+'Occupancy Report'!E118+'Occupancy Report'!E122 -> 2572 | N41: =SUM(L41/M41) -> 0.7966563
J42: Total October Occupancy | L42: =SUM(L40:L41) -> 4158 | M42: =SUM(M40:M41) -> 5000 | N42: =SUM(L42/M42) -> 0.8316
J44: November | K44: AM | L44: =GETPIVOTDATA("Sum of AM FIELD",'Pivot Table'!$A$124) -> 1975 | M44: ='Occupancy Report'!L97+'Occupancy Report'!L101+'Occupancy Report'!L105+'Occupancy Report'!L109+'Occupancy Report'!L113+'Occupancy Report'!L117+'Occupancy Report'!L121 -> 2264 | N44: =SUM(L44/M44) -> 0.87234982
K45: PM | L45: =GETPIVOTDATA("Sum of PM FIELD",'Pivot Table'!$A$124) -> 1578 | M45: ='Occupancy Report'!L98+'Occupancy Report'!L102+'Occupancy Report'!L106+'Occupancy Report'!L110+'Occupancy Report'!L114+'Occupancy Report'!L118+'Occupancy Report'!L122 -> 2108 | N45: =SUM(L45/M45) -> 0.74857685
J46: Total November Occupancy | L46: =SUM(L44:L45) -> 3553 | M46: =SUM(M44:M45) -> 4372 | N46: =SUM(L46/M46) -> 0.81267155
J48: December | K48: AM | L48: =GETPIVOTDATA("Sum of AM FIELD",'Pivot Table'!$A$136) -> 2357 | M48: ='Occupancy Report'!S97+'Occupancy Report'!S101+'Occupancy Report'!S105+'Occupancy Report'!S109+'Occupancy Report'!S113+'Occupancy Report'!S117+'Occupancy Report'!S121 -> 2684 | N48: =SUM(L48/M48) -> 0.87816692
K49: PM | L49: =GETPIVOTDATA("Sum of PM FIELD",'Pivot Table'!$A$136) -> 1842 | M49: ='Occupancy Report'!S98+'Occupancy Report'!S102+'Occupancy Report'!S106+'Occupancy Report'!S110+'Occupancy Report'!S114+'Occupancy Report'!S118+'Occupancy Report'!S122 -> 2458 | N49: =SUM(L49/M49) -> 0.74938975
J50: Total December Occupancy | L50: =SUM(L48:L49) -> 4199 | M50: =SUM(M48:M49) -> 5142 | N50: =SUM(L50/M50) -> 0.81660832

Sheet Day by Day Totals
B2: Day by Totals
B4: Monday | E4: Tuesday | H4: Wednesday | K4: Thursday | N4: Friday | Q4: Saturday | T4: Sunday
B6: AM Field | C6: =GETPIVOTDATA("Sum of AM FIELD",'Pivot Table'!$A$4,"DAY","Mon")+GETPIVOTDATA("Sum of AM FIELD",'Pivot Table'!$A$16,"DAY","Mon")+GETPIVOTDATA("Sum of AM FIELD",'Pivot Table'!$A$28,"DAY","Mon")+GETPIVOTDATA("Sum of AM FIELD",'Pivot Table'!$A$40,"DAY","Mon")+GETPIVOTDATA("Sum of AM FIELD",'Pivot Table'!$A$52,"DAY","Mon")+GETPIVOTDATA("Sum of AM FIELD",'Pivot Table'!$A$64,"DAY","Mon")+GETPIVOTDATA("Sum of AM FIELD",'Pivot Table'!$A$76,"DAY","Mon")+GETPIVOTDATA("Sum of AM FIELD",'Pivot Table'!$A$88,"DAY","Mon")+GETPIVOTDATA("Sum of AM FIELD",'Pivot Table'!$A$100,"DAY","Mon")+GETPIVOTDATA("Sum of AM FIELD",'Pivot Table'!$A$112,"DAY","Mon")+GETPIVOTDATA("Sum of AM FIELD",'Pivot Table'!$A$124,"DAY","Mon")+GETPIVOTDATA("Sum of AM FIELD",'Pivot Table'!$A$136,"DAY","Mon") -> 2260 | E6: AM Field | F6: =GETPIVOTDATA("Sum of AM FIELD",'Pivot Table'!$A$4,"DAY","Tue")+GETPIVOTDATA("Sum of AM FIELD",'Pivot Table'!$A$16,"DAY","Tue")+GETPIVOTDATA("Sum of AM FIELD",'Pivot Table'!$A$28,"DAY","Tue")+GETPIVOTDATA("Sum of AM FIELD",'Pivot Table'!$A$40,"DAY","Tue")+GETPIVOTDATA("Sum of AM FIELD",'Pivot Table'!$A$52,"DAY","Tue")+GETPIVOTDATA("Sum of AM FIELD",'Pivot Table'!$A$64,"DAY","Tue")+GETPIVOTDATA("Sum of AM FIELD",'Pivot Table'!$A$76,"DAY","Tue")+GETPIVOTDATA("Sum of AM FIELD",'Pivot Table'!$A$88,"DAY","Tue")+GETPIVOTDATA("Sum of AM FIELD",'Pivot Table'!$A$100,"DAY","Tue")+GETPIVOTDATA("Sum of AM FIELD",'Pivot Table'!$A$112,"DAY","Tue")+GETPIVOTDATA("Sum of AM FIELD",'Pivot Table'!$A$124,"DAY","Tue")+GETPIVOTDATA("Sum of AM FIELD",'Pivot Table'!$A$136,"DAY","Tue") -> 4220 | H6: AM Field | I6: =GETPIVOTDATA("Sum of AM FIELD",'Pivot Table'!$A$4,"DAY","Wed")+GETPIVOTDATA("Sum of AM FIELD",'Pivot Table'!$A$16,"DAY","Wed")+GETPIVOTDATA("Sum of AM FIELD",'Pivot Table'!$A$28,"DAY","Wed")+GETPIVOTDATA("Sum of AM FIELD",'Pivot Table'!$A$40,"DAY","Wed")+GETPIVOTDATA("Sum of AM FIELD",'Pivot Table'!$A$52,"DAY","Wed")+GETPIVOTDATA("Sum of AM FIELD",'Pivot Table'!$A$64,"DAY","Wed")+GETPIVOTDATA("Sum of AM FIELD",'Pivot Table'!$A$76,"DAY","Wed")+GETPIVOTDATA("Sum of AM FIELD",'Pivot Table'!$A$88,"DAY","Wed")+GETPIVOTDATA("Sum of AM FIELD",'Pivot Table'!$A$100,"DAY","Wed")+GETPIVOTDATA("Sum of AM FIELD",'Pivot Table'!$A$112,"DAY","Wed")+GETPIVOTDATA("Sum of AM FIELD",'Pivot Table'!$A$124,"DAY","Wed")+GETPIVOTDATA("Sum of AM FIELD",'Pivot Table'!$A$136,"DAY","Wed") -> 3352 | K6: AM Field | L6: =GETPIVOTDATA("Sum of AM FIELD",'Pivot Table'!$A$4,"DAY","Thu")+GETPIVOTDATA("Sum of AM FIELD",'Pivot Table'!$A$16,"DAY","Thu")+GETPIVOTDATA("Sum of AM FIELD",'Pivot Table'!$A$28,"DAY","Thu")+GETPIVOTDATA("Sum of AM FIELD",'Pivot Table'!$A$40,"DAY","Thu")+GETPIVOTDATA("Sum of AM FIELD",'Pivot Table'!$A$52,"DAY","Thu")+GETPIVOTDATA("Sum of AM FIELD",'Pivot Table'!$A$64,"DAY","Thu")+GETPIVOTDATA("Sum of AM FIELD",'Pivot Table'!$A$76,"DAY","Thu")+GETPIVOTDATA("Sum of AM FIELD",'Pivot Table'!$A$88,"DAY","Thu")+GETPIVOTDATA("Sum of AM FIELD",'Pivot Table'!$A$100,"DAY","Thu")+GETPIVOTDATA("Sum of AM FIELD",'Pivot Table'!$A$112,"DAY","Thu")+GETPIVOTDATA("Sum of AM FIELD",'Pivot Table'!$A$124,"DAY","Thu")+GETPIVOTDATA("Sum of AM FIELD",'Pivot Table'!$A$136,"DAY","Thu") -> 3874 | N6: AM Field | O6: =GETPIVOTDATA("Sum of AM FIELD",'Pivot Table'!$A$4,"DAY","Fri")+GETPIVOTDATA("Sum of AM FIELD",'Pivot Table'!$A$16,"DAY","Fri")+GETPIVOTDATA("Sum of AM FIELD",'Pivot Table'!$A$28,"DAY","Fri")+GETPIVOTDATA("Sum of AM FIELD",'Pivot Table'!$A$40,"DAY","Fri")+GETPIVOTDATA("Sum of AM FIELD",'Pivot Table'!$A$52,"DAY","Fri")+GETPIVOTDATA("Sum of AM FIELD",'Pivot Table'!$A$64,"DAY","Fri")+GETPIVOTDATA("Sum of AM FIELD",'Pivot Table'!$A$76,"DAY","Fri")+GETPIVOTDATA("Sum of AM FIELD",'Pivot Table'!$A$88,"DAY","Fri")+GETPIVOTDATA("Sum of AM FIELD",'Pivot Table'!$A$100,"DAY","Fri")+GETPIVOTDATA("Sum of AM FIELD",'Pivot Table'!$A$112,"DAY","Fri")+GETPIVOTDATA("Sum of AM FIELD",'Pivot Table'!$A$124,"DAY","Fri")+GETPIVOTDATA("Sum of AM FIELD",'Pivot Table'!$A$136,"DAY","Fri") -> 4579 | Q6: AM Field | R6: =GETPIVOTDATA("Sum of AM FIELD",'Pivot Table'!$A$4,"DAY","Sat")+GETPIVOTDATA("Sum of AM FIELD",'Pivot Table'!$A$16,"DAY","Sat")+GETPIVOTDATA("Sum of AM FIELD",'Pivot Table'!$A$28,"DAY","Sat")+GETPIVOTDATA("Sum of AM FIELD",'Pivot Table'!$A$40,"DAY","Sat")+GETPIVOTDATA("Sum of AM FIELD",'Pivot Table'!$A$52,"DAY","Sat")+GETPIVOTDATA("Sum of AM FIELD",'Pivot Table'!$A$64,"DAY","Sat")+GETPIVOTDATA("Sum of AM FIELD",'Pivot Table'!$A$76,"DAY","Sat")+GETPIVOTDATA("Sum of AM FIELD",'Pivot Table'!$A$88,"DAY","Sat")+GETPIVOTDATA("Sum of AM FIELD",'Pivot Table'!$A$100,"DAY","Sat")+GETPIVOTDATA("Sum of AM FIELD",'Pivot Table'!$A$112,"DAY","Sat")+GETPIVOTDATA("Sum of AM FIELD",'Pivot Table'!$A$124,"DAY","Sat")+GETPIVOTDATA("Sum of AM FIELD",'Pivot Table'!$A$136,"DAY","Sat") -> 4305 | T6: AM Field | U6: =GETPIVOTDATA("Sum of AM FIELD",'Pivot Table'!$A$4,"DAY","Sun")+GETPIVOTDATA("Sum of AM FIELD",'Pivot Table'!$A$16,"DAY","Sun")+GETPIVOTDATA("Sum of AM FIELD",'Pivot Table'!$A$28,"DAY","Sun")+GETPIVOTDATA("Sum of AM FIELD",'Pivot Table'!$A$40,"DAY","Sun")+GETPIVOTDATA("Sum of AM FIELD",'Pivot Table'!$A$52,"DAY","Sun")+GETPIVOTDATA("Sum of AM FIELD",'Pivot Table'!$A$64,"DAY","Sun")+GETPIVOTDATA("Sum of AM FIELD",'Pivot Table'!$A$76,"DAY","Sun")+GETPIVOTDATA("Sum of AM FIELD",'Pivot Table'!$A$88,"DAY","Sun")+GETPIVOTDATA("Sum of AM FIELD",'Pivot Table'!$A$100,"DAY","Sun")+GETPIVOTDATA("Sum of AM FIELD",'Pivot Table'!$A$112,"DAY","Sun")+GETPIVOTDATA("Sum of AM FIELD",'Pivot Table'!$A$124,"DAY","Sun")+GETPIVOTDATA("Sum of AM FIELD",'Pivot Table'!$A$136,"DAY","Sun") -> 4326
B7: PM Field | C7: =GETPIVOTDATA("Sum of PM FIELD",'Pivot Table'!$A$4,"DAY","Mon")+GETPIVOTDATA("Sum of PM FIELD",'Pivot Table'!$A$16,"DAY","Mon")+GETPIVOTDATA("Sum of PM FIELD",'Pivot Table'!$A$28,"DAY","Mon")+GETPIVOTDATA("Sum of PM FIELD",'Pivot Table'!$A$40,"DAY","Mon")+GETPIVOTDATA("Sum of PM FIELD",'Pivot Table'!$A$52,"DAY","Mon")+GETPIVOTDATA("Sum of PM FIELD",'Pivot Table'!$A$64,"DAY","Mon")+GETPIVOTDATA("Sum of PM FIELD",'Pivot Table'!$A$76,"DAY","Mon")+GETPIVOTDATA("Sum of PM FIELD",'Pivot Table'!$A$88,"DAY","Mon")++GETPIVOTDATA("Sum of PM FIELD",'Pivot Table'!$A$112,"DAY","Mon")+GETPIVOTDATA("Sum of PM FIELD",'Pivot Table'!$A$100,"DAY","Mon")+GETPIVOTDATA("Sum of PM FIELD",'Pivot Table'!$A$124,"DAY","Mon")+GETPIVOTDATA("Sum of PM FIELD",'Pivot Table'!$A$136,"DAY","Mon") -> 3399 | E7: PM Field | F7: =GETPIVOTDATA("Sum of PM FIELD",'Pivot Table'!$A$4,"DAY","Tue")+GETPIVOTDATA("Sum of PM FIELD",'Pivot Table'!$A$16,"DAY","Tue")+GETPIVOTDATA("Sum of PM FIELD",'Pivot Table'!$A$28,"DAY","Tue")+GETPIVOTDATA("Sum of PM FIELD",'Pivot Table'!$A$40,"DAY","Tue")+GETPIVOTDATA("Sum of PM FIELD",'Pivot Table'!$A$52,"DAY","Tue")+GETPIVOTDATA("Sum of PM FIELD",'Pivot Table'!$A$64,"DAY","Tue")+GETPIVOTDATA("Sum of PM FIELD",'Pivot Table'!$A$76,"DAY","Tue")+GETPIVOTDATA("Sum of PM FIELD",'Pivot Table'!$A$88,"DAY","Tue")+GETPIVOTDATA("Sum of PM FIELD",'Pivot Table'!$A$100,"DAY","Tue")+GETPIVOTDATA("Sum of PM FIELD",'Pivot Table'!$A$112,"DAY","Tue")+GETPIVOTDATA("Sum of PM FIELD",'Pivot Table'!$A$124,"DAY","Tue")+GETPIVOTDATA("Sum of PM FIELD",'Pivot Table'!$A$136,"DAY","Tue") -> 1635 | H7: PM Field | I7: =GETPIVOTDATA("Sum of PM FIELD",'Pivot Table'!$A$4,"DAY","Wed")+GETPIVOTDATA("Sum of PM FIELD",'Pivot Table'!$A$16,"DAY","Wed")+GETPIVOTDATA("Sum of PM FIELD",'Pivot Table'!$A$28,"DAY","Wed")+GETPIVOTDATA("Sum of PM FIELD",'Pivot Table'!$A$40,"DAY","Wed")+GETPIVOTDATA("Sum of PM FIELD",'Pivot Table'!$A$52,"DAY","Wed")+GETPIVOTDATA("Sum of PM FIELD",'Pivot Table'!$A$64,"DAY","Wed")+GETPIVOTDATA("Sum of PM FIELD",'Pivot Table'!$A$76,"DAY","Wed")+GETPIVOTDATA("Sum of PM FIELD",'Pivot Table'!$A$88,"DAY","Wed")+GETPIVOTDATA("Sum of PM FIELD",'Pivot Table'!$A$100,"DAY","Wed")+GETPIVOTDATA("Sum of PM FIELD",'Pivot Table'!$A$112,"DAY","Wed")+GETPIVOTDATA("Sum of PM FIELD",'Pivot Table'!$A$124,"DAY","Wed")+GETPIVOTDATA("Sum of PM FIELD",'Pivot Table'!$A$136,"DAY","Wed") -> 3559 | K7: PM Field | L7: =GETPIVOTDATA("Sum of PM FIELD",'Pivot Table'!$A$4,"DAY","Thu")+GETPIVOTDATA("Sum of PM FIELD",'Pivot Table'!$A$16,"DAY","Thu")+GETPIVOTDATA("Sum of PM FIELD",'Pivot Table'!$A$28,"DAY","Thu")+GETPIVOTDATA("Sum of PM FIELD",'Pivot Table'!$A$40,"DAY","Thu")+GETPIVOTDATA("Sum of PM FIELD",'Pivot Table'!$A$52,"DAY","Thu")+GETPIVOTDATA("Sum of PM FIELD",'Pivot Table'!$A$64,"DAY","Thu")+GETPIVOTDATA("Sum of PM FIELD",'Pivot Table'!$A$76,"DAY","Thu")+GETPIVOTDATA("Sum of PM FIELD",'Pivot Table'!$A$88,"DAY","Thu")+GETPIVOTDATA("Sum of PM FIELD",'Pivot Table'!$A$100,"DAY","Thu")+GETPIVOTDATA("Sum of PM FIELD",'Pivot Table'!$A$112,"DAY","Thu")+GETPIVOTDATA("Sum of PM FIELD",'Pivot Table'!$A$124,"DAY","Thu")+GETPIVOTDATA("Sum of PM FIELD",'Pivot Table'!$A$136,"DAY","Thu") -> 3826 | N7: PM Field | O7: =GETPIVOTDATA("Sum of PM FIELD",'Pivot Table'!$A$4,"DAY","Fri")+GETPIVOTDATA("Sum of PM FIELD",'Pivot Table'!$A$16,"DAY","Fri")+GETPIVOTDATA("Sum of PM FIELD",'Pivot Table'!$A$28,"DAY","Fri")+GETPIVOTDATA("Sum of PM FIELD",'Pivot Table'!$A$40,"DAY","Fri")+GETPIVOTDATA("Sum of PM FIELD",'Pivot Table'!$A$52,"DAY","Fri")+GETPIVOTDATA("Sum of PM FIELD",'Pivot Table'!$A$64,"DAY","Fri")+GETPIVOTDATA("Sum of PM FIELD",'Pivot Table'!$A$76,"DAY","Fri")+GETPIVOTDATA("Sum of PM FIELD",'Pivot Table'!$A$88,"DAY","Fri")+GETPIVOTDATA("Sum of PM FIELD",'Pivot Table'!$A$100,"DAY","Fri")+GETPIVOTDATA("Sum of PM FIELD",'Pivot Table'!$A$112,"DAY","Fri")+GETPIVOTDATA("Sum of PM FIELD",'Pivot Table'!$A$124,"DAY","Fri")+GETPIVOTDATA("Sum of PM FIELD",'Pivot Table'!$A$136,"DAY","Fri") -> 3759 | Q7: PM Field | R7: =GETPIVOTDATA("Sum of PM FIELD",'Pivot Table'!$A$4,"DAY","Sat")+GETPIVOTDATA("Sum of PM FIELD",'Pivot Table'!$A$16,"DAY","Sat")+GETPIVOTDATA("Sum of PM FIELD",'Pivot Table'!$A$28,"DAY","Sat")+GETPIVOTDATA("Sum of PM FIELD",'Pivot Table'!$A$40,"DAY","Sat")+GETPIVOTDATA("Sum of PM FIELD",'Pivot Table'!$A$52,"DAY","Sat")+GETPIVOTDATA("Sum of PM FIELD",'Pivot Table'!$A$64,"DAY","Sat")+GETPIVOTDATA("Sum of PM FIELD",'Pivot Table'!$A$76,"DAY","Sat")+GETPIVOTDATA("Sum of PM FIELD",'Pivot Table'!$A$88,"DAY","Sat")+GETPIVOTDATA("Sum of PM FIELD",'Pivot Table'!$A$100,"DAY","Sat")+GETPIVOTDATA("Sum of PM FIELD",'Pivot Table'!$A$112,"DAY","Sat")+GETPIVOTDATA("Sum of PM FIELD",'Pivot Table'!$A$124,"DAY","Sat")+GETPIVOTDATA("Sum of PM FIELD",'Pivot Table'!$A$136,"DAY","Sat") -> 3315 | T7: PM Field | U7: =GETPIVOTDATA("Sum of PM FIELD",'Pivot Table'!$A$4,"DAY","Sun")+GETPIVOTDATA("Sum of PM FIELD",'Pivot Table'!$A$16,"DAY","Sun")+GETPIVOTDATA("Sum of PM FIELD",'Pivot Table'!$A$28,"DAY","Sun")+GETPIVOTDATA("Sum of PM FIELD",'Pivot Table'!$A$40,"DAY","Sun")+GETPIVOTDATA("Sum of PM FIELD",'Pivot Table'!$A$52,"DAY","Sun")+GETPIVOTDATA("Sum of PM FIELD",'Pivot Table'!$A$64,"DAY","Sun")+GETPIVOTDATA("Sum of PM FIELD",'Pivot Table'!$A$76,"DAY","Sun")+GETPIVOTDATA("Sum of PM FIELD",'Pivot Table'!$A$88,"DAY","Sun")+GETPIVOTDATA("Sum of PM FIELD",'Pivot Table'!$A$100,"DAY","Sun")+GETPIVOTDATA("Sum of PM FIELD",'Pivot Table'!$A$112,"DAY","Sun")+GETPIVOTDATA("Sum of PM FIELD",'Pivot Table'!$A$124,"DAY","Sun")+GETPIVOTDATA("Sum of PM FIELD",'Pivot Table'!$A$136,"DAY","Sun") -> 3792
