Workbook

Sheet Yearly Total To Date
B4: Yearly Total | F4: Total Average (Month) | J4: Total Average (Week) | N4: Total Average (Day) | R4: 2025 Occupancy Totals
B6: AM Field | C6: ='Monthly Totals'!C5+'Monthly Totals'!F5+'Monthly Totals'!I5+'Monthly Totals'!L5+'Monthly Totals'!O5+'Monthly Totals'!R5+'Monthly Totals'!C28+'Monthly Totals'!F28+'Monthly Totals'!I28+'Monthly Totals'!L28+'Monthly Totals'!O28+'Monthly Totals'!R28 -> 4850 | F6: AM Field | G6: =C6 / 12 -> 404.16667 | J6: AM Field | K6: =C6 / 52 -> 93.269231 | N6: AM Field | O6: =C6 / 365 -> 13.287671 | R6: Time | S6: Bookings | T6: Spots Available | U6: Occupancy
B7: PM Field | C7: ='Monthly Totals'!C6+'Monthly Totals'!F6+'Monthly Totals'!I6+'Monthly Totals'!L6+'Monthly Totals'!O6+'Monthly Totals'!R6+'Monthly Totals'!C29+'Monthly Totals'!F29+'Monthly Totals'!I29+'Monthly Totals'!L29+'Monthly Totals'!O29+'Monthly Totals'!R29 -> 3580 | F7: PM Field | G7: =C7 / 12 -> 298.33333 | J7: PM Field | K7: =C7 / 52 -> 68.846154 | N7: PM Field | O7: =C7 / 365 -> 9.8082192 | R7: AM | S7: ='Occupancy Report Summarised'!L4+'Occupancy Report Summarised'!L8+'Occupancy Report Summarised'!L12+'Occupancy Report Summarised'!L16+'Occupancy Report Summarised'!L20+'Occupancy Report Summarised'!L24+'Occupancy Report Summarised'!L28+'Occupancy Report Summarised'!L32+'Occupancy Report Summarised'!L36+'Occupancy Report Summarised'!L40+'Occupancy Report Summarised'!L44+'Occupancy Report Summarised'!L48 -> 4850 | T7: ='Occupancy Report Summarised'!M4+'Occupancy Report Summarised'!M8+'Occupancy Report Summarised'!M12+'Occupancy Report Summarised'!M16+'Occupancy Report Summarised'!M20+'Occupancy Report Summarised'!M24+'Occupancy Report Summarised'!M28+'Occupancy Report Summarised'!M32+'Occupancy Report Summarised'!M36+'Occupancy Report Summarised'!M40+'Occupancy Report Summarised'!M44+'Occupancy Report Summarised'!M48 -> 5556 | U7: =SUM(S7/T7) -> 0.87293017
B8: After 3PM | C8: ='Monthly Totals'!C7+'Monthly Totals'!F7+'Monthly Totals'!I7+'Monthly Totals'!L7+'Monthly Totals'!O7+'Monthly Totals'!R7+'Monthly Totals'!C30+'Monthly Totals'!F30+'Monthly Totals'!I30+'Monthly Totals'!L30+'Monthly Totals'!O30+'Monthly Totals'!R30 -> 757 | F8: After 3PM | G8: =C8 / 12 -> 63.083333 | J8: After 3PM | K8: =C8 / 52 -> 14.557692 | N8: After 3PM | O8: =C8 / 365 -> 2.0739726 | R8: PM | S8: ='Occupancy Report Summarised'!L5+'Occupancy Report Summarised'!L9+'Occupancy Report Summarised'!L13+'Occupancy Report Summarised'!L17+'Occupancy Report Summarised'!L21+'Occupancy Report Summarised'!L25+'Occupancy Report Summarised'!L29+'Occupancy Report Summarised'!L33+'Occupancy Report Summarised'!L37+'Occupancy Report Summarised'!L41+'Occupancy Report Summarised'!L45+'Occupancy Report Summarised'!L49 -> 3580 | T8: ='Occupancy Report Summarised'!M5+'Occupancy Report Summarised'!M9+'Occupancy Report Summarised'!M13+'Occupancy Report Summarised'!M17+'Occupancy Report Summarised'!M21+'Occupancy Report Summarised'!M25+'Occupancy Report Summarised'!M29+'Occupancy Report Summarised'!M33+'Occupancy Report Summarised'!M37+'Occupancy Report Summarised'!M41+'Occupancy Report Summarised'!M45+'Occupancy Report Summarised'!M49 -> 4936 | U8: =SUM(S8/T8) -> 0.72528363
B9: Total Field | C9: ='Monthly Totals'!C8+'Monthly Totals'!F8+'Monthly Totals'!I8+'Monthly Totals'!L8+'Monthly Totals'!O8+'Monthly Totals'!R8+'Monthly Totals'!C31+'Monthly Totals'!F31+'Monthly Totals'!I31+'Monthly Totals'!L31+'Monthly Totals'!O31+'Monthly Totals'!R31 -> 9922 | F9: Total Field | G9: =C9 / 12 -> 826.83333 | J9: Total Field | K9: =C9 / 52 -> 190.80769 | N9: Total Field | O9: =C9 / 365 -> 27.183562 | R9: After 3PM | S9: ='After 3pm Data'!Z4+'After 3pm Data'!Z6+'After 3pm Data'!Z8 -> 1492 | T9: ='After 3pm Data'!AA4+'After 3pm Data'!AA6+'After 3pm Data'!AA8 -> 4692 | U9: =SUM(S9/T9) -> 0.31798806
B10: Guests | C10: ='Monthly Totals'!C9+'Monthly Totals'!F9+'Monthly Totals'!I9+'Monthly Totals'!L9+'Monthly Totals'!O9+'Monthly Totals'!R9+'Monthly Totals'!C32+'Monthly Totals'!F32+'Monthly Totals'!I32+'Monthly Totals'!L32+'Monthly Totals'!O32+'Monthly Totals'!R32 -> 2063 | F10: Guests | G10: =C10 / 12 -> 171.91667 | J10: Guests | K10: =C10 / 52 -> 39.673077 | N10: Guests | O10: =C10 / 365 -> 5.6520548 | R10: Total | S10: =SUM(S7:S9) -> 9922 | T10: =SUM(T7:T9) -> 15184 | U10: =SUM(S10/T10) -> 0.653451
B11: Member / Guest Ratio | C11: =SUM(C10/C9) -> 0.20792179 | F11: Member / Guest Ratio | G11: - | J11: Member / Guest Ratio | K11: - | N11: Member / Guest Ratio | O11: -
B12: Member Play | C12: ='Monthly Totals'!C11+'Monthly Totals'!F11+'Monthly Totals'!I11+'Monthly Totals'!L11+'Monthly Totals'!O11+'Monthly Totals'!R11+'Monthly Totals'!C34+'Monthly Totals'!F34+'Monthly Totals'!I34+'Monthly Totals'!L34+'Monthly Totals'!O34+'Monthly Totals'!R34 -> 7824 | F12: Member Play | G12: =C12 / 12 -> 652 | J12: Member Play | K12: =C12 / 52 -> 150.46154 | N12: Member Play | O12: =C12 / 365 -> 21.435616 | R12: Occupancy (Excluding 3pm)
B13: Manger Intro | C13: ='Monthly Totals'!C12+'Monthly Totals'!F12+'Monthly Totals'!I12+'Monthly Totals'!L12+'Monthly Totals'!O12+'Monthly Totals'!R12+'Monthly Totals'!C35+'Monthly Totals'!F35+'Monthly Totals'!I35+'Monthly Totals'!L35+'Monthly Totals'!O35+'Monthly Totals'!R35 -> 78 | F13: Manger Intro | G13: =C13 / 12 -> 6.5 | J13: Manger Intro | K13: =C13 / 52 -> 1.5 | N13: Manger Intro | O13: =C13 / 365 -> 0.21369863
B14: Interstate | C14: ='Monthly Totals'!C13+'Monthly Totals'!F13+'Monthly Totals'!I13+'Monthly Totals'!L13+'Monthly Totals'!O13+'Monthly Totals'!R13+'Monthly Totals'!C36+'Monthly Totals'!F36+'Monthly Totals'!I36+'Monthly Totals'!L36+'Monthly Totals'!O36+'Monthly Totals'!R36 -> 34 | F14: Interstate | G14: =C14 / 12 -> 2.8333333 | J14: Interstate | K14: =C14 / 52 -> 0.65384615 | N14: Interstate | O14: =C14 / 365 -> 0.093150685 | R14: Time | S14: Bookings | T14: Spots Available | U14: Occupancy
B15: International | C15: ='Monthly Totals'!C14+'Monthly Totals'!F14+'Monthly Totals'!I14+'Monthly Totals'!L14+'Monthly Totals'!O14+'Monthly Totals'!R14+'Monthly Totals'!C37+'Monthly Totals'!F37+'Monthly Totals'!I37+'Monthly Totals'!L37+'Monthly Totals'!O37+'Monthly Totals'!R37 -> 168 | F15: International | G15: =C15 / 12 -> 14 | J15: International | K15: =C15 / 52 -> 3.2307692 | N15: International | O15: =C15 / 365 -> 0.46027397 | R15: AM | S15: ='Occupancy Report Summarised'!L4+'Occupancy Report Summarised'!L8+'Occupancy Report Summarised'!L12+'Occupancy Report Summarised'!L16+'Occupancy Report Summarised'!L20+'Occupancy Report Summarised'!L24+'Occupancy Report Summarised'!L28+'Occupancy Report Summarised'!L32+'Occupancy Report Summarised'!L36+'Occupancy Report Summarised'!L40+'Occupancy Report Summarised'!L44+'Occupancy Report Summarised'!L48 -> 4850 | T15: ='Occupancy Report Summarised'!M4+'Occupancy Report Summarised'!M8+'Occupancy Report Summarised'!M12+'Occupancy Report Summarised'!M16+'Occupancy Report Summarised'!M20+'Occupancy Report Summarised'!M24+'Occupancy Report Summarised'!M28+'Occupancy Report Summarised'!M32+'Occupancy Report Summarised'!M36+'Occupancy Report Summarised'!M40+'Occupancy Report Summarised'!M44+'Occupancy Report Summarised'!M48 -> 5556 | U15: =SUM(S15/T15) -> 0.87293017
B16: Industry Guest | C16: ='Monthly Totals'!C15+'Monthly Totals'!F15+'Monthly Totals'!I15+'Monthly Totals'!L15+'Monthly Totals'!O15+'Monthly Totals'!R15+'Monthly Totals'!C38+'Monthly Totals'!F38+'Monthly Totals'!I38+'Monthly Totals'!L38+'Monthly Totals'!O38+'Monthly Totals'!R38 -> 19 | F16: Industry Guest | G16: =C16 / 12 -> 1.5833333 | J16: Industry Guest | K16: =C16 / 52 -> 0.36538462 | N16: Industry Guest | O16: =C16 / 365 -> 0.052054795 | R16: PM | S16: ='Occupancy Report Summarised'!L5+'Occupancy Report Summarised'!L9+'Occupancy Report Summarised'!L13+'Occupancy Report Summarised'!L17+'Occupancy Report Summarised'!L21+'Occupancy Report Summarised'!L25+'Occupancy Report Summarised'!L29+'Occupancy Report Summarised'!L33+'Occupancy Report Summarised'!L37+'Occupancy Report Summarised'!L41+'Occupancy Report Summarised'!L45+'Occupancy Report Summarised'!L49 -> 3580 | T16: ='Occupancy Report Summarised'!M5+'Occupancy Report Summarised'!M9+'Occupancy Report Summarised'!M13+'Occupancy Report Summarised'!M17+'Occupancy Report Summarised'!M21+'Occupancy Report Summarised'!M25+'Occupancy Report Summarised'!M29+'Occupancy Report Summarised'!M33+'Occupancy Report Summarised'!M37+'Occupancy Report Summarised'!M41+'Occupancy Report Summarised'!M45+'Occupancy Report Summarised'!M49 -> 4936 | U16: =SUM(S16/T16) -> 0.72528363
B17: Member Intro | C17: ='Monthly Totals'!C16+'Monthly Totals'!F16+'Monthly Totals'!I16+'Monthly Totals'!L16+'Monthly Totals'!O16+'Monthly Totals'!R16+'Monthly Totals'!C39+'Monthly Totals'!F39+'Monthly Totals'!I39+'Monthly Totals'!L39+'Monthly Totals'!O39+'Monthly Totals'!R39 -> 1011 | F17: Member Intro | G17: =C17 / 12 -> 84.25 | J17: Member Intro | K17: =C17 / 52 -> 19.442308 | N17: Member Intro | O17: =C17 / 365 -> 2.769863 | R17: Total | S17: =SUM(S15+S16) -> 8430 | T17: =SUM(T15+T16) -> 10492 | U17: =SUM(S17/T17) -> 0.80346931
B18: Member Guest Unaccompanied | C18: ='Monthly Totals'!C17+'Monthly Totals'!F17+'Monthly Totals'!I17+'Monthly Totals'!L17+'Monthly Totals'!O17+'Monthly Totals'!R17+'Monthly Totals'!C40+'Monthly Totals'!F40+'Monthly Totals'!I40+'Monthly Totals'!L40+'Monthly Totals'!O40+'Monthly Totals'!R40 -> 17 | F18: Member Guest Unaccompanied | G18: =C18 / 12 -> 1.4166667 | J18: Member Guest Unaccompanied | K18: =C18 / 52 -> 0.32692308 | N18: Member Guest Unaccompanied | O18: =C18 / 365 -> 0.046575342
B19: Corporate | C19: ='Monthly Totals'!C18+'Monthly Totals'!F18+'Monthly Totals'!I18+'Monthly Totals'!L18+'Monthly Totals'!O18+'Monthly Totals'!R18+'Monthly Totals'!C41+'Monthly Totals'!F41+'Monthly Totals'!I41+'Monthly Totals'!L41+'Monthly Totals'!O41+'Monthly Totals'!R41 -> 318 | F19: Corporate | G19: =C19 / 12 -> 26.5 | J19: Corporate | K19: =C19 / 52 -> 6.1153846 | N19: Corporate | O19: =C19 / 365 -> 0.87123288
B20: Event | C20: ='Monthly Totals'!C19+'Monthly Totals'!F19+'Monthly Totals'!I19+'Monthly Totals'!L19+'Monthly Totals'!O19+'Monthly Totals'!R19+'Monthly Totals'!C42+'Monthly Totals'!F42+'Monthly Totals'!I42+'Monthly Totals'!L42+'Monthly Totals'!O42+'Monthly Totals'!R42 -> 0 | F20: Event | G20: =C20 / 12 -> 0 | J20: Event | K20: =C20 / 52 -> 0 | N20: Event | O20: =C20 / 365 -> 0
B21: Non Playing | C21: ='Monthly Totals'!C20+'Monthly Totals'!F20+'Monthly Totals'!I20+'Monthly Totals'!L20+'Monthly Totals'!O20+'Monthly Totals'!R20+'Monthly Totals'!C43+'Monthly Totals'!F43+'Monthly Totals'!I43+'Monthly Totals'!L43+'Monthly Totals'!O43+'Monthly Totals'!R43 -> 35 | F21: Non Playing | G21: =C21 / 12 -> 2.9166667 | J21: Non Playing | K21: =C21 / 52 -> 0.67307692 | N21: Non Playing | O21: =C21 / 365 -> 0.095890411
B22: Voucher | C22: ='Monthly Totals'!C21+'Monthly Totals'!F21+'Monthly Totals'!I21+'Monthly Totals'!L21+'Monthly Totals'!O21+'Monthly Totals'!R21+'Monthly Totals'!C44+'Monthly Totals'!F44+'Monthly Totals'!I44+'Monthly Totals'!L44+'Monthly Totals'!O44+'Monthly Totals'!R44 -> 218 | F22: Voucher | G22: =C22 / 12 -> 18.166667 | J22: Voucher | K22: =C22 / 52 -> 4.1923077 | N22: Voucher | O22: =C22 / 365 -> 0.59726027
B23: Reciprocal | C23: ='Monthly Totals'!C22+'Monthly Totals'!F22+'Monthly Totals'!I22+'Monthly Totals'!L22+'Monthly Totals'!O22+'Monthly Totals'!R22+'Monthly Totals'!C45+'Monthly Totals'!F45+'Monthly Totals'!I45+'Monthly Totals'!L45+'Monthly Totals'!O45+'Monthly Totals'!R45 -> 178 | F23: Reciprocal | G23: =C23 / 12 -> 14.833333 | J23: Reciprocal | K23: =C23 / 52 -> 3.4230769 | N23: Reciprocal | O23: =C23 / 365 -> 0.48767123
B24: Competition | C24: ='Monthly Totals'!C23+'Monthly Totals'!F23+'Monthly Totals'!I23+'Monthly Totals'!L23+'Monthly Totals'!O23+'Monthly Totals'!R23+'Monthly Totals'!C46+'Monthly Totals'!F46+'Monthly Totals'!I46+'Monthly Totals'!L46+'Monthly Totals'!O46+'Monthly Totals'!R46 -> 5583 | F24: Competition | G24: =C24 / 12 -> 465.25 | J24: Competition | K24: =C24 / 52 -> 107.36538 | N24: Competition | O24: =C24 / 365 -> 15.29589

Sheet Occupancy Report
B2: January | D2: Bookings | E2: Spots Available | F2: Occupancy | G2: Notes | I2: Feburary | K2: Bookings | L2: Spots Available | M2: Occupancy | N2: Notes | P2: March | R2: Bookings | S2: Spots Available | T2: Occupancy | U2: Notes
B4: Monday | C4: AM | D4: =GETPIVOTDATA("Sum of AM FIELD",'Pivot Table'!$A$4,"DAY","Mon") -> 292 | E4: =108+108+0+96 -> 312 | F4: =SUM(D4/E4) -> 0.93589744 | I4: Monday | J4: AM | K4: =GETPIVOTDATA("Sum of AM FIELD",'Pivot Table'!$A$16,"DAY","Mon") -> 153 | L4: =88+88+0+68 -> 244 | M4: =SUM(K4/L4) -> 0.62704918 | P4: Monday | Q4: AM | R4: =GETPIVOTDATA("Sum of AM FIELD",'Pivot Table'!$A$28,"DAY","Mon") -> 0 | T4: =SUM(R4/S4) -> #DIV/0!
C5: PM | D5: =GETPIVOTDATA("Sum of PM FIELD",'Pivot Table'!$A$4,"DAY","Mon") -> 278 | E5: =76+76+80+96 -> 328 | F5: =SUM(D5/E5) -> 0.84756098 | J5: PM | K5: =GETPIVOTDATA("Sum of PM FIELD",'Pivot Table'!$A$16,"DAY","Mon") -> 324 | L5: =88+84+80+104 -> 356 | M5: =SUM(K5/L5) -> 0.91011236 | Q5: PM | R5: =GETPIVOTDATA("Sum of PM FIELD",'Pivot Table'!$A$28,"DAY","Mon") -> 0 | T5: =SUM(R5/S5) -> #DIV/0!
B6: Total Occupancy | D6: =SUM(D3:D5) -> 570 | E6: =SUM(E3:E5) -> 640 | F6: =SUM(D6/E6) -> 0.890625 | I6: Total Occupancy | K6: =SUM(K3:K5) -> 477 | L6: =SUM(L3:L5) -> 600 | M6: =SUM(K6/L6) -> 0.795 | P6: Total Occupancy | R6: =SUM(R3:R5) -> 0 | S6: =SUM(S4:S5) -> 0 | T6: =SUM(R6/S6) -> #DIV/0!
B8: Tuesday | C8: AM | D8: =GETPIVOTDATA("Sum of AM FIELD",'Pivot Table'!$A$4,"DAY","Tue") -> 326 | E8: =112+112+112+112 -> 448 | F8: =SUM(D8/E8) -> 0.72767857 | I8: Tuesday | J8: AM | K8: =GETPIVOTDATA("Sum of AM FIELD",'Pivot Table'!$A$16,"DAY","Tue") -> 397 | L8: =100+112+100+112 -> 424 | M8: =SUM(K8/L8) -> 0.93632075 | P8: Tuesday | Q8: AM | R8: =GETPIVOTDATA("Sum of AM FIELD",'Pivot Table'!$A$28,"DAY","Tue") -> 0 | T8: =SUM(R8/S8) -> #DIV/0!
C9: PM | D9: =GETPIVOTDATA("Sum of PM FIELD",'Pivot Table'!$A$4,"DAY","Tue") -> 45 | E9: =80+80+80+80 -> 320 | F9: =SUM(D9/E9) -> 0.140625 | J9: PM | K9: =GETPIVOTDATA("Sum of PM FIELD",'Pivot Table'!$A$16,"DAY","Tue") -> 68 | L9: =72+60+84+80 -> 296 | M9: =SUM(K9/L9) -> 0.22972973 | Q9: PM | R9: =GETPIVOTDATA("Sum of PM FIELD",'Pivot Table'!$A$28,"DAY","Tue") -> 0 | T9: =SUM(R9/S9) -> #DIV/0!
B10: Total Occupancy | D10: =SUM(D7:D9) -> 371 | E10: =SUM(E7:E9) -> 768 | F10: =SUM(D10/E10) -> 0.48307292 | I10: Total Occupancy | K10: =SUM(K7:K9) -> 465 | L10: =SUM(L7:L9) -> 720 | M10: =SUM(K10/L10) -> 0.64583333 | P10: Total Occupancy | R10: =SUM(R7:R9) -> 0 | S10: =SUM(S7:S9) -> 0 | T10: =SUM(R10/S10) -> #DIV/0!
B12: Wednesday | C12: AM | D12: =GETPIVOTDATA("Sum of AM FIELD",'Pivot Table'!$A$4,"DAY","Wed") -> 288 | E12: =108+108+108+108 -> 432 | F12: =SUM(D12/E12) -> 0.66666667 | I12: Wednesday | J12: AM | K12: =GETPIVOTDATA("Sum of AM FIELD",'Pivot Table'!$A$16,"DAY","Wed") -> 398 | L12: =100+128+112+92 -> 432 | M12: =SUM(K12/L12) -> 0.9212963 | P12: Wednesday | Q12: AM | R12: =GETPIVOTDATA("Sum of AM FIELD",'Pivot Table'!$A$28,"DAY","Wed") -> 0 | T12: =SUM(R12/S12) -> #DIV/0!
C13: PM | D13: =GETPIVOTDATA("Sum of PM FIELD",'Pivot Table'!$A$4,"DAY","Wed") -> 169 | E13: =76+76+76+76 -> 304 | F13: =SUM(D13/E13) -> 0.55592105 | J13: PM | K13: =GETPIVOTDATA("Sum of PM FIELD",'Pivot Table'!$A$16,"DAY","Wed") -> 253 | L13: =88+84+72+84 -> 328 | M13: =SUM(K13/L13) -> 0.77134146 | Q13: PM | R13: =GETPIVOTDATA("Sum of PM FIELD",'Pivot Table'!$A$28,"DAY","Wed") -> 0 | T13: =SUM(R13/S13) -> #DIV/0!
B14: Total Occupancy | D14: =SUM(D11:D13) -> 457 | E14: =SUM(E11:E13) -> 736 | F14: =SUM(D14/E14) -> 0.62092391 | I14: Total Occupancy | K14: =SUM(K11:K13) -> 651 | L14: =SUM(L11:L13) -> 760 | M14: =SUM(K14/L14) -> 0.85657895 | P14: Total Occupancy | R14: =SUM(R11:R13) -> 0 | S14: =SUM(S11:S13) -> 0 | T14: =SUM(R14/S14) -> #DIV/0!
B16: Thursday | C16: AM | D16: =GETPIVOTDATA("Sum of AM FIELD",'Pivot Table'!$A$4,"DAY","Thu") -> 404 | E16: =96+88+88+88+88 -> 448 | F16: =SUM(D16/E16) -> 0.90178571 | I16: Thursday | J16: AM | K16: =GETPIVOTDATA("Sum of AM FIELD",'Pivot Table'!$A$16,"DAY","Thu") -> 330 | L16: =88+88+88+88 -> 352 | M16: =SUM(K16/L16) -> 0.9375 | P16: Thursday | Q16: AM | R16: =GETPIVOTDATA("Sum of AM FIELD",'Pivot Table'!$A$28,"DAY","Thu") -> 0 | T16: =SUM(R16/S16) -> #DIV/0!
C17: PM | D17: =GETPIVOTDATA("Sum of PM FIELD",'Pivot Table'!$A$4,"DAY","Thu") -> 356 | E17: =88+88+88+88+88 -> 440 | F17: =SUM(D17/E17) -> 0.80909091 | J17: PM | K17: =GETPIVOTDATA("Sum of PM FIELD",'Pivot Table'!$A$16,"DAY","Thu") -> 309 | L17: =88+88+88+88 -> 352 | M17: =SUM(K17/L17) -> 0.87784091 | Q17: PM | R17: =GETPIVOTDATA("Sum of PM FIELD",'Pivot Table'!$A$28,"DAY","Thu") -> 0 | T17: =SUM(R17/S17) -> #DIV/0!
B18: Total Occupancy | D18: =SUM(D15:D17) -> 760 | E18: =SUM(E15:E17) -> 888 | F18: =SUM(D18/E18) -> 0.85585586 | I18: Total Occupancy | K18: =SUM(K15:K17) -> 639 | L18: =SUM(L15:L17) -> 704 | M18: =SUM(K18/L18) -> 0.90767045 | P18: Total Occupancy | R18: =SUM(R15:R17) -> 0 | S18: =SUM(S15:S17) -> 0 | T18: =SUM(R18/S18) -> #DIV/0!
B20: Friday | C20: AM | D20: =GETPIVOTDATA("Sum of AM FIELD",'Pivot Table'!$A$4,"DAY","Fri") -> 446 | E20: =108+108+80+108+108 -> 512 | F20: =SUM(D20/E20) -> 0.87109375 | I20: Friday | J20: AM | K20: =GETPIVOTDATA("Sum of AM FIELD",'Pivot Table'!$A$16,"DAY","Fri") -> 305 | L20: =80+80+108+80 -> 348 | M20: =SUM(K20/L20) -> 0.87643678 | P20: Friday | Q20: AM | R20: =GETPIVOTDATA("Sum of AM FIELD",'Pivot Table'!$A$28,"DAY","Fri") -> 0 | T20: =SUM(R20/S20) -> #DIV/0!
C21: PM | D21: =GETPIVOTDATA("Sum of PM FIELD",'Pivot Table'!$A$4,"DAY","Fri") -> 269 | E21: =76+76+80+76+76 -> 384 | F21: =SUM(D21/E21) -> 0.70052083 | J21: PM | K21: =GETPIVOTDATA("Sum of PM FIELD",'Pivot Table'!$A$16,"DAY","Fri") -> 290 | L21: =80+84+72+88 -> 324 | M21: =SUM(K21/L21) -> 0.89506173 | Q21: PM | R21: =GETPIVOTDATA("Sum of PM FIELD",'Pivot Table'!$A$28,"DAY","Fri") -> 0 | T21: =SUM(R21/S21) -> #DIV/0!
B22: Total Occupancy | D22: =SUM(D19:D21) -> 715 | E22: =SUM(E19:E21) -> 896 | F22: =SUM(D22/E22) -> 0.79799107 | I22: Total Occupancy | K22: =SUM(K19:K21) -> 595 | L22: =SUM(L19:L21) -> 672 | M22: =SUM(K22/L22) -> 0.88541667 | P22: Total Occupancy | R22: =SUM(R19:R21) -> 0 | S22: =SUM(S19:S21) -> 0 | T22: =SUM(R22/S22) -> #DIV/0!
B24: Saturday | C24: AM | D24: =GETPIVOTDATA("Sum of AM FIELD",'Pivot Table'!$A$4,"DAY","Sat") -> 439 | E24: =96+88+96+96+96 -> 472 | F24: =SUM(D24/E24) -> 0.93008475 | I24: Saturday | J24: AM | K24: =GETPIVOTDATA("Sum of AM FIELD",'Pivot Table'!$A$16,"DAY","Sat") -> 348 | L24: =96+80+92+96 -> 364 | M24: =SUM(K24/L24) -> 0.95604396 | P24: Saturday | Q24: AM | R24: =GETPIVOTDATA("Sum of AM FIELD",'Pivot Table'!$A$28,"DAY","Sat") -> 0 | T24: =SUM(R24/S24) -> #DIV/0!
C25: PM | D25: =GETPIVOTDATA("Sum of PM FIELD",'Pivot Table'!$A$4,"DAY","Sat") -> 265 | E25: =88+88+92+88+88 -> 444 | F25: =SUM(D25/E25) -> 0.59684685 | J25: PM | K25: =GETPIVOTDATA("Sum of PM FIELD",'Pivot Table'!$A$16,"DAY","Sat") -> 319 | L25: =92+84+88+92 -> 356 | M25: =SUM(K25/L25) -> 0.89606742 | Q25: PM | R25: =GETPIVOTDATA("Sum of PM FIELD",'Pivot Table'!$A$28,"DAY","Sat") -> 0 | T25: =SUM(R25/S25) -> #DIV/0!
B26: Total Occupancy | D26: =SUM(D23:D25) -> 704 | E26: =SUM(E23:E25) -> 916 | F26: =SUM(D26/E26) -> 0.76855895 | I26: Total Occupancy | K26: =SUM(K23:K25) -> 667 | L26: =SUM(L23:L25) -> 720 | M26: =SUM(K26/L26) -> 0.92638889 | P26: Total Occupancy | R26: =SUM(R23:R25) -> 0 | S26: =SUM(S23:S25) -> 0 | T26: =SUM(R26/S26) -> #DIV/0!
B28: Sunday | C28: AM | D28: =GETPIVOTDATA("Sum of AM FIELD",'Pivot Table'!$A$4,"DAY","Sun") -> 362 | E28: =96+96+96+96 -> 384 | F28: =SUM(D28/E28) -> 0.94270833 | I28: Sunday | J28: AM | K28: =GETPIVOTDATA("Sum of AM FIELD",'Pivot Table'!$A$16,"DAY","Sun") -> 362 | L28: =96+96+96+96 -> 384 | M28: =SUM(K28/L28) -> 0.94270833 | P28: Sunday | Q28: AM | R28: =GETPIVOTDATA("Sum of AM FIELD",'Pivot Table'!$A$28,"DAY","Sun") -> 0 | T28: =SUM(R28/S28) -> #DIV/0!
C29: PM | D29: =GETPIVOTDATA("Sum of PM FIELD",'Pivot Table'!$A$4,"DAY","Sun") -> 346 | E29: =88+88+88+88 -> 352 | F29: =SUM(D29/E29) -> 0.98295455 | J29: PM | K29: =GETPIVOTDATA("Sum of PM FIELD",'Pivot Table'!$A$16,"DAY","Sun") -> 289 | L29: =88+88+88+88 -> 352 | M29: =SUM(K29/L29) -> 0.82102273 | Q29: PM | R29: =GETPIVOTDATA("Sum of PM FIELD",'Pivot Table'!$A$28,"DAY","Sun") -> 0 | T29: =SUM(R29/S29) -> #DIV/0!
B30: Total Occupancy | D30: =SUM(D27:D29) -> 708 | E30: =SUM(E27:E29) -> 736 | F30: =SUM(D30/E30) -> 0.96195652 | I30: Total Occupancy | K30: =SUM(K27:K29) -> 651 | L30: =SUM(L27:L29) -> 736 | M30: =SUM(K30/L30) -> 0.88451087 | P30: Total Occupancy | R30: =SUM(R27:R29) -> 0 | S30: =SUM(S27:S29) -> 0 | T30: =SUM(R30/S30) -> #DIV/0!
B33: April | D33: Bookings | E33: Spots Available | F33: Occupancy | G33: Notes | I33: May | K33: Bookings | L33: Spots Available | M33: Occupancy | N33: Notes | P33: June | R33: Bookings | S33: Spots Available | T33: Occupancy | U33: Notes
B35: Monday | C35: AM | D35: =GETPIVOTDATA("Sum of AM FIELD",'Pivot Table'!$A$40,"DAY","Mon") -> 0 | F35: =SUM(D35/E35) -> #DIV/0! | I35: Monday | J35: AM | K35: =GETPIVOTDATA("Sum of AM FIELD",'Pivot Table'!$A$52,"DAY","Mon") -> 0 | M35: =SUM(K35/L35) -> #DIV/0! | P35: Monday | Q35: AM | R35: =GETPIVOTDATA("Sum of AM FIELD",'Pivot Table'!$A$64,"DAY","Mon") -> 0 | T35: =SUM(R35/S35) -> #DIV/0!
C36: PM | D36: =GETPIVOTDATA("Sum of PM FIELD",'Pivot Table'!$A$40,"DAY","Mon") -> 0 | F36: =SUM(D36/E36) -> #DIV/0! | J36: PM | K36: =GETPIVOTDATA("Sum of PM FIELD",'Pivot Table'!$A$52,"DAY","Mon") -> 0 | M36: =SUM(K36/L36) -> #DIV/0! | Q36: PM | R36: =GETPIVOTDATA("Sum of PM FIELD",'Pivot Table'!$A$64,"DAY","Mon") -> 0 | T36: =SUM(R36/S36) -> #DIV/0!
B37: Total Occupancy | D37: =SUM(D34:D36) -> 0 | E37: =SUM(E34:E36) -> 0 | F37: =SUM(D37/E37) -> #DIV/0! | I37: Total Occupancy | K37: =SUM(K34:K36) -> 0 | L37: =SUM(L34:L36) -> 0 | M37: =SUM(K37/L37) -> #DIV/0! | P37: Total Occupancy | R37: =SUM(R34:R36) -> 0 | S37: =SUM(S34:S36) -> 0 | T37: =SUM(R37/S37) -> #DIV/0!
B39: Tuesday | C39: AM | D39: =GETPIVOTDATA("Sum of AM FIELD",'Pivot Table'!$A$40,"DAY","Tue") -> 0 | F39: =SUM(D39/E39) -> #DIV/0! | I39: Tuesday | J39: AM | K39: =GETPIVOTDATA("Sum of AM FIELD",'Pivot Table'!$A$52,"DAY","Tue") -> 0 | M39: =SUM(K39/L39) -> #DIV/0! | P39: Tuesday | Q39: AM | R39: =GETPIVOTDATA("Sum of AM FIELD",'Pivot Table'!$A$64,"DAY","Tue") -> 0 | T39: =SUM(R39/S39) -> #DIV/0!
C40: PM | D40: =GETPIVOTDATA("Sum of PM FIELD",'Pivot Table'!$A$40,"DAY","Tue") -> 0 | F40: =SUM(D40/E40) -> #DIV/0! | J40: PM | K40: =GETPIVOTDATA("Sum of PM FIELD",'Pivot Table'!$A$52,"DAY","Tue") -> 0 | M40: =SUM(K40/L40) -> #DIV/0! | Q40: PM | R40: =GETPIVOTDATA("Sum of PM FIELD",'Pivot Table'!$A$64,"DAY","Tue") -> 0 | T40: =SUM(R40/S40) -> #DIV/0!
B41: Total Occupancy | D41: =SUM(D38:D40) -> 0 | E41: =SUM(E38:E40) -> 0 | F41: =SUM(D41/E41) -> #DIV/0! | I41: Total Occupancy | K41: =SUM(K38:K40) -> 0 | L41: =SUM(L38:L40) -> 0 | M41: =SUM(K41/L41) -> #DIV/0! | P41: Total Occupancy | R41: =SUM(R38:R40) -> 0 | S41: =SUM(S38:S40) -> 0 | T41: =SUM(R41/S41) -> #DIV/0!
B43: Wednesday | C43: AM | D43: =GETPIVOTDATA("Sum of AM FIELD",'Pivot Table'!$A$40,"DAY","Wed") -> 0 | F43: =SUM(D43/E43) -> #DIV/0! | I43: Wednesday | J43: AM | K43: =GETPIVOTDATA("Sum of AM FIELD",'Pivot Table'!$A$52,"DAY","Wed") -> 0 | M43: =SUM(K43/L43) -> #DIV/0! | P43: Wednesday | Q43: AM | R43: =GETPIVOTDATA("Sum of AM FIELD",'Pivot Table'!$A$64,"DAY","Wed") -> 0 | T43: =SUM(R43/S43) -> #DIV/0!
C44: PM | D44: =GETPIVOTDATA("Sum of PM FIELD",'Pivot Table'!$A$40,"DAY","Wed") -> 0 | F44: =SUM(D44/E44) -> #DIV/0! | J44: PM | K44: =GETPIVOTDATA("Sum of PM FIELD",'Pivot Table'!$A$52,"DAY","Wed") -> 0 | M44: =SUM(K44/L44) -> #DIV/0! | Q44: PM | R44: =GETPIVOTDATA("Sum of PM FIELD",'Pivot Table'!$A$64,"DAY","Wed") -> 0 | T44: =SUM(R44/S44) -> #DIV/0!
B45: Total Occupancy | D45: =SUM(D42:D44) -> 0 | E45: =SUM(E42:E44) -> 0 | F45: =SUM(D45/E45) -> #DIV/0! | I45: Total Occupancy | K45: =SUM(K42:K44) -> 0 | L45: =SUM(L42:L44) -> 0 | M45: =SUM(K45/L45) -> #DIV/0! | P45: Total Occupancy | R45: =SUM(R42:R44) -> 0 | S45: =SUM(S42:S44) -> 0 | T45: =SUM(R45/S45) -> #DIV/0!
B47: Thursday | C47: AM | D47: =GETPIVOTDATA("Sum of AM FIELD",'Pivot Table'!$A$40,"DAY","Thu") -> 0 | F47: =SUM(D47/E47) -> #DIV/0! | I47: Thursday | J47: AM | K47: =GETPIVOTDATA("Sum of AM FIELD",'Pivot Table'!$A$52,"DAY","Thu") -> 0 | M47: =SUM(K47/L47) -> #DIV/0! | P47: Thursday | Q47: AM | R47: =GETPIVOTDATA("Sum of AM FIELD",'Pivot Table'!$A$64,"DAY","Thu") -> 0 | T47: =SUM(R47/S47) -> #DIV/0!
C48: PM | D48: =GETPIVOTDATA("Sum of PM FIELD",'Pivot Table'!$A$40,"DAY","Thu") -> 0 | F48: =SUM(D48/E48) -> #DIV/0! | J48: PM | K48: =GETPIVOTDATA("Sum of PM FIELD",'Pivot Table'!$A$52,"DAY","Thu") -> 0 | M48: =SUM(K48/L48) -> #DIV/0! | Q48: PM | R48: =GETPIVOTDATA("Sum of PM FIELD",'Pivot Table'!$A$64,"DAY","Thu") -> 0 | T48: =SUM(R48/S48) -> #DIV/0!
B49: Total Occupancy | D49: =SUM(D46:D48) -> 0 | E49: =SUM(E46:E48) -> 0 | F49: =SUM(D49/E49) -> #DIV/0! | I49: Total Occupancy | K49: =SUM(K46:K48) -> 0 | L49: =SUM(L46:L48) -> 0 | M49: =SUM(K49/L49) -> #DIV/0! | P49: Total Occupancy | R49: =SUM(R46:R48) -> 0 | S49: =SUM(S46:S48) -> 0 | T49: =SUM(R49/S49) -> #DIV/0!
B51: Friday | C51: AM | D51: =GETPIVOTDATA("Sum of AM FIELD",'Pivot Table'!$A$40,"DAY","Fri") -> 0 | F51: =SUM(D51/E51) -> #DIV/0! | I51: Friday | J51: AM | K51: =GETPIVOTDATA("Sum of AM FIELD",'Pivot Table'!$A$52,"DAY","Fri") -> 0 | M51: =SUM(K51/L51) -> #DIV/0! | P51: Friday | Q51: AM | R51: =GETPIVOTDATA("Sum of AM FIELD",'Pivot Table'!$A$64,"DAY","Fri") -> 0 | T51: =SUM(R51/S51) -> #DIV/0!
C52: PM | D52: =GETPIVOTDATA("Sum of PM FIELD",'Pivot Table'!$A$40,"DAY","Fri") -> 0 | F52: =SUM(D52/E52) -> #DIV/0! | J52: PM | K52: =GETPIVOTDATA("Sum of PM FIELD",'Pivot Table'!$A$52,"DAY","Fri") -> 0 | M52: =SUM(K52/L52) -> #DIV/0! | Q52: PM | R52: =GETPIVOTDATA("Sum of PM FIELD",'Pivot Table'!$A$64,"DAY","Fri") -> 0 | T52: =SUM(R52/S52) -> #DIV/0!
B53: Total Occupancy | D53: =SUM(D50:D52) -> 0 | E53: =SUM(E50:E52) -> 0 | F53: =SUM(D53/E53) -> #DIV/0! | I53: Total Occupancy | K53: =SUM(K50:K52) -> 0 | L53: =SUM(L50:L52) -> 0 | M53: =SUM(K53/L53) -> #DIV/0! | P53: Total Occupancy | R53: =SUM(R50:R52) -> 0 | S53: =SUM(S50:S52) -> 0 | T53: =SUM(R53/S53) -> #DIV/0!
B55: Saturday | C55: AM | D55: =GETPIVOTDATA("Sum of AM FIELD",'Pivot Table'!$A$40,"DAY","Sat") -> 0 | F55: =SUM(D55/E55) -> #DIV/0! | I55: Saturday | J55: AM | K55: =GETPIVOTDATA("Sum of AM FIELD",'Pivot Table'!$A$52,"DAY","Sat") -> 0 | M55: =SUM(K55/L55) -> #DIV/0! | P55: Saturday | Q55: AM | R55: =GETPIVOTDATA("Sum of AM FIELD",'Pivot Table'!$A$64,"DAY","Sat") -> 0 | T55: =SUM(R55/S55) -> #DIV/0!
C56: PM | D56: =GETPIVOTDATA("Sum of PM FIELD",'Pivot Table'!$A$40,"DAY","Sat") -> 0 | F56: =SUM(D56/E56) -> #DIV/0! | J56: PM | K56: =GETPIVOTDATA("Sum of PM FIELD",'Pivot Table'!$A$52,"DAY","Sat") -> 0 | M56: =SUM(K56/L56) -> #DIV/0! | Q56: PM | R56: =GETPIVOTDATA("Sum of PM FIELD",'Pivot Table'!$A$64,"DAY","Sat") -> 0 | T56: =SUM(R56/S56) -> #DIV/0!
...

Sheet Occupancy Report Summarised
B2: 2025 Totals (By Day) | D2: Bookings | E2: Spots Available | F2: Occupancy | G2: Notes | J2: 2025 Totals (By Month) | L2: Bookings | M2: Spots Available | N2: Occupancy | O2: Notes
B4: Monday | C4: AM | D4: ='Occupancy Report'!D4+'Occupancy Report'!K4+'Occupancy Report'!R4+'Occupancy Report'!D35+'Occupancy Report'!K35+'Occupancy Report'!R35+'Occupancy Report'!D66+'Occupancy Report'!K66+'Occupancy Report'!R66+'Occupancy Report'!D97+'Occupancy Report'!K97+'Occupancy Report'!R97 -> 445 | E4: ='Occupancy Report'!E4+'Occupancy Report'!L4+'Occupancy Report'!S4+'Occupancy Report'!E35+'Occupancy Report'!L35+'Occupancy Report'!S35+'Occupancy Report'!E66+'Occupancy Report'!L66+'Occupancy Report'!S66+'Occupancy Report'!E97+'Occupancy Report'!L97+'Occupancy Report'!S97 -> 556 | F4: =SUM(D4/E4) -> 0.80035971 | J4: January | K4: AM | L4: =GETPIVOTDATA("Sum of AM FIELD",'Pivot Table'!$A$4) -> 2557 | M4: ='Occupancy Report'!E4+'Occupancy Report'!E8+'Occupancy Report'!E12+'Occupancy Report'!E16+'Occupancy Report'!E20+'Occupancy Report'!E24+'Occupancy Report'!E28 -> 3008 | N4: =SUM(L4/M4) -> 0.85006649
C5: PM | D5: ='Occupancy Report'!D5+'Occupancy Report'!K5+'Occupancy Report'!R5+'Occupancy Report'!D36+'Occupancy Report'!K36+'Occupancy Report'!R36+'Occupancy Report'!D67+'Occupancy Report'!K67+'Occupancy Report'!R67+'Occupancy Report'!D98+'Occupancy Report'!K98+'Occupancy Report'!R98 -> 602 | E5: ='Occupancy Report'!E5+'Occupancy Report'!L5+'Occupancy Report'!S5+'Occupancy Report'!E36+'Occupancy Report'!L36+'Occupancy Report'!S36+'Occupancy Report'!E67+'Occupancy Report'!L67+'Occupancy Report'!S67+'Occupancy Report'!E98+'Occupancy Report'!L98+'Occupancy Report'!S98 -> 684 | F5: =SUM(D5/E5) -> 0.88011696 | K5: PM | L5: =GETPIVOTDATA("Sum of PM FIELD",'Pivot Table'!$A$4) -> 1728 | M5: ='Occupancy Report'!E5+'Occupancy Report'!E9+'Occupancy Report'!E13+'Occupancy Report'!E17+'Occupancy Report'!E21+'Occupancy Report'!E25+'Occupancy Report'!E29 -> 2572 | N5: =SUM(L5/M5) -> 0.6718507
B6: Total Occupancy | D6: =SUM(D4:D5) -> 1047 | E6: =SUM(E4:E5) -> 1240 | F6: =SUM(D6/E6) -> 0.84435484 | J6: Total Occupancy | L6: =SUM(L4:L5) -> 4285 | M6: =SUM(M4:M5) -> 5580 | N6: =SUM(L6/M6) -> 0.76792115
B8: Tuesday | C8: AM | D8: ='Occupancy Report'!D8+'Occupancy Report'!K8+'Occupancy Report'!R8+'Occupancy Report'!D39+'Occupancy Report'!K39+'Occupancy Report'!R39+'Occupancy Report'!D70+'Occupancy Report'!K70+'Occupancy Report'!R70+'Occupancy Report'!D101+'Occupancy Report'!K101+'Occupancy Report'!R101 -> 723 | E8: ='Occupancy Report'!E8+'Occupancy Report'!L8+'Occupancy Report'!S8+'Occupancy Report'!E39+'Occupancy Report'!L39+'Occupancy Report'!S39+'Occupancy Report'!E70+'Occupancy Report'!L70+'Occupancy Report'!S70+'Occupancy Report'!E101+'Occupancy Report'!L101+'Occupancy Report'!S101 -> 872 | F8: =SUM(D8/E8) -> 0.82912844 | J8: February | K8: AM | L8: =GETPIVOTDATA("Sum of AM FIELD",'Pivot Table'!$A$16) -> 2293 | M8: ='Occupancy Report'!L4+'Occupancy Report'!L8+'Occupancy Report'!L12+'Occupancy Report'!L16+'Occupancy Report'!L20+'Occupancy Report'!L24+'Occupancy Report'!L28 -> 2548 | N8: =SUM(L8/M8) -> 0.89992151
C9: PM | D9: ='Occupancy Report'!D9+'Occupancy Report'!K9+'Occupancy Report'!R9+'Occupancy Report'!D40+'Occupancy Report'!K40+'Occupancy Report'!R40+'Occupancy Report'!D71+'Occupancy Report'!K71+'Occupancy Report'!R71+'Occupancy Report'!D102+'Occupancy Report'!K102+'Occupancy Report'!R102 -> 113 | E9: ='Occupancy Report'!E9+'Occupancy Report'!L9+'Occupancy Report'!S9+'Occupancy Report'!E40+'Occupancy Report'!L40+'Occupancy Report'!S40+'Occupancy Report'!E71+'Occupancy Report'!L71+'Occupancy Report'!S71+'Occupancy Report'!E102+'Occupancy Report'!L102+'Occupancy Report'!S102 -> 616 | F9: =SUM(D9/E9) -> 0.18344156 | K9: PM | L9: =GETPIVOTDATA("Sum of PM FIELD",'Pivot Table'!$A$16) -> 1852 | M9: ='Occupancy Report'!L5+'Occupancy Report'!L9+'Occupancy Report'!L13+'Occupancy Report'!L17+'Occupancy Report'!L21+'Occupancy Report'!L25+'Occupancy Report'!L29 -> 2364 | N9: =SUM(L9/M9) -> 0.78341794
B10: Total Occupancy | D10: =SUM(D8:D9) -> 836 | E10: =SUM(E8:E9) -> 1488 | F10: =SUM(D10/E10) -> 0.56182796 | J10: Total Occupancy | L10: =SUM(L8:L9) -> 4145 | M10: =SUM(M8:M9) -> 4912 | N10: =SUM(L10/M10) -> 0.84385179
B12: Wednesday | C12: AM | D12: ='Occupancy Report'!D12+'Occupancy Report'!K12+'Occupancy Report'!R12+'Occupancy Report'!D43+'Occupancy Report'!K43+'Occupancy Report'!R43+'Occupancy Report'!D74+'Occupancy Report'!K74+'Occupancy Report'!R74+'Occupancy Report'!D105+'Occupancy Report'!K105+'Occupancy Report'!R105 -> 686 | E12: ='Occupancy Report'!E12+'Occupancy Report'!L12+'Occupancy Report'!S12+'Occupancy Report'!E43+'Occupancy Report'!L43+'Occupancy Report'!S43+'Occupancy Report'!E74+'Occupancy Report'!L74+'Occupancy Report'!S74+'Occupancy Report'!E105+'Occupancy Report'!L105+'Occupancy Report'!S105 -> 864 | F12: =SUM(D12/E12) -> 0.79398148 | J12: March | K12: AM | L12: =GETPIVOTDATA("Sum of AM FIELD",'Pivot Table'!$A$28) -> 0 | M12: ='Occupancy Report'!S4+'Occupancy Report'!S8+'Occupancy Report'!S12+'Occupancy Report'!S16+'Occupancy Report'!S20+'Occupancy Report'!S24+'Occupancy Report'!S28 -> 0 | N12: =SUM(L12/M12) -> #DIV/0!
C13: PM | D13: ='Occupancy Report'!D13+'Occupancy Report'!K13+'Occupancy Report'!R13+'Occupancy Report'!D44+'Occupancy Report'!K44+'Occupancy Report'!R44+'Occupancy Report'!D75+'Occupancy Report'!K75+'Occupancy Report'!R75+'Occupancy Report'!D106+'Occupancy Report'!K106+'Occupancy Report'!R106 -> 422 | E13: ='Occupancy Report'!E13+'Occupancy Report'!L13+'Occupancy Report'!S13+'Occupancy Report'!E44+'Occupancy Report'!L44+'Occupancy Report'!S44+'Occupancy Report'!E75+'Occupancy Report'!L75+'Occupancy Report'!S75+'Occupancy Report'!E106+'Occupancy Report'!L106+'Occupancy Report'!S106 -> 632 | F13: =SUM(D13/E13) -> 0.66772152 | K13: PM | L13: =GETPIVOTDATA("Sum of PM FIELD",'Pivot Table'!$A$28) -> 0 | M13: ='Occupancy Report'!S5+'Occupancy Report'!S9+'Occupancy Report'!S13+'Occupancy Report'!S17+'Occupancy Report'!S21+'Occupancy Report'!S25+'Occupancy Report'!S29 -> 0 | N13: =SUM(L13/M13) -> #DIV/0!
B14: Total Occupancy | D14: =SUM(D12:D13) -> 1108 | E14: =SUM(E12:E13) -> 1496 | F14: =SUM(D14/E14) -> 0.74064171 | J14: Total Occupancy | L14: =SUM(L12:L13) -> 0 | M14: =SUM(M12:M13) -> 0 | N14: =SUM(L14/M14) -> #DIV/0!
B16: Thursday | C16: AM | D16: ='Occupancy Report'!D16+'Occupancy Report'!K16+'Occupancy Report'!R16+'Occupancy Report'!D47+'Occupancy Report'!K47+'Occupancy Report'!R47+'Occupancy Report'!D78+'Occupancy Report'!K78+'Occupancy Report'!R78+'Occupancy Report'!D109+'Occupancy Report'!K109+'Occupancy Report'!R109 -> 734 | E16: ='Occupancy Report'!E16+'Occupancy Report'!L16+'Occupancy Report'!S16+'Occupancy Report'!E47+'Occupancy Report'!L47+'Occupancy Report'!S47+'Occupancy Report'!E78+'Occupancy Report'!L78+'Occupancy Report'!S78+'Occupancy Report'!E109+'Occupancy Report'!L109+'Occupancy Report'!S109 -> 800 | F16: =SUM(D16/E16) -> 0.9175 | J16: April | K16: AM | L16: =GETPIVOTDATA("Sum of AM FIELD",'Pivot Table'!$A$40) -> 0 | M16: ='Occupancy Report'!E35+'Occupancy Report'!E39+'Occupancy Report'!E43+'Occupancy Report'!E47+'Occupancy Report'!E51+'Occupancy Report'!E55+'Occupancy Report'!E59 -> 0 | N16: =SUM(L16/M16) -> #DIV/0!
C17: PM | D17: ='Occupancy Report'!D17+'Occupancy Report'!K17+'Occupancy Report'!R17+'Occupancy Report'!D48+'Occupancy Report'!K48+'Occupancy Report'!R48+'Occupancy Report'!D79+'Occupancy Report'!K79+'Occupancy Report'!R79+'Occupancy Report'!D110+'Occupancy Report'!K110+'Occupancy Report'!R110 -> 665 | E17: ='Occupancy Report'!E17+'Occupancy Report'!L17+'Occupancy Report'!S17+'Occupancy Report'!E48+'Occupancy Report'!L48+'Occupancy Report'!S48+'Occupancy Report'!E79+'Occupancy Report'!L79+'Occupancy Report'!S79+'Occupancy Report'!E110+'Occupancy Report'!L110+'Occupancy Report'!S110 -> 792 | F17: =SUM(D17/E17) -> 0.83964646 | K17: PM | L17: =GETPIVOTDATA("Sum of PM FIELD",'Pivot Table'!$A$40) -> 0 | M17: ='Occupancy Report'!E36+'Occupancy Report'!E40+'Occupancy Report'!E44+'Occupancy Report'!E48+'Occupancy Report'!E52+'Occupancy Report'!E56+'Occupancy Report'!E60 -> 0 | N17: =SUM(L17/M17) -> #DIV/0!
B18: Total Occupancy | D18: =SUM(D16:D17) -> 1399 | E18: =SUM(E16:E17) -> 1592 | F18: =SUM(D18/E18) -> 0.87876884 | J18: Total Occupancy | L18: =SUM(L16:L17) -> 0 | M18: =SUM(M16:M17) -> 0 | N18: =SUM(L18/M18) -> #DIV/0!
B20: Friday | C20: AM | D20: ='Occupancy Report'!D20+'Occupancy Report'!K20+'Occupancy Report'!R20+'Occupancy Report'!D51+'Occupancy Report'!K51+'Occupancy Report'!R51+'Occupancy Report'!D82+'Occupancy Report'!K82+'Occupancy Report'!R82+'Occupancy Report'!D113+'Occupancy Report'!K113+'Occupancy Report'!R113 -> 751 | E20: ='Occupancy Report'!E20+'Occupancy Report'!L20+'Occupancy Report'!S20+'Occupancy Report'!E51+'Occupancy Report'!L51+'Occupancy Report'!S51+'Occupancy Report'!E82+'Occupancy Report'!L82+'Occupancy Report'!S82+'Occupancy Report'!E113+'Occupancy Report'!L113+'Occupancy Report'!S113 -> 860 | F20: =SUM(D20/E20) -> 0.87325581 | J20: May | K20: AM | L20: =GETPIVOTDATA("Sum of AM FIELD",'Pivot Table'!$A$52) -> 0 | M20: ='Occupancy Report'!L35+'Occupancy Report'!L39+'Occupancy Report'!L43+'Occupancy Report'!L47+'Occupancy Report'!L51+'Occupancy Report'!L55+'Occupancy Report'!L59 -> 0 | N20: =SUM(L20/M20) -> #DIV/0!
C21: PM | D21: ='Occupancy Report'!D21+'Occupancy Report'!K21+'Occupancy Report'!R21+'Occupancy Report'!D52+'Occupancy Report'!K52+'Occupancy Report'!R52+'Occupancy Report'!D83+'Occupancy Report'!K83+'Occupancy Report'!R83+'Occupancy Report'!D114+'Occupancy Report'!K114+'Occupancy Report'!R114 -> 559 | E21: ='Occupancy Report'!E21+'Occupancy Report'!L21+'Occupancy Report'!S21+'Occupancy Report'!E52+'Occupancy Report'!L52+'Occupancy Report'!S52+'Occupancy Report'!E83+'Occupancy Report'!L83+'Occupancy Report'!S83+'Occupancy Report'!E114+'Occupancy Report'!L114+'Occupancy Report'!S114 -> 708 | F21: =SUM(D21/E21) -> 0.78954802 | K21: PM | L21: =GETPIVOTDATA("Sum of PM FIELD",'Pivot Table'!$A$52) -> 0 | M21: ='Occupancy Report'!L60+'Occupancy Report'!L56+'Occupancy Report'!L52+'Occupancy Report'!L48+'Occupancy Report'!L44+'Occupancy Report'!L40+'Occupancy Report'!L36 -> 0 | N21: =SUM(L21/M21) -> #DIV/0!
B22: Total Occupancy | D22: =SUM(D20:D21) -> 1310 | E22: =SUM(E20:E21) -> 1568 | F22: =SUM(D22/E22) -> 0.83545918 | J22: Total Occupancy | L22: =SUM(L20:L21) -> 0 | M22: =SUM(M20:M21) -> 0 | N22: =SUM(L22/M22) -> #DIV/0!
B24: Saturday | C24: AM | D24: ='Occupancy Report'!D24+'Occupancy Report'!K24+'Occupancy Report'!R24+'Occupancy Report'!D55+'Occupancy Report'!K55+'Occupancy Report'!R55+'Occupancy Report'!D86+'Occupancy Report'!K86+'Occupancy Report'!R86+'Occupancy Report'!D117+'Occupancy Report'!K117+'Occupancy Report'!R117 -> 787 | E24: ='Occupancy Report'!E24+'Occupancy Report'!L24+'Occupancy Report'!S24+'Occupancy Report'!E55+'Occupancy Report'!L55+'Occupancy Report'!S55+'Occupancy Report'!E86+'Occupancy Report'!L86+'Occupancy Report'!S86+'Occupancy Report'!E117+'Occupancy Report'!L117+'Occupancy Report'!S117 -> 836 | F24: =SUM(D24/E24) -> 0.94138756 | J24: June | K24: AM | L24: =GETPIVOTDATA("Sum of AM FIELD",'Pivot Table'!$A$64) -> 0 | M24: ='Occupancy Report'!S35+'Occupancy Report'!S39+'Occupancy Report'!S43+'Occupancy Report'!S47+'Occupancy Report'!S51+'Occupancy Report'!S55+'Occupancy Report'!S59 -> 0 | N24: =SUM(L24/M24) -> #DIV/0!
C25: PM | D25: ='Occupancy Report'!D25+'Occupancy Report'!K25+'Occupancy Report'!R25+'Occupancy Report'!D56+'Occupancy Report'!K56+'Occupancy Report'!R56+'Occupancy Report'!D87+'Occupancy Report'!K87+'Occupancy Report'!R87+'Occupancy Report'!D118+'Occupancy Report'!K118+'Occupancy Report'!R118 -> 584 | E25: ='Occupancy Report'!E25+'Occupancy Report'!L25+'Occupancy Report'!S25+'Occupancy Report'!E56+'Occupancy Report'!L56+'Occupancy Report'!S56+'Occupancy Report'!E87+'Occupancy Report'!L87+'Occupancy Report'!S87+'Occupancy Report'!E118+'Occupancy Report'!L118+'Occupancy Report'!S118 -> 800 | F25: =SUM(D25/E25) -> 0.73 | K25: PM | L25: =GETPIVOTDATA("Sum of PM FIELD",'Pivot Table'!$A$64) -> 0 | M25: ='Occupancy Report'!S36+'Occupancy Report'!S40+'Occupancy Report'!S44+'Occupancy Report'!S48+'Occupancy Report'!S52+'Occupancy Report'!S56+'Occupancy Report'!S60 -> 0 | N25: =SUM(L25/M25) -> #DIV/0!
B26: Total Occupancy | D26: =SUM(D24:D25) -> 1371 | E26: =SUM(E24:E25) -> 1636 | F26: =SUM(D26/E26) -> 0.83801956 | J26: Total Occupancy | L26: =SUM(L24:L25) -> 0 | M26: =SUM(M24:M25) -> 0 | N26: =SUM(L26/M26) -> #DIV/0!
B28: Sunday | C28: AM | D28: ='Occupancy Report'!D28+'Occupancy Report'!K28+'Occupancy Report'!R28+'Occupancy Report'!D59+'Occupancy Report'!K59+'Occupancy Report'!R59+'Occupancy Report'!D90+'Occupancy Report'!K90+'Occupancy Report'!R90+'Occupancy Report'!D121+'Occupancy Report'!K121+'Occupancy Report'!R121 -> 724 | E28: ='Occupancy Report'!E28+'Occupancy Report'!L28+'Occupancy Report'!S28+'Occupancy Report'!E59+'Occupancy Report'!L59+'Occupancy Report'!S59+'Occupancy Report'!E90+'Occupancy Report'!L90+'Occupancy Report'!S90+'Occupancy Report'!E121+'Occupancy Report'!L121+'Occupancy Report'!S121 -> 768 | F28: =SUM(D28/E28) -> 0.94270833 | J28: July | K28: AM | L28: =GETPIVOTDATA("Sum of AM FIELD",'Pivot Table'!$A$76) -> 0 | M28: ='Occupancy Report'!E66+'Occupancy Report'!E70+'Occupancy Report'!E74+'Occupancy Report'!E78+'Occupancy Report'!E82+'Occupancy Report'!E86+'Occupancy Report'!E90 -> 0 | N28: =SUM(L28/M28) -> #DIV/0!
C29: PM | D29: ='Occupancy Report'!D29+'Occupancy Report'!K29+'Occupancy Report'!R29+'Occupancy Report'!D60+'Occupancy Report'!K60+'Occupancy Report'!R60+'Occupancy Report'!D91+'Occupancy Report'!K91+'Occupancy Report'!R91+'Occupancy Report'!D122+'Occupancy Report'!K122+'Occupancy Report'!R122 -> 635 | E29: ='Occupancy Report'!E29+'Occupancy Report'!L29+'Occupancy Report'!S29+'Occupancy Report'!E60+'Occupancy Report'!L60+'Occupancy Report'!S60+'Occupancy Report'!E91+'Occupancy Report'!L91+'Occupancy Report'!S91+'Occupancy Report'!E122+'Occupancy Report'!L122+'Occupancy Report'!S122 -> 704 | F29: =SUM(D29/E29) -> 0.90198864 | K29: PM | L29: =GETPIVOTDATA("Sum of PM FIELD",'Pivot Table'!$A$76) -> 0 | M29: ='Occupancy Report'!E67+'Occupancy Report'!E71+'Occupancy Report'!E75+'Occupancy Report'!E79+'Occupancy Report'!E83++'Occupancy Report'!E87+'Occupancy Report'!E91 -> 0 | N29: =SUM(L29/M29) -> #DIV/0!
B30: Total Occupancy | D30: =SUM(D28:D29) -> 1359 | E30: =SUM(E28:E29) -> 1472 | F30: =SUM(D30/E30) -> 0.9232337 | J30: Total Occupancy | L30: =SUM(L28:L29) -> 0 | M30: =SUM(M28:M29) -> 0 | N30: =SUM(L30/M30) -> #DIV/0!
J32: August | K32: AM | L32: =GETPIVOTDATA("Sum of AM FIELD",'Pivot Table'!$A$88) -> 0 | M32: ='Occupancy Report'!L66+'Occupancy Report'!L70+'Occupancy Report'!L74+'Occupancy Report'!L78+'Occupancy Report'!L82+'Occupancy Report'!L86+'Occupancy Report'!L90 -> 0 | N32: =SUM(L32/M32) -> #DIV/0!
K33: PM | L33: =GETPIVOTDATA("Sum of PM FIELD",'Pivot Table'!$A$88) -> 0 | M33: ='Occupancy Report'!L67+'Occupancy Report'!L71+'Occupancy Report'!L75+'Occupancy Report'!L79+'Occupancy Report'!L83+'Occupancy Report'!L87+'Occupancy Report'!L91 -> 0 | N33: =SUM(L33/M33) -> #DIV/0!
J34: Total Occupancy | L34: =SUM(L32:L33) -> 0 | M34: =SUM(M32:M33) -> 0 | N34: =SUM(L34/M34) -> #DIV/0!
J36: September | K36: AM | L36: =GETPIVOTDATA("Sum of AM FIELD",'Pivot Table'!$A$100) -> 0 | M36: ='Occupancy Report'!S66+'Occupancy Report'!S70+'Occupancy Report'!S74+'Occupancy Report'!S78+'Occupancy Report'!S82+'Occupancy Report'!S86+'Occupancy Report'!S90 -> 0 | N36: =SUM(L36/M36) -> #DIV/0!
K37: PM | L37: =GETPIVOTDATA("Sum of PM FIELD",'Pivot Table'!$A$100) -> 0 | M37: ='Occupancy Report'!S67+'Occupancy Report'!S71+'Occupancy Report'!S75+'Occupancy Report'!S79+'Occupancy Report'!S83+'Occupancy Report'!S87+'Occupancy Report'!S91 -> 0 | N37: =SUM(L37/M37) -> #DIV/0!
J38: Total Occupancy | L38: =SUM(L36:L37) -> 0 | M38: =SUM(M36:M37) -> 0 | N38: =SUM(L38/M38) -> #DIV/0!
J40: October | K40: AM | L40: =GETPIVOTDATA("Sum of AM FIELD",'Pivot Table'!$A$112) -> 0 | M40: ='Occupancy Report'!E97+'Occupancy Report'!E101+'Occupancy Report'!E105+'Occupancy Report'!E109+'Occupancy Report'!E113+'Occupancy Report'!E117+'Occupancy Report'!E121 -> 0 | N40: =SUM(L40/M40) -> #DIV/0!
K41: PM | L41: =GETPIVOTDATA("Sum of PM FIELD",'Pivot Table'!$A$112) -> 0 | M41: ='Occupancy Report'!E98+'Occupancy Report'!E102+'Occupancy Report'!E106+'Occupancy Report'!E110+'Occupancy Report'!E114+'Occupancy Report'!E118+'Occupancy Report'!E122 -> 0 | N41: =SUM(L41/M41) -> #DIV/0!
J42: Total Occupancy | L42: =SUM(L40:L41) -> 0 | M42: =SUM(M40:M41) -> 0 | N42: =SUM(L42/M42) -> #DIV/0!
J44: November | K44: AM | L44: =GETPIVOTDATA("Sum of AM FIELD",'Pivot Table'!$A$124) -> 0 | M44: ='Occupancy Report'!L97+'Occupancy Report'!L101+'Occupancy Report'!L105+'Occupancy Report'!L109+'Occupancy Report'!L113+'Occupancy Report'!L117+'Occupancy Report'!L121 -> 0 | N44: =SUM(L44/M44) -> #DIV/0!
K45: PM | L45: =GETPIVOTDATA("Sum of PM FIELD",'Pivot Table'!$A$124) -> 0 | M45: ='Occupancy Report'!L98+'Occupancy Report'!L102+'Occupancy Report'!L106+'Occupancy Report'!L110+'Occupancy Report'!L114+'Occupancy Report'!L118+'Occupancy Report'!L122 -> 0 | N45: =SUM(L45/M45) -> #DIV/0!
J46: Total Occupancy | L46: =SUM(L44:L45) -> 0 | M46: =SUM(M44:M45) -> 0 | N46: =SUM(L46/M46) -> #DIV/0!
J48: December | K48: AM | L48: =GETPIVOTDATA("Sum of AM FIELD",'Pivot Table'!$A$136) -> 0 | M48: ='Occupancy Report'!S97+'Occupancy Report'!S101+'Occupancy Report'!S105+'Occupancy Report'!S109+'Occupancy Report'!S113+'Occupancy Report'!S117+'Occupancy Report'!S121 -> 0 | N48: =SUM(L48/M48) -> #DIV/0!
K49: PM | L49: =GETPIVOTDATA("Sum of PM FIELD",'Pivot Table'!$A$136) -> 0 | M49: ='Occupancy Report'!S98+'Occupancy Report'!S102+'Occupancy Report'!S106+'Occupancy Report'!S110+'Occupancy Report'!S114+'Occupancy Report'!S118+'Occupancy Report'!S122 -> 0 | N49: =SUM(L49/M49) -> #DIV/0!
J50: Total Occupancy | L50: =SUM(L48:L49) -> 0 | M50: =SUM(M48:M49) -> 0 | N50: =SUM(L50/M50) -> #DIV/0!

Sheet After 3pm Data
B2: January | D2: Bookings | E2: Spots Available | F2: Occupancy | G2: Notes | I2: February | K2: Bookings | L2: Spots Available | M2: Occupancy | N2: Notes | P2: December | R2: Bookings | S2: Spots Available | T2: Occupancy | U2: Notes | X2: 2025 Totals (By Month) | Z2: Bookings | AA2: Spots Available | AB2: Occupancy | AC2: Notes
B4: Monday | C4: After 3pm | D4: =GETPIVOTDATA("Sum of AFTER 3PM",'Pivot Table'!$A$4,"DAY","Mon") -> 77 | E4: =76+76+80+80 -> 312 | F4: =SUM(D4/E4) -> 0.24679487 | I4: Monday | J4: After 3pm | K4: =GETPIVOTDATA("Sum of AFTER 3PM",'Pivot Table'!$A$16,"DAY","Mon") -> 75 | L4: =80+56+80+80 -> 296 | M4: =SUM(K4/L4) -> 0.25337838 | P4: Monday | Q4: After 3pm | R4: =GETPIVOTDATA("Sum of AFTER 3PM",'Pivot Table'!$A$136,"DAY","Mon") -> 0 | T4: =SUM(R4/S4) -> #DIV/0! | X4: January | Y4: After 3pm | Z4: =SUM(D4+D6+D8+D10+D12+D14+D16) -> 757 | AA4: =SUM(E4+E6+E8+E10+E12+E14+E16) -> 2536 | AB4: =SUM(Z4/AA4) -> 0.29850158
B6: Tuesday | C6: After 3pm | D6: =GETPIVOTDATA("Sum of AFTER 3PM",'Pivot Table'!$A$4,"DAY","Tue") -> 105 | E6: =104+104+104+104 -> 416 | F6: =SUM(D6/E6) -> 0.25240385 | I6: Tuesday | J6: After 3pm | K6: =GETPIVOTDATA("Sum of AFTER 3PM",'Pivot Table'!$A$16,"DAY","Tue") -> 87 | L6: =104+104+104+104 -> 416 | M6: =SUM(K6/L6) -> 0.20913462 | P6: Tuesday | Q6: After 3pm | R6: =GETPIVOTDATA("Sum of AFTER 3PM",'Pivot Table'!$A$136,"DAY","Tue") -> 0 | T6: =SUM(R6/S6) -> #DIV/0! | X6: November | Y6: After 3pm | Z6: =SUM(K4+K6+K8+K10+K12+K14+K16) -> 735 | AA6: =SUM(L4+L6+L8+L10+L12+L14+L16) -> 2156 | AB6: =SUM(Z6/AA6) -> 0.34090909
B8: Wednesday | C8: After 3pm | D8: =GETPIVOTDATA("Sum of AFTER 3PM",'Pivot Table'!$A$4,"DAY","Wed") -> 93 | E8: =76+76+76+76 -> 304 | F8: =SUM(D8/E8) -> 0.30592105 | I8: Wednesday | J8: After 3pm | K8: =GETPIVOTDATA("Sum of AFTER 3PM",'Pivot Table'!$A$16,"DAY","Wed") -> 79 | L8: =76+76+76+76 -> 304 | M8: =SUM(K8/L8) -> 0.25986842 | P8: Wednesday | Q8: After 3pm | R8: =GETPIVOTDATA("Sum of AFTER 3PM",'Pivot Table'!$A$136,"DAY","Wed") -> 0 | T8: =SUM(R8/S8) -> #DIV/0! | X8: December | Y8: After 3pm | Z8: =SUM(R4+R6+R8+R10+R12+R14+R16) -> 0 | AA8: =SUM(S4+S6+S8+S10+S12+S14+S16) -> 0 | AB8: =SUM(Z8/AA8) -> #DIV/0!
B10: Thursday | C10: After 3pm | D10: =GETPIVOTDATA("Sum of AFTER 3PM",'Pivot Table'!$A$4,"DAY","Thu") -> 113 | E10: =80+80+80+80+80 -> 400 | F10: =SUM(D10/E10) -> 0.2825 | I10: Thursday | J10: After 3pm | K10: =GETPIVOTDATA("Sum of AFTER 3PM",'Pivot Table'!$A$16,"DAY","Thu") -> 137 | L10: =80+80+80+80 -> 320 | M10: =SUM(K10/L10) -> 0.428125 | P10: Thursday | Q10: After 3pm | R10: =GETPIVOTDATA("Sum of AFTER 3PM",'Pivot Table'!$A$136,"DAY","Thu") -> 0 | T10: =SUM(R10/S10) -> #DIV/0!
B12: Friday | C12: After 3pm | D12: =GETPIVOTDATA("Sum of AFTER 3PM",'Pivot Table'!$A$4,"DAY","Fri") -> 185 | E12: =76+76+80+76+76 -> 384 | F12: =SUM(D12/E12) -> 0.48177083 | I12: Friday | J12: After 3pm | K12: =GETPIVOTDATA("Sum of AFTER 3PM",'Pivot Table'!$A$16,"DAY","Fri") -> 212 | L12: =88+80+76+96 -> 340 | M12: =SUM(K12/L12) -> 0.62352941 | P12: Friday | Q12: After 3pm | R12: =GETPIVOTDATA("Sum of AFTER 3PM",'Pivot Table'!$A$136,"DAY","Fri") -> 0 | T12: =SUM(R12/S12) -> #DIV/0!
B14: Saturday | C14: After 3pm | D14: =GETPIVOTDATA("Sum of AFTER 3PM",'Pivot Table'!$A$4,"DAY","Sat") -> 23 | E14: =80+80+80+80+80 -> 400 | F14: =SUM(D14/E14) -> 0.0575 | I14: Saturday | J14: After 3pm | K14: =GETPIVOTDATA("Sum of AFTER 3PM",'Pivot Table'!$A$16,"DAY","Sat") -> 7 | L14: =80+80 -> 160 | M14: =SUM(K14/L14) -> 0.04375 | P14: Saturday | Q14: After 3pm | R14: =GETPIVOTDATA("Sum of AFTER 3PM",'Pivot Table'!$A$136,"DAY","Sat") -> 0 | T14: =SUM(R14/S14) -> #DIV/0!
B16: Sunday | C16: After 3pm | D16: =GETPIVOTDATA("Sum of AFTER 3PM",'Pivot Table'!$A$4,"DAY","Sun") -> 161 | E16: =80+80+80+80 -> 320 | F16: =SUM(D16/E16) -> 0.503125 | I16: Sunday | J16: After 3pm | K16: =GETPIVOTDATA("Sum of AFTER 3PM",'Pivot Table'!$A$16,"DAY","Sun") -> 138 | L16: =80+80+80+80 -> 320 | M16: =SUM(K16/L16) -> 0.43125 | P16: Sunday | Q16: After 3pm | R16: =GETPIVOTDATA("Sum of AFTER 3PM",'Pivot Table'!$A$136,"DAY","Sun") -> 0 | T16: =SUM(R16/S16) -> #DIV/0!
B20: 2025 Totals (By Day) | D20: Bookings | E20: Spots Available | F20: Occupancy | G20: Notes
B23: Monday | C23: After 3pm | D23: =SUM(D4+K4+R4) -> 152 | E23: =SUM(E4+L4+S4) -> 608 | F23: =SUM(D23/E23) -> 0.25
B25: Tuesday | C25: After 3pm | D25: =SUM(D6+K6+R6) -> 192 | E25: =SUM(E6+L6+S6) -> 832 | F25: =SUM(D25/E25) -> 0.23076923
B27: Wednesday | C27: After 3pm | D27: =SUM(D8+K8+R8) -> 172 | E27: =SUM(E8+L8+S8) -> 608 | F27: =SUM(D27/E27) -> 0.28289474
B29: Thursday | C29: After 3pm | D29: =SUM(D10+K10+R10) -> 250 | E29: =SUM(E10+L10+S10) -> 720 | F29: =SUM(D29/E29) -> 0.34722222
B31: Friday | C31: After 3pm | D31: =SUM(D12+K12+R12) -> 397 | E31: =SUM(E12+L12+S12) -> 724 | F31: =SUM(D31/E31) -> 0.54834254
B33: Saturday | C33: After 3pm | D33: =SUM(D14+K14+R14) -> 30 | E33: =SUM(E14+L14+S14) -> 560 | F33: =SUM(D33/E33) -> 0.053571429
B35: Sunday | C35: After 3pm | D35: =SUM(D16+K16+R16) -> 299 | E35: =SUM(E16+L16+S16) -> 640 | F35: =SUM(D35/E35) -> 0.4671875

Sheet Day by Day Totals
B2: Day by Totals
B4: Monday | E4: Tuesday | H4: Wednesday | K4: Thursday | N4: Friday | Q4: Saturday | T4: Sunday
B6: AM Field | C6: =GETPIVOTDATA("Sum of AM FIELD",'Pivot Table'!$A$4,"DAY","Mon")+GETPIVOTDATA("Sum of AM FIELD",'Pivot Table'!$A$16,"DAY","Mon")+GETPIVOTDATA("Sum of AM FIELD",'Pivot Table'!$A$28,"DAY","Mon")+GETPIVOTDATA("Sum of AM FIELD",'Pivot Table'!$A$40,"DAY","Mon")+GETPIVOTDATA("Sum of AM FIELD",'Pivot Table'!$A$52,"DAY","Mon")+GETPIVOTDATA("Sum of AM FIELD",'Pivot Table'!$A$64,"DAY","Mon")+GETPIVOTDATA("Sum of AM FIELD",'Pivot Table'!$A$76,"DAY","Mon")+GETPIVOTDATA("Sum of AM FIELD",'Pivot Table'!$A$88,"DAY","Mon")+GETPIVOTDATA("Sum of AM FIELD",'Pivot Table'!$A$100,"DAY","Mon")+GETPIVOTDATA("Sum of AM FIELD",'Pivot Table'!$A$112,"DAY","Mon")+GETPIVOTDATA("Sum of AM FIELD",'Pivot Table'!$A$124,"DAY","Mon")+GETPIVOTDATA("Sum of AM FIELD",'Pivot Table'!$A$136,"DAY","Mon") -> 445 | E6: AM Field | F6: =GETPIVOTDATA("Sum of AM FIELD",'Pivot Table'!$A$4,"DAY","Tue") +GETPIVOTDATA("Sum of AM FIELD",'Pivot Table'!$A$16,"DAY","Tue") +GETPIVOTDATA("Sum of AM FIELD",'Pivot Table'!$A$28,"DAY","Tue") +GETPIVOTDATA("Sum of AM FIELD",'Pivot Table'!$A$40,"DAY","Tue") +GETPIVOTDATA("Sum of AM FIELD",'Pivot Table'!$A$52,"DAY","Tue") +GETPIVOTDATA("Sum of AM FIELD",'Pivot Table'!$A$64,"DAY","Tue") +GETPIVOTDATA("Sum of AM FIELD",'Pivot Table'!$A$76,"DAY","Tue") +GETPIVOTDATA("Sum of AM FIELD",'Pivot Table'!$A$88,"DAY","Tue") +GETPIVOTDATA("Sum of AM FIELD",'Pivot Table'!$A$100,"DAY","Tue") +GETPIVOTDATA("Sum of AM FIELD",'Pivot Table'!$A$112,"DAY","Tue") +GETPIVOTDATA("Sum of AM FIELD",'Pivot Table'!$A$124,"DAY","Tue") +GETPIVOTDATA("Sum of AM FIELD",'Pivot Table'!$A$136,"DAY","Tue") -> 723 | H6: AM Field | I6: =GETPIVOTDATA("Sum of AM FIELD",'Pivot Table'!$A$4,"DAY","Wed") +GETPIVOTDATA("Sum of AM FIELD",'Pivot Table'!$A$16,"DAY","Wed") +GETPIVOTDATA("Sum of AM FIELD",'Pivot Table'!$A$28,"DAY","Wed") +GETPIVOTDATA("Sum of AM FIELD",'Pivot Table'!$A$40,"DAY","Wed") +GETPIVOTDATA("Sum of AM FIELD",'Pivot Table'!$A$52,"DAY","Wed") +GETPIVOTDATA("Sum of AM FIELD",'Pivot Table'!$A$64,"DAY","Wed") +GETPIVOTDATA("Sum of AM FIELD",'Pivot Table'!$A$76,"DAY","Wed") +GETPIVOTDATA("Sum of AM FIELD",'Pivot Table'!$A$88,"DAY","Wed") +GETPIVOTDATA("Sum of AM FIELD",'Pivot Table'!$A$100,"DAY","Wed") +GETPIVOTDATA("Sum of AM FIELD",'Pivot Table'!$A$112,"DAY","Wed") +GETPIVOTDATA("Sum of AM FIELD",'Pivot Table'!$A$124,"DAY","Wed") +GETPIVOTDATA("Sum of AM FIELD",'Pivot Table'!$A$136,"DAY","Wed") -> 686 | K6: AM Field | L6: =GETPIVOTDATA("Sum of AM FIELD",'Pivot Table'!$A$4,"DAY","Thu") +GETPIVOTDATA("Sum of AM FIELD",'Pivot Table'!$A$16,"DAY","Thu") +GETPIVOTDATA("Sum of AM FIELD",'Pivot Table'!$A$28,"DAY","Thu") +GETPIVOTDATA("Sum of AM FIELD",'Pivot Table'!$A$40,"DAY","Thu") +GETPIVOTDATA("Sum of AM FIELD",'Pivot Table'!$A$52,"DAY","Thu") +GETPIVOTDATA("Sum of AM FIELD",'Pivot Table'!$A$64,"DAY","Thu") +GETPIVOTDATA("Sum of AM FIELD",'Pivot Table'!$A$76,"DAY","Thu") +GETPIVOTDATA("Sum of AM FIELD",'Pivot Table'!$A$88,"DAY","Thu") +GETPIVOTDATA("Sum of AM FIELD",'Pivot Table'!$A$100,"DAY","Thu") +GETPIVOTDATA("Sum of AM FIELD",'Pivot Table'!$A$112,"DAY","Thu") +GETPIVOTDATA("Sum of AM FIELD",'Pivot Table'!$A$124,"DAY","Thu") +GETPIVOTDATA("Sum of AM FIELD",'Pivot Table'!$A$136,"DAY","Thu") -> 734 | N6: AM Field | O6: =GETPIVOTDATA("Sum of AM FIELD",'Pivot Table'!$A$4,"DAY","Fri") +GETPIVOTDATA("Sum of AM FIELD",'Pivot Table'!$A$16,"DAY","Fri") +GETPIVOTDATA("Sum of AM FIELD",'Pivot Table'!$A$28,"DAY","Fri") +GETPIVOTDATA("Sum of AM FIELD",'Pivot Table'!$A$40,"DAY","Fri") +GETPIVOTDATA("Sum of AM FIELD",'Pivot Table'!$A$52,"DAY","Fri") +GETPIVOTDATA("Sum of AM FIELD",'Pivot Table'!$A$64,"DAY","Fri") +GETPIVOTDATA("Sum of AM FIELD",'Pivot Table'!$A$76,"DAY","Fri") +GETPIVOTDATA("Sum of AM FIELD",'Pivot Table'!$A$88,"DAY","Fri") +GETPIVOTDATA("Sum of AM FIELD",'Pivot Table'!$A$100,"DAY","Fri") +GETPIVOTDATA("Sum of AM FIELD",'Pivot Table'!$A$112,"DAY","Fri") +GETPIVOTDATA("Sum of AM FIELD",'Pivot Table'!$A$124,"DAY","Fri") +GETPIVOTDATA("Sum of AM FIELD",'Pivot Table'!$A$136,"DAY","Fri") -> 751 | Q6: AM Field | R6: =GETPIVOTDATA("Sum of AM FIELD",'Pivot Table'!$A$4,"DAY","Sat") +GETPIVOTDATA("Sum of AM FIELD",'Pivot Table'!$A$16,"DAY","Sat") +GETPIVOTDATA("Sum of AM FIELD",'Pivot Table'!$A$28,"DAY","Sat") +GETPIVOTDATA("Sum of AM FIELD",'Pivot Table'!$A$40,"DAY","Sat") +GETPIVOTDATA("Sum of AM FIELD",'Pivot Table'!$A$52,"DAY","Sat") +GETPIVOTDATA("Sum of AM FIELD",'Pivot Table'!$A$64,"DAY","Sat") +GETPIVOTDATA("Sum of AM FIELD",'Pivot Table'!$A$76,"DAY","Sat") +GETPIVOTDATA("Sum of AM FIELD",'Pivot Table'!$A$88,"DAY","Sat") +GETPIVOTDATA("Sum of AM FIELD",'Pivot Table'!$A$100,"DAY","Sat") +GETPIVOTDATA("Sum of AM FIELD",'Pivot Table'!$A$112,"DAY","Sat") +GETPIVOTDATA("Sum of AM FIELD",'Pivot Table'!$A$124,"DAY","Sat") +GETPIVOTDATA("Sum of AM FIELD",'Pivot Table'!$A$136,"DAY","Sat") -> 787 | T6: AM Field | U6: =GETPIVOTDATA("Sum of AM FIELD",'Pivot Table'!$A$4,"DAY","Sun") +GETPIVOTDATA("Sum of AM FIELD",'Pivot Table'!$A$16,"DAY","Sun") +GETPIVOTDATA("Sum of AM FIELD",'Pivot Table'!$A$28,"DAY","Sun") +GETPIVOTDATA("Sum of AM FIELD",'Pivot Table'!$A$40,"DAY","Sun") +GETPIVOTDATA("Sum of AM FIELD",'Pivot Table'!$A$52,"DAY","Sun") +GETPIVOTDATA("Sum of AM FIELD",'Pivot Table'!$A$64,"DAY","Sun") +GETPIVOTDATA("Sum of AM FIELD",'Pivot Table'!$A$76,"DAY","Sun") +GETPIVOTDATA("Sum of AM FIELD",'Pivot Table'!$A$88,"DAY","Sun") +GETPIVOTDATA("Sum of AM FIELD",'Pivot Table'!$A$100,"DAY","Sun") +GETPIVOTDATA("Sum of AM FIELD",'Pivot Table'!$A$112,"DAY","Sun") +GETPIVOTDATA("Sum of AM FIELD",'Pivot Table'!$A$124,"DAY","Sun") +GETPIVOTDATA("Sum of AM FIELD",'Pivot Table'!$A$136,"DAY","Sun") -> 724
